2024-01-25 16:45:53,407 - logging_bot - ERROR - Произошла непредвиденная ошибка:
Traceback (most recent call last):
  File "/home/shliamb/Desktop/WORK_FOLDER/chatgpt/app/run_bot.py", line 9, in <module>
    from tele_bot import start_bot
  File "/home/shliamb/Desktop/WORK_FOLDER/chatgpt/app/tele_bot.py", line 47, in <module>
    start_bot = bot.polling()
                ^^^^^^^^^^^^^
  File "/home/shliamb/Desktop/WORK_FOLDER/chatgpt/myvenv/lib/python3.11/site-packages/telebot/__init__.py", line 1045, in polling
    self.__threaded_polling(non_stop=non_stop, interval=interval, timeout=timeout, long_polling_timeout=long_polling_timeout,
  File "/home/shliamb/Desktop/WORK_FOLDER/chatgpt/myvenv/lib/python3.11/site-packages/telebot/__init__.py", line 1120, in __threaded_polling
    raise e
  File "/home/shliamb/Desktop/WORK_FOLDER/chatgpt/myvenv/lib/python3.11/site-packages/telebot/__init__.py", line 1082, in __threaded_polling
    self.worker_pool.raise_exceptions()
  File "/home/shliamb/Desktop/WORK_FOLDER/chatgpt/myvenv/lib/python3.11/site-packages/telebot/util.py", line 147, in raise_exceptions
    raise self.exception_info
  File "/home/shliamb/Desktop/WORK_FOLDER/chatgpt/myvenv/lib/python3.11/site-packages/telebot/util.py", line 90, in run
    task(*args, **kwargs)
  File "/home/shliamb/Desktop/WORK_FOLDER/chatgpt/myvenv/lib/python3.11/site-packages/telebot/__init__.py", line 6793, in _run_middlewares_and_handler
    result = handler['function'](message)
             ^^^^^^^^^^^^^^^^^^^^^^^^^^^^
  File "/home/shliamb/Desktop/WORK_FOLDER/chatgpt/app/tele_bot.py", line 17, in start
    elif context.message.from_user.first_name:
         ^^^^^^^^^^^^^^^
AttributeError: 'Message' object has no attribute 'message'
2024-01-25 16:46:36,021 - logging_bot - ERROR - Произошла непредвиденная ошибка:
Traceback (most recent call last):
  File "/home/shliamb/Desktop/WORK_FOLDER/chatgpt/app/run_bot.py", line 9, in <module>
    from tele_bot import start_bot
  File "/home/shliamb/Desktop/WORK_FOLDER/chatgpt/app/tele_bot.py", line 47, in <module>
    start_bot = bot.polling()
                ^^^^^^^^^^^^^
  File "/home/shliamb/Desktop/WORK_FOLDER/chatgpt/myvenv/lib/python3.11/site-packages/telebot/__init__.py", line 1045, in polling
    self.__threaded_polling(non_stop=non_stop, interval=interval, timeout=timeout, long_polling_timeout=long_polling_timeout,
  File "/home/shliamb/Desktop/WORK_FOLDER/chatgpt/myvenv/lib/python3.11/site-packages/telebot/__init__.py", line 1120, in __threaded_polling
    raise e
  File "/home/shliamb/Desktop/WORK_FOLDER/chatgpt/myvenv/lib/python3.11/site-packages/telebot/__init__.py", line 1082, in __threaded_polling
    self.worker_pool.raise_exceptions()
  File "/home/shliamb/Desktop/WORK_FOLDER/chatgpt/myvenv/lib/python3.11/site-packages/telebot/util.py", line 147, in raise_exceptions
    raise self.exception_info
  File "/home/shliamb/Desktop/WORK_FOLDER/chatgpt/myvenv/lib/python3.11/site-packages/telebot/util.py", line 90, in run
    task(*args, **kwargs)
  File "/home/shliamb/Desktop/WORK_FOLDER/chatgpt/myvenv/lib/python3.11/site-packages/telebot/__init__.py", line 6793, in _run_middlewares_and_handler
    result = handler['function'](message)
             ^^^^^^^^^^^^^^^^^^^^^^^^^^^^
  File "/home/shliamb/Desktop/WORK_FOLDER/chatgpt/app/tele_bot.py", line 17, in start
    elif context.message.from_user.first_name:
         ^^^^^^^^^^^^^^^
AttributeError: 'Message' object has no attribute 'message'
2024-01-25 16:49:12,993 - logging_bot - ERROR - Произошла непредвиденная ошибка:
Traceback (most recent call last):
  File "/home/shliamb/Desktop/WORK_FOLDER/chatgpt/app/run_bot.py", line 9, in <module>
    from tele_bot import start_bot
  File "/home/shliamb/Desktop/WORK_FOLDER/chatgpt/app/tele_bot.py", line 47, in <module>
    start_bot = bot.polling()
                ^^^^^^^^^^^^^
  File "/home/shliamb/Desktop/WORK_FOLDER/chatgpt/myvenv/lib/python3.11/site-packages/telebot/__init__.py", line 1045, in polling
    self.__threaded_polling(non_stop=non_stop, interval=interval, timeout=timeout, long_polling_timeout=long_polling_timeout,
  File "/home/shliamb/Desktop/WORK_FOLDER/chatgpt/myvenv/lib/python3.11/site-packages/telebot/__init__.py", line 1120, in __threaded_polling
    raise e
  File "/home/shliamb/Desktop/WORK_FOLDER/chatgpt/myvenv/lib/python3.11/site-packages/telebot/__init__.py", line 1082, in __threaded_polling
    self.worker_pool.raise_exceptions()
  File "/home/shliamb/Desktop/WORK_FOLDER/chatgpt/myvenv/lib/python3.11/site-packages/telebot/util.py", line 147, in raise_exceptions
    raise self.exception_info
  File "/home/shliamb/Desktop/WORK_FOLDER/chatgpt/myvenv/lib/python3.11/site-packages/telebot/util.py", line 90, in run
    task(*args, **kwargs)
  File "/home/shliamb/Desktop/WORK_FOLDER/chatgpt/myvenv/lib/python3.11/site-packages/telebot/__init__.py", line 6793, in _run_middlewares_and_handler
    result = handler['function'](message)
             ^^^^^^^^^^^^^^^^^^^^^^^^^^^^
  File "/home/shliamb/Desktop/WORK_FOLDER/chatgpt/app/tele_bot.py", line 17, in start
    elif context.from_user.first_name:
         ^^^^^^^^^^^^^^^
AttributeError: 'Message' object has no attribute 'message'
2024-01-25 17:52:00,304 - logging_bot - ERROR - Произошла непредвиденная ошибка:
Traceback (most recent call last):
  File "/home/shliamb/Desktop/WORK_FOLDER/chatgpt/app/run_bot.py", line 9, in <module>
    from tele_bot import start_bot
  File "/home/shliamb/Desktop/WORK_FOLDER/chatgpt/app/tele_bot.py", line 45, in <module>
    start_bot = bot.polling()
                ^^^^^^^^^^^^^
  File "/home/shliamb/Desktop/WORK_FOLDER/chatgpt/myvenv/lib/python3.11/site-packages/telebot/__init__.py", line 1045, in polling
    self.__threaded_polling(non_stop=non_stop, interval=interval, timeout=timeout, long_polling_timeout=long_polling_timeout,
  File "/home/shliamb/Desktop/WORK_FOLDER/chatgpt/myvenv/lib/python3.11/site-packages/telebot/__init__.py", line 1120, in __threaded_polling
    raise e
  File "/home/shliamb/Desktop/WORK_FOLDER/chatgpt/myvenv/lib/python3.11/site-packages/telebot/__init__.py", line 1082, in __threaded_polling
    self.worker_pool.raise_exceptions()
  File "/home/shliamb/Desktop/WORK_FOLDER/chatgpt/myvenv/lib/python3.11/site-packages/telebot/util.py", line 147, in raise_exceptions
    raise self.exception_info
  File "/home/shliamb/Desktop/WORK_FOLDER/chatgpt/myvenv/lib/python3.11/site-packages/telebot/util.py", line 90, in run
    task(*args, **kwargs)
  File "/home/shliamb/Desktop/WORK_FOLDER/chatgpt/myvenv/lib/python3.11/site-packages/telebot/__init__.py", line 6793, in _run_middlewares_and_handler
    result = handler['function'](message)
             ^^^^^^^^^^^^^^^^^^^^^^^^^^^^
  File "/home/shliamb/Desktop/WORK_FOLDER/chatgpt/app/tele_bot.py", line 31, in start
    add_tele_user(context.from_user.id, context.from_user.username, context.from_user.first_name, context.from_user.last_name)
  File "/home/shliamb/Desktop/WORK_FOLDER/chatgpt/app/worker_db.py", line 23, in add_tele_user
    session.commit()
  File "/home/shliamb/Desktop/WORK_FOLDER/chatgpt/myvenv/lib/python3.11/site-packages/sqlalchemy/orm/session.py", line 1969, in commit
    trans.commit(_to_root=True)
  File "<string>", line 2, in commit
  File "/home/shliamb/Desktop/WORK_FOLDER/chatgpt/myvenv/lib/python3.11/site-packages/sqlalchemy/orm/state_changes.py", line 139, in _go
    ret_value = fn(self, *arg, **kw)
                ^^^^^^^^^^^^^^^^^^^^
  File "/home/shliamb/Desktop/WORK_FOLDER/chatgpt/myvenv/lib/python3.11/site-packages/sqlalchemy/orm/session.py", line 1256, in commit
    self._prepare_impl()
  File "<string>", line 2, in _prepare_impl
  File "/home/shliamb/Desktop/WORK_FOLDER/chatgpt/myvenv/lib/python3.11/site-packages/sqlalchemy/orm/state_changes.py", line 139, in _go
    ret_value = fn(self, *arg, **kw)
                ^^^^^^^^^^^^^^^^^^^^
  File "/home/shliamb/Desktop/WORK_FOLDER/chatgpt/myvenv/lib/python3.11/site-packages/sqlalchemy/orm/session.py", line 1231, in _prepare_impl
    self.session.flush()
  File "/home/shliamb/Desktop/WORK_FOLDER/chatgpt/myvenv/lib/python3.11/site-packages/sqlalchemy/orm/session.py", line 4312, in flush
    self._flush(objects)
  File "/home/shliamb/Desktop/WORK_FOLDER/chatgpt/myvenv/lib/python3.11/site-packages/sqlalchemy/orm/session.py", line 4447, in _flush
    with util.safe_reraise():
  File "/home/shliamb/Desktop/WORK_FOLDER/chatgpt/myvenv/lib/python3.11/site-packages/sqlalchemy/util/langhelpers.py", line 146, in __exit__
    raise exc_value.with_traceback(exc_tb)
  File "/home/shliamb/Desktop/WORK_FOLDER/chatgpt/myvenv/lib/python3.11/site-packages/sqlalchemy/orm/session.py", line 4414, in _flush
    flush_context.finalize_flush_changes()
  File "/home/shliamb/Desktop/WORK_FOLDER/chatgpt/myvenv/lib/python3.11/site-packages/sqlalchemy/orm/unitofwork.py", line 487, in finalize_flush_changes
    self.session._register_persistent(other)
  File "/home/shliamb/Desktop/WORK_FOLDER/chatgpt/myvenv/lib/python3.11/site-packages/sqlalchemy/orm/session.py", line 3313, in _register_persistent
    raise exc.FlushError(
sqlalchemy.orm.exc.FlushError: Instance <ChatGpt at 0x7f80bdbb7290> has a NULL identity key.  If this is an auto-generated value, check that the database table allows generation of new primary key values, and that the mapped Column object is configured to expect these generated values.  Ensure also that this flush() is not occurring at an inappropriate time, such as within a load() event.
2024-01-25 18:31:57,810 - logging_bot - ERROR - Произошла непредвиденная ошибка:
Traceback (most recent call last):
  File "/home/shliamb/Desktop/WORK_FOLDER/chatgpt/app/run_bot.py", line 9, in <module>
    from tele_bot import start_bot
  File "/home/shliamb/Desktop/WORK_FOLDER/chatgpt/app/tele_bot.py", line 63, in <module>
    start_bot = bot.polling()
                ^^^^^^^^^^^^^
  File "/home/shliamb/Desktop/WORK_FOLDER/chatgpt/myvenv/lib/python3.11/site-packages/telebot/__init__.py", line 1045, in polling
    self.__threaded_polling(non_stop=non_stop, interval=interval, timeout=timeout, long_polling_timeout=long_polling_timeout,
  File "/home/shliamb/Desktop/WORK_FOLDER/chatgpt/myvenv/lib/python3.11/site-packages/telebot/__init__.py", line 1120, in __threaded_polling
    raise e
  File "/home/shliamb/Desktop/WORK_FOLDER/chatgpt/myvenv/lib/python3.11/site-packages/telebot/__init__.py", line 1082, in __threaded_polling
    self.worker_pool.raise_exceptions()
  File "/home/shliamb/Desktop/WORK_FOLDER/chatgpt/myvenv/lib/python3.11/site-packages/telebot/util.py", line 147, in raise_exceptions
    raise self.exception_info
  File "/home/shliamb/Desktop/WORK_FOLDER/chatgpt/myvenv/lib/python3.11/site-packages/telebot/util.py", line 90, in run
    task(*args, **kwargs)
  File "/home/shliamb/Desktop/WORK_FOLDER/chatgpt/myvenv/lib/python3.11/site-packages/telebot/__init__.py", line 6793, in _run_middlewares_and_handler
    result = handler['function'](message)
             ^^^^^^^^^^^^^^^^^^^^^^^^^^^^
  File "/home/shliamb/Desktop/WORK_FOLDER/chatgpt/app/tele_bot.py", line 34, in start
    print(added_user_id.user.id)
          ^^^^^^^^^^^^^^^^^^
AttributeError: 'tuple' object has no attribute 'user'
2024-01-25 19:52:54,949 - logging_bot - ERROR - Произошла непредвиденная ошибка:
Traceback (most recent call last):
  File "/home/shliamb/Desktop/WORK_FOLDER/chatgpt/app/run_bot.py", line 9, in <module>
    from tele_bot import start_bot
  File "/home/shliamb/Desktop/WORK_FOLDER/chatgpt/app/tele_bot.py", line 4, in <module>
    from open_ai import first_choice_message, open_ai
ImportError: cannot import name 'first_choice_message' from 'open_ai' (/home/shliamb/Desktop/WORK_FOLDER/chatgpt/app/open_ai.py)
2024-01-25 19:54:29,965 - logging_bot - ERROR - Произошла непредвиденная ошибка:
Traceback (most recent call last):
  File "/home/shliamb/Desktop/WORK_FOLDER/chatgpt/app/run_bot.py", line 9, in <module>
    from tele_bot import start_bot
  File "/home/shliamb/Desktop/WORK_FOLDER/chatgpt/app/tele_bot.py", line 4, in <module>
    from open_ai import first_choice_message, open_ai, first_choice_message
ImportError: cannot import name 'first_choice_message' from 'open_ai' (/home/shliamb/Desktop/WORK_FOLDER/chatgpt/app/open_ai.py)
2024-01-25 19:55:03,152 - logging_bot - ERROR - Произошла непредвиденная ошибка:
Traceback (most recent call last):
  File "/home/shliamb/Desktop/WORK_FOLDER/chatgpt/app/run_bot.py", line 9, in <module>
    from tele_bot import start_bot
  File "/home/shliamb/Desktop/WORK_FOLDER/chatgpt/app/tele_bot.py", line 4, in <module>
    from open_ai import first_choice_message, open_ai
ImportError: cannot import name 'first_choice_message' from 'open_ai' (/home/shliamb/Desktop/WORK_FOLDER/chatgpt/app/open_ai.py)
2024-01-25 20:53:48,761 - logging_bot - ERROR - Произошла непредвиденная ошибка:
Traceback (most recent call last):
  File "/home/shliamb/Desktop/WORK_FOLDER/chatgpt/app/run_bot.py", line 9, in <module>
    from tele_bot import start_bot
  File "/home/shliamb/Desktop/WORK_FOLDER/chatgpt/app/tele_bot.py", line 4, in <module>
    from open_ai import send_message # open_ai, first_choice_message,
    ^^^^^^^^^^^^^^^^^^^^^^^^^^^^^^^^
  File "/home/shliamb/Desktop/WORK_FOLDER/chatgpt/app/open_ai.py", line 68, in <module>
    assistant_reply = send_message(user_input)
                      ^^^^^^^^^^^^^^^^^^^^^^^^
  File "/home/shliamb/Desktop/WORK_FOLDER/chatgpt/app/open_ai.py", line 51, in send_message
    response = openai.ChatCompletion.create(
               ^^^^^^^^^^^^^^^^^^^^^^^^^^^^^
  File "/home/shliamb/Desktop/WORK_FOLDER/chatgpt/myvenv/lib/python3.11/site-packages/openai/lib/_old_api.py", line 39, in __call__
    raise APIRemovedInV1(symbol=self._symbol)
openai.lib._old_api.APIRemovedInV1: 

You tried to access openai.ChatCompletion, but this is no longer supported in openai>=1.0.0 - see the README at https://github.com/openai/openai-python for the API.

You can run `openai migrate` to automatically upgrade your codebase to use the 1.0.0 interface. 

Alternatively, you can pin your installation to the old version, e.g. `pip install openai==0.28`

A detailed migration guide is available here: https://github.com/openai/openai-python/discussions/742

2024-01-25 20:55:50,117 - logging_bot - ERROR - Произошла непредвиденная ошибка:
Traceback (most recent call last):
  File "/home/shliamb/Desktop/WORK_FOLDER/chatgpt/app/run_bot.py", line 9, in <module>
    from tele_bot import start_bot
  File "/home/shliamb/Desktop/WORK_FOLDER/chatgpt/app/tele_bot.py", line 4, in <module>
    from open_ai import open_ai #first_choice_message,
    ^^^^^^^^^^^^^^^^^^^^^^^^^^^
  File "/home/shliamb/Desktop/WORK_FOLDER/chatgpt/app/open_ai.py", line 40, in <module>
    openai.api_key = 'YOUR_API_KEY'
    ^^^^^^
NameError: name 'openai' is not defined
2024-01-25 21:07:38,483 - logging_bot - ERROR - Произошла непредвиденная ошибка:
Traceback (most recent call last):
  File "/home/shliamb/Desktop/WORK_FOLDER/chatgpt/app/run_bot.py", line 9, in <module>
    from tele_bot import start_bot
  File "/home/shliamb/Desktop/WORK_FOLDER/chatgpt/app/tele_bot.py", line 4, in <module>
    from open_ai import main # open_ai first_choice_message,
    ^^^^^^^^^^^^^^^^^^^^^^^^
  File "/home/shliamb/Desktop/WORK_FOLDER/chatgpt/app/open_ai.py", line 24, in <module>
    asyncio.run(main())
                ^^^^^^
TypeError: main() missing 1 required positional argument: 'message'
2024-01-25 21:08:45,427 - logging_bot - ERROR - Произошла непредвиденная ошибка:
Traceback (most recent call last):
  File "/home/shliamb/Desktop/WORK_FOLDER/chatgpt/app/run_bot.py", line 9, in <module>
    from tele_bot import start_bot
  File "/home/shliamb/Desktop/WORK_FOLDER/chatgpt/app/tele_bot.py", line 4, in <module>
    from open_ai import maine # open_ai first_choice_message,
    ^^^^^^^^^^^^^^^^^^^^^^^^^
  File "/home/shliamb/Desktop/WORK_FOLDER/chatgpt/app/open_ai.py", line 24, in <module>
    asyncio.run(main())
                ^^^^
NameError: name 'main' is not defined
2024-01-25 21:09:30,519 - logging_bot - ERROR - Произошла непредвиденная ошибка:
Traceback (most recent call last):
  File "/home/shliamb/Desktop/WORK_FOLDER/chatgpt/app/run_bot.py", line 9, in <module>
    from tele_bot import start_bot
  File "/home/shliamb/Desktop/WORK_FOLDER/chatgpt/app/tele_bot.py", line 4, in <module>
    from open_ai import maine # open_ai first_choice_message,
    ^^^^^^^^^^^^^^^^^^^^^^^^^
  File "/home/shliamb/Desktop/WORK_FOLDER/chatgpt/app/open_ai.py", line 24, in <module>
    asyncio.run(maine())
                ^^^^^^^
TypeError: maine() missing 1 required positional argument: 'message'
2024-01-25 21:13:44,646 - logging_bot - ERROR - Произошла непредвиденная ошибка:
Traceback (most recent call last):
  File "/home/shliamb/Desktop/WORK_FOLDER/chatgpt/app/run_bot.py", line 9, in <module>
    from tele_bot import start_bot
  File "/home/shliamb/Desktop/WORK_FOLDER/chatgpt/app/tele_bot.py", line 62, in <module>
    start_bot = bot.polling()
                ^^^^^^^^^^^^^
  File "/home/shliamb/Desktop/WORK_FOLDER/chatgpt/myvenv/lib/python3.11/site-packages/telebot/__init__.py", line 1045, in polling
    self.__threaded_polling(non_stop=non_stop, interval=interval, timeout=timeout, long_polling_timeout=long_polling_timeout,
  File "/home/shliamb/Desktop/WORK_FOLDER/chatgpt/myvenv/lib/python3.11/site-packages/telebot/__init__.py", line 1120, in __threaded_polling
    raise e
  File "/home/shliamb/Desktop/WORK_FOLDER/chatgpt/myvenv/lib/python3.11/site-packages/telebot/__init__.py", line 1082, in __threaded_polling
    self.worker_pool.raise_exceptions()
  File "/home/shliamb/Desktop/WORK_FOLDER/chatgpt/myvenv/lib/python3.11/site-packages/telebot/util.py", line 147, in raise_exceptions
    raise self.exception_info
  File "/home/shliamb/Desktop/WORK_FOLDER/chatgpt/myvenv/lib/python3.11/site-packages/telebot/util.py", line 90, in run
    task(*args, **kwargs)
  File "/home/shliamb/Desktop/WORK_FOLDER/chatgpt/myvenv/lib/python3.11/site-packages/telebot/__init__.py", line 6793, in _run_middlewares_and_handler
    result = handler['function'](message)
             ^^^^^^^^^^^^^^^^^^^^^^^^^^^^
  File "/home/shliamb/Desktop/WORK_FOLDER/chatgpt/app/tele_bot.py", line 48, in handle_message
    asyncio.run(saar)
  File "/usr/lib/python3.11/asyncio/runners.py", line 190, in run
    return runner.run(main)
           ^^^^^^^^^^^^^^^^
  File "/usr/lib/python3.11/asyncio/runners.py", line 118, in run
    return self._loop.run_until_complete(task)
           ^^^^^^^^^^^^^^^^^^^^^^^^^^^^^^^^^^^
  File "/usr/lib/python3.11/asyncio/base_events.py", line 653, in run_until_complete
    return future.result()
           ^^^^^^^^^^^^^^^
  File "/home/shliamb/Desktop/WORK_FOLDER/chatgpt/app/open_ai.py", line 15, in maine
    stream = await client.chat.completions.create(
             ^^^^^^^^^^^^^^^^^^^^^^^^^^^^^^^^^^^^^
  File "/home/shliamb/Desktop/WORK_FOLDER/chatgpt/myvenv/lib/python3.11/site-packages/openai/resources/chat/completions.py", line 1291, in create
    return await self._post(
           ^^^^^^^^^^^^^^^^^
  File "/home/shliamb/Desktop/WORK_FOLDER/chatgpt/myvenv/lib/python3.11/site-packages/openai/_base_client.py", line 1578, in post
    return await self.request(cast_to, opts, stream=stream, stream_cls=stream_cls)
           ^^^^^^^^^^^^^^^^^^^^^^^^^^^^^^^^^^^^^^^^^^^^^^^^^^^^^^^^^^^^^^^^^^^^^^^
  File "/home/shliamb/Desktop/WORK_FOLDER/chatgpt/myvenv/lib/python3.11/site-packages/openai/_base_client.py", line 1339, in request
    return await self._request(
           ^^^^^^^^^^^^^^^^^^^^
  File "/home/shliamb/Desktop/WORK_FOLDER/chatgpt/myvenv/lib/python3.11/site-packages/openai/_base_client.py", line 1359, in _request
    request = self._build_request(options)
              ^^^^^^^^^^^^^^^^^^^^^^^^^^^^
  File "/home/shliamb/Desktop/WORK_FOLDER/chatgpt/myvenv/lib/python3.11/site-packages/openai/_base_client.py", line 467, in _build_request
    return self._client.build_request(  # pyright: ignore[reportUnknownMemberType]
           ^^^^^^^^^^^^^^^^^^^^^^^^^^^^^^^^^^^^^^^^^^^^^^^^^^^^^^^^^^^^^^^^^^^^^^^
  File "/home/shliamb/Desktop/WORK_FOLDER/chatgpt/myvenv/lib/python3.11/site-packages/httpx/_client.py", line 358, in build_request
    return Request(
           ^^^^^^^^
  File "/home/shliamb/Desktop/WORK_FOLDER/chatgpt/myvenv/lib/python3.11/site-packages/httpx/_models.py", line 338, in __init__
    headers, stream = encode_request(
                      ^^^^^^^^^^^^^^^
  File "/home/shliamb/Desktop/WORK_FOLDER/chatgpt/myvenv/lib/python3.11/site-packages/httpx/_content.py", line 214, in encode_request
    return encode_json(json)
           ^^^^^^^^^^^^^^^^^
  File "/home/shliamb/Desktop/WORK_FOLDER/chatgpt/myvenv/lib/python3.11/site-packages/httpx/_content.py", line 177, in encode_json
    body = json_dumps(json).encode("utf-8")
           ^^^^^^^^^^^^^^^^
  File "/usr/lib/python3.11/json/__init__.py", line 231, in dumps
    return _default_encoder.encode(obj)
           ^^^^^^^^^^^^^^^^^^^^^^^^^^^^
  File "/usr/lib/python3.11/json/encoder.py", line 200, in encode
    chunks = self.iterencode(o, _one_shot=True)
             ^^^^^^^^^^^^^^^^^^^^^^^^^^^^^^^^^^
  File "/usr/lib/python3.11/json/encoder.py", line 258, in iterencode
    return _iterencode(o, 0)
           ^^^^^^^^^^^^^^^^^
  File "/usr/lib/python3.11/json/encoder.py", line 180, in default
    raise TypeError(f'Object of type {o.__class__.__name__} '
TypeError: Object of type Message is not JSON serializable
2024-01-25 21:15:32,040 - httpx - INFO - HTTP Request: POST https://api.openai.com/v1/chat/completions "HTTP/1.1 200 OK"
2024-01-25 21:18:08,166 - httpx - INFO - HTTP Request: POST https://api.openai.com/v1/chat/completions "HTTP/1.1 200 OK"
2024-01-25 21:19:21,136 - openai._base_client - INFO - Retrying request to /chat/completions in 0.859743 seconds
2024-01-25 21:21:15,725 - logging_bot - ERROR - Произошла непредвиденная ошибка:
Traceback (most recent call last):
  File "/home/shliamb/Desktop/WORK_FOLDER/chatgpt/app/run_bot.py", line 9, in <module>
    from tele_bot import start_bot
  File "/home/shliamb/Desktop/WORK_FOLDER/chatgpt/app/tele_bot.py", line 62, in <module>
    start_bot = bot.polling()
                ^^^^^^^^^^^^^
  File "/home/shliamb/Desktop/WORK_FOLDER/chatgpt/myvenv/lib/python3.11/site-packages/telebot/__init__.py", line 1045, in polling
    self.__threaded_polling(non_stop=non_stop, interval=interval, timeout=timeout, long_polling_timeout=long_polling_timeout,
  File "/home/shliamb/Desktop/WORK_FOLDER/chatgpt/myvenv/lib/python3.11/site-packages/telebot/__init__.py", line 1120, in __threaded_polling
    raise e
  File "/home/shliamb/Desktop/WORK_FOLDER/chatgpt/myvenv/lib/python3.11/site-packages/telebot/__init__.py", line 1082, in __threaded_polling
    self.worker_pool.raise_exceptions()
  File "/home/shliamb/Desktop/WORK_FOLDER/chatgpt/myvenv/lib/python3.11/site-packages/telebot/util.py", line 147, in raise_exceptions
    raise self.exception_info
  File "/home/shliamb/Desktop/WORK_FOLDER/chatgpt/myvenv/lib/python3.11/site-packages/telebot/util.py", line 90, in run
    task(*args, **kwargs)
  File "/home/shliamb/Desktop/WORK_FOLDER/chatgpt/myvenv/lib/python3.11/site-packages/telebot/__init__.py", line 6793, in _run_middlewares_and_handler
    result = handler['function'](message)
             ^^^^^^^^^^^^^^^^^^^^^^^^^^^^
  File "/home/shliamb/Desktop/WORK_FOLDER/chatgpt/app/tele_bot.py", line 48, in handle_message
    asyncio.run(saar)
  File "/usr/lib/python3.11/asyncio/runners.py", line 190, in run
    return runner.run(main)
           ^^^^^^^^^^^^^^^^
  File "/usr/lib/python3.11/asyncio/runners.py", line 118, in run
    return self._loop.run_until_complete(task)
           ^^^^^^^^^^^^^^^^^^^^^^^^^^^^^^^^^^^
  File "/usr/lib/python3.11/asyncio/base_events.py", line 653, in run_until_complete
    return future.result()
           ^^^^^^^^^^^^^^^
  File "/home/shliamb/Desktop/WORK_FOLDER/chatgpt/app/open_ai.py", line 16, in main
    stream = await client.chat.completions.create(
             ^^^^^^^^^^^^^^^^^^^^^^^^^^^^^^^^^^^^^
  File "/home/shliamb/Desktop/WORK_FOLDER/chatgpt/myvenv/lib/python3.11/site-packages/openai/resources/chat/completions.py", line 1291, in create
    return await self._post(
           ^^^^^^^^^^^^^^^^^
  File "/home/shliamb/Desktop/WORK_FOLDER/chatgpt/myvenv/lib/python3.11/site-packages/openai/_base_client.py", line 1578, in post
    return await self.request(cast_to, opts, stream=stream, stream_cls=stream_cls)
           ^^^^^^^^^^^^^^^^^^^^^^^^^^^^^^^^^^^^^^^^^^^^^^^^^^^^^^^^^^^^^^^^^^^^^^^
  File "/home/shliamb/Desktop/WORK_FOLDER/chatgpt/myvenv/lib/python3.11/site-packages/openai/_base_client.py", line 1339, in request
    return await self._request(
           ^^^^^^^^^^^^^^^^^^^^
  File "/home/shliamb/Desktop/WORK_FOLDER/chatgpt/myvenv/lib/python3.11/site-packages/openai/_base_client.py", line 1359, in _request
    request = self._build_request(options)
              ^^^^^^^^^^^^^^^^^^^^^^^^^^^^
  File "/home/shliamb/Desktop/WORK_FOLDER/chatgpt/myvenv/lib/python3.11/site-packages/openai/_base_client.py", line 467, in _build_request
    return self._client.build_request(  # pyright: ignore[reportUnknownMemberType]
           ^^^^^^^^^^^^^^^^^^^^^^^^^^^^^^^^^^^^^^^^^^^^^^^^^^^^^^^^^^^^^^^^^^^^^^^
  File "/home/shliamb/Desktop/WORK_FOLDER/chatgpt/myvenv/lib/python3.11/site-packages/httpx/_client.py", line 358, in build_request
    return Request(
           ^^^^^^^^
  File "/home/shliamb/Desktop/WORK_FOLDER/chatgpt/myvenv/lib/python3.11/site-packages/httpx/_models.py", line 338, in __init__
    headers, stream = encode_request(
                      ^^^^^^^^^^^^^^^
  File "/home/shliamb/Desktop/WORK_FOLDER/chatgpt/myvenv/lib/python3.11/site-packages/httpx/_content.py", line 214, in encode_request
    return encode_json(json)
           ^^^^^^^^^^^^^^^^^
  File "/home/shliamb/Desktop/WORK_FOLDER/chatgpt/myvenv/lib/python3.11/site-packages/httpx/_content.py", line 177, in encode_json
    body = json_dumps(json).encode("utf-8")
           ^^^^^^^^^^^^^^^^
  File "/usr/lib/python3.11/json/__init__.py", line 231, in dumps
    return _default_encoder.encode(obj)
           ^^^^^^^^^^^^^^^^^^^^^^^^^^^^
  File "/usr/lib/python3.11/json/encoder.py", line 200, in encode
    chunks = self.iterencode(o, _one_shot=True)
             ^^^^^^^^^^^^^^^^^^^^^^^^^^^^^^^^^^
  File "/usr/lib/python3.11/json/encoder.py", line 258, in iterencode
    return _iterencode(o, 0)
           ^^^^^^^^^^^^^^^^^
  File "/usr/lib/python3.11/json/encoder.py", line 180, in default
    raise TypeError(f'Object of type {o.__class__.__name__} '
TypeError: Object of type set is not JSON serializable
2024-01-25 21:22:56,693 - httpx - INFO - HTTP Request: POST https://api.openai.com/v1/chat/completions "HTTP/1.1 200 OK"
2024-01-25 21:24:59,266 - logging_bot - ERROR - Произошла непредвиденная ошибка:
Traceback (most recent call last):
  File "/home/shliamb/Desktop/WORK_FOLDER/chatgpt/app/run_bot.py", line 9, in <module>
    from tele_bot import start_bot
  File "/home/shliamb/Desktop/WORK_FOLDER/chatgpt/app/tele_bot.py", line 61, in <module>
    start_bot = bot.polling()
                ^^^^^^^^^^^^^
  File "/home/shliamb/Desktop/WORK_FOLDER/chatgpt/myvenv/lib/python3.11/site-packages/telebot/__init__.py", line 1045, in polling
    self.__threaded_polling(non_stop=non_stop, interval=interval, timeout=timeout, long_polling_timeout=long_polling_timeout,
  File "/home/shliamb/Desktop/WORK_FOLDER/chatgpt/myvenv/lib/python3.11/site-packages/telebot/__init__.py", line 1120, in __threaded_polling
    raise e
  File "/home/shliamb/Desktop/WORK_FOLDER/chatgpt/myvenv/lib/python3.11/site-packages/telebot/__init__.py", line 1082, in __threaded_polling
    self.worker_pool.raise_exceptions()
  File "/home/shliamb/Desktop/WORK_FOLDER/chatgpt/myvenv/lib/python3.11/site-packages/telebot/util.py", line 147, in raise_exceptions
    raise self.exception_info
  File "/home/shliamb/Desktop/WORK_FOLDER/chatgpt/myvenv/lib/python3.11/site-packages/telebot/util.py", line 90, in run
    task(*args, **kwargs)
  File "/home/shliamb/Desktop/WORK_FOLDER/chatgpt/myvenv/lib/python3.11/site-packages/telebot/__init__.py", line 6793, in _run_middlewares_and_handler
    result = handler['function'](message)
             ^^^^^^^^^^^^^^^^^^^^^^^^^^^^
  File "/home/shliamb/Desktop/WORK_FOLDER/chatgpt/app/tele_bot.py", line 47, in handle_message
    asyncio.run(main(message_text))
  File "/usr/lib/python3.11/asyncio/runners.py", line 190, in run
    return runner.run(main)
           ^^^^^^^^^^^^^^^^
  File "/usr/lib/python3.11/asyncio/runners.py", line 118, in run
    return self._loop.run_until_complete(task)
           ^^^^^^^^^^^^^^^^^^^^^^^^^^^^^^^^^^^
  File "/usr/lib/python3.11/asyncio/base_events.py", line 653, in run_until_complete
    return future.result()
           ^^^^^^^^^^^^^^^
  File "/home/shliamb/Desktop/WORK_FOLDER/chatgpt/app/open_ai.py", line 16, in main
    stream = await client.chat.completions.create(
             ^^^^^^^^^^^^^^^^^^^^^^^^^^^^^^^^^^^^^
  File "/home/shliamb/Desktop/WORK_FOLDER/chatgpt/myvenv/lib/python3.11/site-packages/openai/resources/chat/completions.py", line 1291, in create
    return await self._post(
           ^^^^^^^^^^^^^^^^^
  File "/home/shliamb/Desktop/WORK_FOLDER/chatgpt/myvenv/lib/python3.11/site-packages/openai/_base_client.py", line 1578, in post
    return await self.request(cast_to, opts, stream=stream, stream_cls=stream_cls)
           ^^^^^^^^^^^^^^^^^^^^^^^^^^^^^^^^^^^^^^^^^^^^^^^^^^^^^^^^^^^^^^^^^^^^^^^
  File "/home/shliamb/Desktop/WORK_FOLDER/chatgpt/myvenv/lib/python3.11/site-packages/openai/_base_client.py", line 1339, in request
    return await self._request(
           ^^^^^^^^^^^^^^^^^^^^
  File "/home/shliamb/Desktop/WORK_FOLDER/chatgpt/myvenv/lib/python3.11/site-packages/openai/_base_client.py", line 1359, in _request
    request = self._build_request(options)
              ^^^^^^^^^^^^^^^^^^^^^^^^^^^^
  File "/home/shliamb/Desktop/WORK_FOLDER/chatgpt/myvenv/lib/python3.11/site-packages/openai/_base_client.py", line 467, in _build_request
    return self._client.build_request(  # pyright: ignore[reportUnknownMemberType]
           ^^^^^^^^^^^^^^^^^^^^^^^^^^^^^^^^^^^^^^^^^^^^^^^^^^^^^^^^^^^^^^^^^^^^^^^
  File "/home/shliamb/Desktop/WORK_FOLDER/chatgpt/myvenv/lib/python3.11/site-packages/httpx/_client.py", line 358, in build_request
    return Request(
           ^^^^^^^^
  File "/home/shliamb/Desktop/WORK_FOLDER/chatgpt/myvenv/lib/python3.11/site-packages/httpx/_models.py", line 338, in __init__
    headers, stream = encode_request(
                      ^^^^^^^^^^^^^^^
  File "/home/shliamb/Desktop/WORK_FOLDER/chatgpt/myvenv/lib/python3.11/site-packages/httpx/_content.py", line 214, in encode_request
    return encode_json(json)
           ^^^^^^^^^^^^^^^^^
  File "/home/shliamb/Desktop/WORK_FOLDER/chatgpt/myvenv/lib/python3.11/site-packages/httpx/_content.py", line 177, in encode_json
    body = json_dumps(json).encode("utf-8")
           ^^^^^^^^^^^^^^^^
  File "/usr/lib/python3.11/json/__init__.py", line 231, in dumps
    return _default_encoder.encode(obj)
           ^^^^^^^^^^^^^^^^^^^^^^^^^^^^
  File "/usr/lib/python3.11/json/encoder.py", line 200, in encode
    chunks = self.iterencode(o, _one_shot=True)
             ^^^^^^^^^^^^^^^^^^^^^^^^^^^^^^^^^^
  File "/usr/lib/python3.11/json/encoder.py", line 258, in iterencode
    return _iterencode(o, 0)
           ^^^^^^^^^^^^^^^^^
  File "/usr/lib/python3.11/json/encoder.py", line 180, in default
    raise TypeError(f'Object of type {o.__class__.__name__} '
TypeError: Object of type set is not JSON serializable
2024-01-25 21:27:01,920 - logging_bot - ERROR - Произошла непредвиденная ошибка:
Traceback (most recent call last):
  File "/home/shliamb/Desktop/WORK_FOLDER/chatgpt/app/run_bot.py", line 9, in <module>
    from tele_bot import start_bot
  File "/home/shliamb/Desktop/WORK_FOLDER/chatgpt/app/tele_bot.py", line 61, in <module>
    start_bot = bot.polling()
                ^^^^^^^^^^^^^
  File "/home/shliamb/Desktop/WORK_FOLDER/chatgpt/myvenv/lib/python3.11/site-packages/telebot/__init__.py", line 1045, in polling
    self.__threaded_polling(non_stop=non_stop, interval=interval, timeout=timeout, long_polling_timeout=long_polling_timeout,
  File "/home/shliamb/Desktop/WORK_FOLDER/chatgpt/myvenv/lib/python3.11/site-packages/telebot/__init__.py", line 1120, in __threaded_polling
    raise e
  File "/home/shliamb/Desktop/WORK_FOLDER/chatgpt/myvenv/lib/python3.11/site-packages/telebot/__init__.py", line 1082, in __threaded_polling
    self.worker_pool.raise_exceptions()
  File "/home/shliamb/Desktop/WORK_FOLDER/chatgpt/myvenv/lib/python3.11/site-packages/telebot/util.py", line 147, in raise_exceptions
    raise self.exception_info
  File "/home/shliamb/Desktop/WORK_FOLDER/chatgpt/myvenv/lib/python3.11/site-packages/telebot/util.py", line 90, in run
    task(*args, **kwargs)
  File "/home/shliamb/Desktop/WORK_FOLDER/chatgpt/myvenv/lib/python3.11/site-packages/telebot/__init__.py", line 6793, in _run_middlewares_and_handler
    result = handler['function'](message)
             ^^^^^^^^^^^^^^^^^^^^^^^^^^^^
  File "/home/shliamb/Desktop/WORK_FOLDER/chatgpt/app/tele_bot.py", line 47, in handle_message
    asyncio.run(main(message_text))
  File "/usr/lib/python3.11/asyncio/runners.py", line 190, in run
    return runner.run(main)
           ^^^^^^^^^^^^^^^^
  File "/usr/lib/python3.11/asyncio/runners.py", line 118, in run
    return self._loop.run_until_complete(task)
           ^^^^^^^^^^^^^^^^^^^^^^^^^^^^^^^^^^^
  File "/usr/lib/python3.11/asyncio/base_events.py", line 653, in run_until_complete
    return future.result()
           ^^^^^^^^^^^^^^^
  File "/home/shliamb/Desktop/WORK_FOLDER/chatgpt/app/open_ai.py", line 16, in main
    stream = await client.chat.completions.create(
             ^^^^^^^^^^^^^^^^^^^^^^^^^^^^^^^^^^^^^
  File "/home/shliamb/Desktop/WORK_FOLDER/chatgpt/myvenv/lib/python3.11/site-packages/openai/resources/chat/completions.py", line 1291, in create
    return await self._post(
           ^^^^^^^^^^^^^^^^^
  File "/home/shliamb/Desktop/WORK_FOLDER/chatgpt/myvenv/lib/python3.11/site-packages/openai/_base_client.py", line 1578, in post
    return await self.request(cast_to, opts, stream=stream, stream_cls=stream_cls)
           ^^^^^^^^^^^^^^^^^^^^^^^^^^^^^^^^^^^^^^^^^^^^^^^^^^^^^^^^^^^^^^^^^^^^^^^
  File "/home/shliamb/Desktop/WORK_FOLDER/chatgpt/myvenv/lib/python3.11/site-packages/openai/_base_client.py", line 1339, in request
    return await self._request(
           ^^^^^^^^^^^^^^^^^^^^
  File "/home/shliamb/Desktop/WORK_FOLDER/chatgpt/myvenv/lib/python3.11/site-packages/openai/_base_client.py", line 1359, in _request
    request = self._build_request(options)
              ^^^^^^^^^^^^^^^^^^^^^^^^^^^^
  File "/home/shliamb/Desktop/WORK_FOLDER/chatgpt/myvenv/lib/python3.11/site-packages/openai/_base_client.py", line 467, in _build_request
    return self._client.build_request(  # pyright: ignore[reportUnknownMemberType]
           ^^^^^^^^^^^^^^^^^^^^^^^^^^^^^^^^^^^^^^^^^^^^^^^^^^^^^^^^^^^^^^^^^^^^^^^
  File "/home/shliamb/Desktop/WORK_FOLDER/chatgpt/myvenv/lib/python3.11/site-packages/httpx/_client.py", line 358, in build_request
    return Request(
           ^^^^^^^^
  File "/home/shliamb/Desktop/WORK_FOLDER/chatgpt/myvenv/lib/python3.11/site-packages/httpx/_models.py", line 338, in __init__
    headers, stream = encode_request(
                      ^^^^^^^^^^^^^^^
  File "/home/shliamb/Desktop/WORK_FOLDER/chatgpt/myvenv/lib/python3.11/site-packages/httpx/_content.py", line 214, in encode_request
    return encode_json(json)
           ^^^^^^^^^^^^^^^^^
  File "/home/shliamb/Desktop/WORK_FOLDER/chatgpt/myvenv/lib/python3.11/site-packages/httpx/_content.py", line 177, in encode_json
    body = json_dumps(json).encode("utf-8")
           ^^^^^^^^^^^^^^^^
  File "/usr/lib/python3.11/json/__init__.py", line 231, in dumps
    return _default_encoder.encode(obj)
           ^^^^^^^^^^^^^^^^^^^^^^^^^^^^
  File "/usr/lib/python3.11/json/encoder.py", line 200, in encode
    chunks = self.iterencode(o, _one_shot=True)
             ^^^^^^^^^^^^^^^^^^^^^^^^^^^^^^^^^^
  File "/usr/lib/python3.11/json/encoder.py", line 258, in iterencode
    return _iterencode(o, 0)
           ^^^^^^^^^^^^^^^^^
  File "/usr/lib/python3.11/json/encoder.py", line 180, in default
    raise TypeError(f'Object of type {o.__class__.__name__} '
TypeError: Object of type Message is not JSON serializable
2024-01-25 21:28:13,658 - logging_bot - ERROR - Произошла непредвиденная ошибка:
Traceback (most recent call last):
  File "/home/shliamb/Desktop/WORK_FOLDER/chatgpt/app/run_bot.py", line 9, in <module>
    from tele_bot import start_bot
  File "/home/shliamb/Desktop/WORK_FOLDER/chatgpt/app/tele_bot.py", line 61, in <module>
    start_bot = bot.polling()
                ^^^^^^^^^^^^^
  File "/home/shliamb/Desktop/WORK_FOLDER/chatgpt/myvenv/lib/python3.11/site-packages/telebot/__init__.py", line 1045, in polling
    self.__threaded_polling(non_stop=non_stop, interval=interval, timeout=timeout, long_polling_timeout=long_polling_timeout,
  File "/home/shliamb/Desktop/WORK_FOLDER/chatgpt/myvenv/lib/python3.11/site-packages/telebot/__init__.py", line 1120, in __threaded_polling
    raise e
  File "/home/shliamb/Desktop/WORK_FOLDER/chatgpt/myvenv/lib/python3.11/site-packages/telebot/__init__.py", line 1082, in __threaded_polling
    self.worker_pool.raise_exceptions()
  File "/home/shliamb/Desktop/WORK_FOLDER/chatgpt/myvenv/lib/python3.11/site-packages/telebot/util.py", line 147, in raise_exceptions
    raise self.exception_info
  File "/home/shliamb/Desktop/WORK_FOLDER/chatgpt/myvenv/lib/python3.11/site-packages/telebot/util.py", line 90, in run
    task(*args, **kwargs)
  File "/home/shliamb/Desktop/WORK_FOLDER/chatgpt/myvenv/lib/python3.11/site-packages/telebot/__init__.py", line 6793, in _run_middlewares_and_handler
    result = handler['function'](message)
             ^^^^^^^^^^^^^^^^^^^^^^^^^^^^
  File "/home/shliamb/Desktop/WORK_FOLDER/chatgpt/app/tele_bot.py", line 47, in handle_message
    asyncio.run(main(message_text))
  File "/usr/lib/python3.11/asyncio/runners.py", line 190, in run
    return runner.run(main)
           ^^^^^^^^^^^^^^^^
  File "/usr/lib/python3.11/asyncio/runners.py", line 118, in run
    return self._loop.run_until_complete(task)
           ^^^^^^^^^^^^^^^^^^^^^^^^^^^^^^^^^^^
  File "/usr/lib/python3.11/asyncio/base_events.py", line 653, in run_until_complete
    return future.result()
           ^^^^^^^^^^^^^^^
  File "/home/shliamb/Desktop/WORK_FOLDER/chatgpt/app/open_ai.py", line 23, in main
    async for chunk in stream:
                       ^^^^^^
NameError: name 'stream' is not defined
2024-01-25 21:29:11,059 - logging_bot - ERROR - Произошла непредвиденная ошибка:
Traceback (most recent call last):
  File "/home/shliamb/Desktop/WORK_FOLDER/chatgpt/app/run_bot.py", line 9, in <module>
    from tele_bot import start_bot
  File "/home/shliamb/Desktop/WORK_FOLDER/chatgpt/app/tele_bot.py", line 61, in <module>
    start_bot = bot.polling()
                ^^^^^^^^^^^^^
  File "/home/shliamb/Desktop/WORK_FOLDER/chatgpt/myvenv/lib/python3.11/site-packages/telebot/__init__.py", line 1045, in polling
    self.__threaded_polling(non_stop=non_stop, interval=interval, timeout=timeout, long_polling_timeout=long_polling_timeout,
  File "/home/shliamb/Desktop/WORK_FOLDER/chatgpt/myvenv/lib/python3.11/site-packages/telebot/__init__.py", line 1120, in __threaded_polling
    raise e
  File "/home/shliamb/Desktop/WORK_FOLDER/chatgpt/myvenv/lib/python3.11/site-packages/telebot/__init__.py", line 1082, in __threaded_polling
    self.worker_pool.raise_exceptions()
  File "/home/shliamb/Desktop/WORK_FOLDER/chatgpt/myvenv/lib/python3.11/site-packages/telebot/util.py", line 147, in raise_exceptions
    raise self.exception_info
  File "/home/shliamb/Desktop/WORK_FOLDER/chatgpt/myvenv/lib/python3.11/site-packages/telebot/util.py", line 90, in run
    task(*args, **kwargs)
  File "/home/shliamb/Desktop/WORK_FOLDER/chatgpt/myvenv/lib/python3.11/site-packages/telebot/__init__.py", line 6793, in _run_middlewares_and_handler
    result = handler['function'](message)
             ^^^^^^^^^^^^^^^^^^^^^^^^^^^^
  File "/home/shliamb/Desktop/WORK_FOLDER/chatgpt/app/tele_bot.py", line 47, in handle_message
    asyncio.run(main(message_text))
  File "/usr/lib/python3.11/asyncio/runners.py", line 190, in run
    return runner.run(main)
           ^^^^^^^^^^^^^^^^
  File "/usr/lib/python3.11/asyncio/runners.py", line 118, in run
    return self._loop.run_until_complete(task)
           ^^^^^^^^^^^^^^^^^^^^^^^^^^^^^^^^^^^
  File "/usr/lib/python3.11/asyncio/base_events.py", line 653, in run_until_complete
    return future.result()
           ^^^^^^^^^^^^^^^
  File "/home/shliamb/Desktop/WORK_FOLDER/chatgpt/app/open_ai.py", line 24, in main
    async for chunk in stream:
                       ^^^^^^
NameError: name 'stream' is not defined
2024-01-25 21:31:23,567 - logging_bot - ERROR - Произошла непредвиденная ошибка:
Traceback (most recent call last):
  File "/home/shliamb/Desktop/WORK_FOLDER/chatgpt/app/run_bot.py", line 9, in <module>
    from tele_bot import start_bot
  File "/home/shliamb/Desktop/WORK_FOLDER/chatgpt/app/tele_bot.py", line 61, in <module>
    start_bot = bot.polling()
                ^^^^^^^^^^^^^
  File "/home/shliamb/Desktop/WORK_FOLDER/chatgpt/myvenv/lib/python3.11/site-packages/telebot/__init__.py", line 1045, in polling
    self.__threaded_polling(non_stop=non_stop, interval=interval, timeout=timeout, long_polling_timeout=long_polling_timeout,
  File "/home/shliamb/Desktop/WORK_FOLDER/chatgpt/myvenv/lib/python3.11/site-packages/telebot/__init__.py", line 1120, in __threaded_polling
    raise e
  File "/home/shliamb/Desktop/WORK_FOLDER/chatgpt/myvenv/lib/python3.11/site-packages/telebot/__init__.py", line 1082, in __threaded_polling
    self.worker_pool.raise_exceptions()
  File "/home/shliamb/Desktop/WORK_FOLDER/chatgpt/myvenv/lib/python3.11/site-packages/telebot/util.py", line 147, in raise_exceptions
    raise self.exception_info
  File "/home/shliamb/Desktop/WORK_FOLDER/chatgpt/myvenv/lib/python3.11/site-packages/telebot/util.py", line 90, in run
    task(*args, **kwargs)
  File "/home/shliamb/Desktop/WORK_FOLDER/chatgpt/myvenv/lib/python3.11/site-packages/telebot/__init__.py", line 6793, in _run_middlewares_and_handler
    result = handler['function'](message)
             ^^^^^^^^^^^^^^^^^^^^^^^^^^^^
  File "/home/shliamb/Desktop/WORK_FOLDER/chatgpt/app/tele_bot.py", line 47, in handle_message
    asyncio.run(main(message_text))
  File "/usr/lib/python3.11/asyncio/runners.py", line 190, in run
    return runner.run(main)
           ^^^^^^^^^^^^^^^^
  File "/usr/lib/python3.11/asyncio/runners.py", line 118, in run
    return self._loop.run_until_complete(task)
           ^^^^^^^^^^^^^^^^^^^^^^^^^^^^^^^^^^^
  File "/usr/lib/python3.11/asyncio/base_events.py", line 653, in run_until_complete
    return future.result()
           ^^^^^^^^^^^^^^^
  File "/home/shliamb/Desktop/WORK_FOLDER/chatgpt/app/open_ai.py", line 15, in main
    user_content = [message.text for message in message_text]
                   ^^^^^^^^^^^^^^^^^^^^^^^^^^^^^^^^^^^^^^^^^^
TypeError: 'Message' object is not iterable
2024-01-25 21:31:56,944 - logging_bot - ERROR - Произошла непредвиденная ошибка:
Traceback (most recent call last):
  File "/home/shliamb/Desktop/WORK_FOLDER/chatgpt/app/run_bot.py", line 9, in <module>
    from tele_bot import start_bot
  File "/home/shliamb/Desktop/WORK_FOLDER/chatgpt/app/tele_bot.py", line 61, in <module>
    start_bot = bot.polling()
                ^^^^^^^^^^^^^
  File "/home/shliamb/Desktop/WORK_FOLDER/chatgpt/myvenv/lib/python3.11/site-packages/telebot/__init__.py", line 1045, in polling
    self.__threaded_polling(non_stop=non_stop, interval=interval, timeout=timeout, long_polling_timeout=long_polling_timeout,
  File "/home/shliamb/Desktop/WORK_FOLDER/chatgpt/myvenv/lib/python3.11/site-packages/telebot/__init__.py", line 1120, in __threaded_polling
    raise e
  File "/home/shliamb/Desktop/WORK_FOLDER/chatgpt/myvenv/lib/python3.11/site-packages/telebot/__init__.py", line 1082, in __threaded_polling
    self.worker_pool.raise_exceptions()
  File "/home/shliamb/Desktop/WORK_FOLDER/chatgpt/myvenv/lib/python3.11/site-packages/telebot/util.py", line 147, in raise_exceptions
    raise self.exception_info
  File "/home/shliamb/Desktop/WORK_FOLDER/chatgpt/myvenv/lib/python3.11/site-packages/telebot/util.py", line 90, in run
    task(*args, **kwargs)
  File "/home/shliamb/Desktop/WORK_FOLDER/chatgpt/myvenv/lib/python3.11/site-packages/telebot/__init__.py", line 6793, in _run_middlewares_and_handler
    result = handler['function'](message)
             ^^^^^^^^^^^^^^^^^^^^^^^^^^^^
  File "/home/shliamb/Desktop/WORK_FOLDER/chatgpt/app/tele_bot.py", line 47, in handle_message
    asyncio.run(main(message_text))
  File "/usr/lib/python3.11/asyncio/runners.py", line 190, in run
    return runner.run(main)
           ^^^^^^^^^^^^^^^^
  File "/usr/lib/python3.11/asyncio/runners.py", line 118, in run
    return self._loop.run_until_complete(task)
           ^^^^^^^^^^^^^^^^^^^^^^^^^^^^^^^^^^^
  File "/usr/lib/python3.11/asyncio/base_events.py", line 653, in run_until_complete
    return future.result()
           ^^^^^^^^^^^^^^^
  File "/home/shliamb/Desktop/WORK_FOLDER/chatgpt/app/open_ai.py", line 15, in main
    user_content = [message.text for message in message_text]
                   ^^^^^^^^^^^^^^^^^^^^^^^^^^^^^^^^^^^^^^^^^^
TypeError: 'Message' object is not iterable
2024-01-25 21:32:39,222 - logging_bot - ERROR - Произошла непредвиденная ошибка:
Traceback (most recent call last):
  File "/home/shliamb/Desktop/WORK_FOLDER/chatgpt/app/run_bot.py", line 9, in <module>
    from tele_bot import start_bot
  File "/home/shliamb/Desktop/WORK_FOLDER/chatgpt/app/tele_bot.py", line 61, in <module>
    start_bot = bot.polling()
                ^^^^^^^^^^^^^
  File "/home/shliamb/Desktop/WORK_FOLDER/chatgpt/myvenv/lib/python3.11/site-packages/telebot/__init__.py", line 1045, in polling
    self.__threaded_polling(non_stop=non_stop, interval=interval, timeout=timeout, long_polling_timeout=long_polling_timeout,
  File "/home/shliamb/Desktop/WORK_FOLDER/chatgpt/myvenv/lib/python3.11/site-packages/telebot/__init__.py", line 1120, in __threaded_polling
    raise e
  File "/home/shliamb/Desktop/WORK_FOLDER/chatgpt/myvenv/lib/python3.11/site-packages/telebot/__init__.py", line 1082, in __threaded_polling
    self.worker_pool.raise_exceptions()
  File "/home/shliamb/Desktop/WORK_FOLDER/chatgpt/myvenv/lib/python3.11/site-packages/telebot/util.py", line 147, in raise_exceptions
    raise self.exception_info
  File "/home/shliamb/Desktop/WORK_FOLDER/chatgpt/myvenv/lib/python3.11/site-packages/telebot/util.py", line 90, in run
    task(*args, **kwargs)
  File "/home/shliamb/Desktop/WORK_FOLDER/chatgpt/myvenv/lib/python3.11/site-packages/telebot/__init__.py", line 6793, in _run_middlewares_and_handler
    result = handler['function'](message)
             ^^^^^^^^^^^^^^^^^^^^^^^^^^^^
  File "/home/shliamb/Desktop/WORK_FOLDER/chatgpt/app/tele_bot.py", line 47, in handle_message
    asyncio.run(main(message_text))
  File "/usr/lib/python3.11/asyncio/runners.py", line 190, in run
    return runner.run(main)
           ^^^^^^^^^^^^^^^^
  File "/usr/lib/python3.11/asyncio/runners.py", line 118, in run
    return self._loop.run_until_complete(task)
           ^^^^^^^^^^^^^^^^^^^^^^^^^^^^^^^^^^^
  File "/usr/lib/python3.11/asyncio/base_events.py", line 653, in run_until_complete
    return future.result()
           ^^^^^^^^^^^^^^^
  File "/home/shliamb/Desktop/WORK_FOLDER/chatgpt/app/open_ai.py", line 15, in main
    user_content = [messager.text for messager in message_text]
                   ^^^^^^^^^^^^^^^^^^^^^^^^^^^^^^^^^^^^^^^^^^^^
TypeError: 'Message' object is not iterable
2024-01-25 21:37:09,635 - httpx - INFO - HTTP Request: POST https://api.openai.com/v1/chat/completions "HTTP/1.1 200 OK"
2024-01-25 21:38:14,964 - logging_bot - ERROR - Произошла непредвиденная ошибка:
Traceback (most recent call last):
  File "/home/shliamb/Desktop/WORK_FOLDER/chatgpt/app/run_bot.py", line 9, in <module>
    from tele_bot import start_bot
  File "/home/shliamb/Desktop/WORK_FOLDER/chatgpt/app/tele_bot.py", line 61, in <module>
    start_bot = bot.polling()
                ^^^^^^^^^^^^^
  File "/home/shliamb/Desktop/WORK_FOLDER/chatgpt/myvenv/lib/python3.11/site-packages/telebot/__init__.py", line 1045, in polling
    self.__threaded_polling(non_stop=non_stop, interval=interval, timeout=timeout, long_polling_timeout=long_polling_timeout,
  File "/home/shliamb/Desktop/WORK_FOLDER/chatgpt/myvenv/lib/python3.11/site-packages/telebot/__init__.py", line 1120, in __threaded_polling
    raise e
  File "/home/shliamb/Desktop/WORK_FOLDER/chatgpt/myvenv/lib/python3.11/site-packages/telebot/__init__.py", line 1082, in __threaded_polling
    self.worker_pool.raise_exceptions()
  File "/home/shliamb/Desktop/WORK_FOLDER/chatgpt/myvenv/lib/python3.11/site-packages/telebot/util.py", line 147, in raise_exceptions
    raise self.exception_info
  File "/home/shliamb/Desktop/WORK_FOLDER/chatgpt/myvenv/lib/python3.11/site-packages/telebot/util.py", line 90, in run
    task(*args, **kwargs)
  File "/home/shliamb/Desktop/WORK_FOLDER/chatgpt/myvenv/lib/python3.11/site-packages/telebot/__init__.py", line 6793, in _run_middlewares_and_handler
    result = handler['function'](message)
             ^^^^^^^^^^^^^^^^^^^^^^^^^^^^
TypeError: handle_message() takes 0 positional arguments but 1 was given
2024-01-25 21:40:01,545 - logging_bot - ERROR - Произошла непредвиденная ошибка:
Traceback (most recent call last):
  File "/home/shliamb/Desktop/WORK_FOLDER/chatgpt/app/run_bot.py", line 9, in <module>
    from tele_bot import start_bot
  File "/home/shliamb/Desktop/WORK_FOLDER/chatgpt/app/tele_bot.py", line 61, in <module>
    start_bot = bot.polling()
                ^^^^^^^^^^^^^
  File "/home/shliamb/Desktop/WORK_FOLDER/chatgpt/myvenv/lib/python3.11/site-packages/telebot/__init__.py", line 1045, in polling
    self.__threaded_polling(non_stop=non_stop, interval=interval, timeout=timeout, long_polling_timeout=long_polling_timeout,
  File "/home/shliamb/Desktop/WORK_FOLDER/chatgpt/myvenv/lib/python3.11/site-packages/telebot/__init__.py", line 1120, in __threaded_polling
    raise e
  File "/home/shliamb/Desktop/WORK_FOLDER/chatgpt/myvenv/lib/python3.11/site-packages/telebot/__init__.py", line 1082, in __threaded_polling
    self.worker_pool.raise_exceptions()
  File "/home/shliamb/Desktop/WORK_FOLDER/chatgpt/myvenv/lib/python3.11/site-packages/telebot/util.py", line 147, in raise_exceptions
    raise self.exception_info
  File "/home/shliamb/Desktop/WORK_FOLDER/chatgpt/myvenv/lib/python3.11/site-packages/telebot/util.py", line 90, in run
    task(*args, **kwargs)
  File "/home/shliamb/Desktop/WORK_FOLDER/chatgpt/myvenv/lib/python3.11/site-packages/telebot/__init__.py", line 6793, in _run_middlewares_and_handler
    result = handler['function'](message)
             ^^^^^^^^^^^^^^^^^^^^^^^^^^^^
TypeError: handle_message() takes 0 positional arguments but 1 was given
2024-01-25 22:27:36,313 - logging_bot - ERROR - Произошла непредвиденная ошибка:
Traceback (most recent call last):
  File "/home/shliamb/Desktop/WORK_FOLDER/chatgpt/app/run_bot.py", line 9, in <module>
    from tele_bot import start_bot
  File "/home/shliamb/Desktop/WORK_FOLDER/chatgpt/app/tele_bot.py", line 4, in <module>
    from open_ai import main # open_ai first_choice_message,
    ^^^^^^^^^^^^^^^^^^^^^^^^
  File "/home/shliamb/Desktop/WORK_FOLDER/chatgpt/app/open_ai.py", line 4, in <module>
    from tele_bot import text
ImportError: cannot import name 'text' from partially initialized module 'tele_bot' (most likely due to a circular import) (/home/shliamb/Desktop/WORK_FOLDER/chatgpt/app/tele_bot.py)
2024-01-25 22:32:58,472 - logging_bot - ERROR - Произошла непредвиденная ошибка:
Traceback (most recent call last):
  File "/home/shliamb/Desktop/WORK_FOLDER/chatgpt/app/run_bot.py", line 9, in <module>
    from tele_bot import start_bot
  File "/home/shliamb/Desktop/WORK_FOLDER/chatgpt/app/tele_bot.py", line 61, in <module>
    start_bot = bot.polling()
                ^^^^^^^^^^^^^
  File "/home/shliamb/Desktop/WORK_FOLDER/chatgpt/myvenv/lib/python3.11/site-packages/telebot/__init__.py", line 1045, in polling
    self.__threaded_polling(non_stop=non_stop, interval=interval, timeout=timeout, long_polling_timeout=long_polling_timeout,
  File "/home/shliamb/Desktop/WORK_FOLDER/chatgpt/myvenv/lib/python3.11/site-packages/telebot/__init__.py", line 1120, in __threaded_polling
    raise e
  File "/home/shliamb/Desktop/WORK_FOLDER/chatgpt/myvenv/lib/python3.11/site-packages/telebot/__init__.py", line 1082, in __threaded_polling
    self.worker_pool.raise_exceptions()
  File "/home/shliamb/Desktop/WORK_FOLDER/chatgpt/myvenv/lib/python3.11/site-packages/telebot/util.py", line 147, in raise_exceptions
    raise self.exception_info
  File "/home/shliamb/Desktop/WORK_FOLDER/chatgpt/myvenv/lib/python3.11/site-packages/telebot/util.py", line 90, in run
    task(*args, **kwargs)
  File "/home/shliamb/Desktop/WORK_FOLDER/chatgpt/myvenv/lib/python3.11/site-packages/telebot/__init__.py", line 6793, in _run_middlewares_and_handler
    result = handler['function'](message)
             ^^^^^^^^^^^^^^^^^^^^^^^^^^^^
  File "/home/shliamb/Desktop/WORK_FOLDER/chatgpt/app/tele_bot.py", line 47, in handle_message
    asyncio.run(main(message))
  File "/usr/lib/python3.11/asyncio/runners.py", line 190, in run
    return runner.run(main)
           ^^^^^^^^^^^^^^^^
  File "/usr/lib/python3.11/asyncio/runners.py", line 118, in run
    return self._loop.run_until_complete(task)
           ^^^^^^^^^^^^^^^^^^^^^^^^^^^^^^^^^^^
  File "/usr/lib/python3.11/asyncio/base_events.py", line 653, in run_until_complete
    return future.result()
           ^^^^^^^^^^^^^^^
  File "/home/shliamb/Desktop/WORK_FOLDER/chatgpt/app/open_ai.py", line 17, in main
    stream = await client.chat.completions.create(
             ^^^^^^^^^^^^^^^^^^^^^^^^^^^^^^^^^^^^^
  File "/home/shliamb/Desktop/WORK_FOLDER/chatgpt/myvenv/lib/python3.11/site-packages/openai/resources/chat/completions.py", line 1291, in create
    return await self._post(
           ^^^^^^^^^^^^^^^^^
  File "/home/shliamb/Desktop/WORK_FOLDER/chatgpt/myvenv/lib/python3.11/site-packages/openai/_base_client.py", line 1578, in post
    return await self.request(cast_to, opts, stream=stream, stream_cls=stream_cls)
           ^^^^^^^^^^^^^^^^^^^^^^^^^^^^^^^^^^^^^^^^^^^^^^^^^^^^^^^^^^^^^^^^^^^^^^^
  File "/home/shliamb/Desktop/WORK_FOLDER/chatgpt/myvenv/lib/python3.11/site-packages/openai/_base_client.py", line 1339, in request
    return await self._request(
           ^^^^^^^^^^^^^^^^^^^^
  File "/home/shliamb/Desktop/WORK_FOLDER/chatgpt/myvenv/lib/python3.11/site-packages/openai/_base_client.py", line 1359, in _request
    request = self._build_request(options)
              ^^^^^^^^^^^^^^^^^^^^^^^^^^^^
  File "/home/shliamb/Desktop/WORK_FOLDER/chatgpt/myvenv/lib/python3.11/site-packages/openai/_base_client.py", line 467, in _build_request
    return self._client.build_request(  # pyright: ignore[reportUnknownMemberType]
           ^^^^^^^^^^^^^^^^^^^^^^^^^^^^^^^^^^^^^^^^^^^^^^^^^^^^^^^^^^^^^^^^^^^^^^^
  File "/home/shliamb/Desktop/WORK_FOLDER/chatgpt/myvenv/lib/python3.11/site-packages/httpx/_client.py", line 358, in build_request
    return Request(
           ^^^^^^^^
  File "/home/shliamb/Desktop/WORK_FOLDER/chatgpt/myvenv/lib/python3.11/site-packages/httpx/_models.py", line 338, in __init__
    headers, stream = encode_request(
                      ^^^^^^^^^^^^^^^
  File "/home/shliamb/Desktop/WORK_FOLDER/chatgpt/myvenv/lib/python3.11/site-packages/httpx/_content.py", line 214, in encode_request
    return encode_json(json)
           ^^^^^^^^^^^^^^^^^
  File "/home/shliamb/Desktop/WORK_FOLDER/chatgpt/myvenv/lib/python3.11/site-packages/httpx/_content.py", line 177, in encode_json
    body = json_dumps(json).encode("utf-8")
           ^^^^^^^^^^^^^^^^
  File "/usr/lib/python3.11/json/__init__.py", line 231, in dumps
    return _default_encoder.encode(obj)
           ^^^^^^^^^^^^^^^^^^^^^^^^^^^^
  File "/usr/lib/python3.11/json/encoder.py", line 200, in encode
    chunks = self.iterencode(o, _one_shot=True)
             ^^^^^^^^^^^^^^^^^^^^^^^^^^^^^^^^^^
  File "/usr/lib/python3.11/json/encoder.py", line 258, in iterencode
    return _iterencode(o, 0)
           ^^^^^^^^^^^^^^^^^
  File "/usr/lib/python3.11/json/encoder.py", line 180, in default
    raise TypeError(f'Object of type {o.__class__.__name__} '
TypeError: Object of type Message is not JSON serializable
2024-01-25 22:33:38,069 - logging_bot - ERROR - Произошла непредвиденная ошибка:
Traceback (most recent call last):
  File "/home/shliamb/Desktop/WORK_FOLDER/chatgpt/app/run_bot.py", line 9, in <module>
    from tele_bot import start_bot
  File "/home/shliamb/Desktop/WORK_FOLDER/chatgpt/app/tele_bot.py", line 61, in <module>
    start_bot = bot.polling()
                ^^^^^^^^^^^^^
  File "/home/shliamb/Desktop/WORK_FOLDER/chatgpt/myvenv/lib/python3.11/site-packages/telebot/__init__.py", line 1045, in polling
    self.__threaded_polling(non_stop=non_stop, interval=interval, timeout=timeout, long_polling_timeout=long_polling_timeout,
  File "/home/shliamb/Desktop/WORK_FOLDER/chatgpt/myvenv/lib/python3.11/site-packages/telebot/__init__.py", line 1120, in __threaded_polling
    raise e
  File "/home/shliamb/Desktop/WORK_FOLDER/chatgpt/myvenv/lib/python3.11/site-packages/telebot/__init__.py", line 1082, in __threaded_polling
    self.worker_pool.raise_exceptions()
  File "/home/shliamb/Desktop/WORK_FOLDER/chatgpt/myvenv/lib/python3.11/site-packages/telebot/util.py", line 147, in raise_exceptions
    raise self.exception_info
  File "/home/shliamb/Desktop/WORK_FOLDER/chatgpt/myvenv/lib/python3.11/site-packages/telebot/util.py", line 90, in run
    task(*args, **kwargs)
  File "/home/shliamb/Desktop/WORK_FOLDER/chatgpt/myvenv/lib/python3.11/site-packages/telebot/__init__.py", line 6793, in _run_middlewares_and_handler
    result = handler['function'](message)
             ^^^^^^^^^^^^^^^^^^^^^^^^^^^^
  File "/home/shliamb/Desktop/WORK_FOLDER/chatgpt/app/tele_bot.py", line 47, in handle_message
    asyncio.run(main(message))
  File "/usr/lib/python3.11/asyncio/runners.py", line 190, in run
    return runner.run(main)
           ^^^^^^^^^^^^^^^^
  File "/usr/lib/python3.11/asyncio/runners.py", line 118, in run
    return self._loop.run_until_complete(task)
           ^^^^^^^^^^^^^^^^^^^^^^^^^^^^^^^^^^^
  File "/usr/lib/python3.11/asyncio/base_events.py", line 653, in run_until_complete
    return future.result()
           ^^^^^^^^^^^^^^^
  File "/home/shliamb/Desktop/WORK_FOLDER/chatgpt/app/open_ai.py", line 18, in main
    stream = await client.chat.completions.create(
             ^^^^^^^^^^^^^^^^^^^^^^^^^^^^^^^^^^^^^
  File "/home/shliamb/Desktop/WORK_FOLDER/chatgpt/myvenv/lib/python3.11/site-packages/openai/resources/chat/completions.py", line 1291, in create
    return await self._post(
           ^^^^^^^^^^^^^^^^^
  File "/home/shliamb/Desktop/WORK_FOLDER/chatgpt/myvenv/lib/python3.11/site-packages/openai/_base_client.py", line 1578, in post
    return await self.request(cast_to, opts, stream=stream, stream_cls=stream_cls)
           ^^^^^^^^^^^^^^^^^^^^^^^^^^^^^^^^^^^^^^^^^^^^^^^^^^^^^^^^^^^^^^^^^^^^^^^
  File "/home/shliamb/Desktop/WORK_FOLDER/chatgpt/myvenv/lib/python3.11/site-packages/openai/_base_client.py", line 1339, in request
    return await self._request(
           ^^^^^^^^^^^^^^^^^^^^
  File "/home/shliamb/Desktop/WORK_FOLDER/chatgpt/myvenv/lib/python3.11/site-packages/openai/_base_client.py", line 1359, in _request
    request = self._build_request(options)
              ^^^^^^^^^^^^^^^^^^^^^^^^^^^^
  File "/home/shliamb/Desktop/WORK_FOLDER/chatgpt/myvenv/lib/python3.11/site-packages/openai/_base_client.py", line 467, in _build_request
    return self._client.build_request(  # pyright: ignore[reportUnknownMemberType]
           ^^^^^^^^^^^^^^^^^^^^^^^^^^^^^^^^^^^^^^^^^^^^^^^^^^^^^^^^^^^^^^^^^^^^^^^
  File "/home/shliamb/Desktop/WORK_FOLDER/chatgpt/myvenv/lib/python3.11/site-packages/httpx/_client.py", line 358, in build_request
    return Request(
           ^^^^^^^^
  File "/home/shliamb/Desktop/WORK_FOLDER/chatgpt/myvenv/lib/python3.11/site-packages/httpx/_models.py", line 338, in __init__
    headers, stream = encode_request(
                      ^^^^^^^^^^^^^^^
  File "/home/shliamb/Desktop/WORK_FOLDER/chatgpt/myvenv/lib/python3.11/site-packages/httpx/_content.py", line 214, in encode_request
    return encode_json(json)
           ^^^^^^^^^^^^^^^^^
  File "/home/shliamb/Desktop/WORK_FOLDER/chatgpt/myvenv/lib/python3.11/site-packages/httpx/_content.py", line 177, in encode_json
    body = json_dumps(json).encode("utf-8")
           ^^^^^^^^^^^^^^^^
  File "/usr/lib/python3.11/json/__init__.py", line 231, in dumps
    return _default_encoder.encode(obj)
           ^^^^^^^^^^^^^^^^^^^^^^^^^^^^
  File "/usr/lib/python3.11/json/encoder.py", line 200, in encode
    chunks = self.iterencode(o, _one_shot=True)
             ^^^^^^^^^^^^^^^^^^^^^^^^^^^^^^^^^^
  File "/usr/lib/python3.11/json/encoder.py", line 258, in iterencode
    return _iterencode(o, 0)
           ^^^^^^^^^^^^^^^^^
  File "/usr/lib/python3.11/json/encoder.py", line 180, in default
    raise TypeError(f'Object of type {o.__class__.__name__} '
TypeError: Object of type Message is not JSON serializable
2024-01-25 22:34:37,203 - logging_bot - ERROR - Произошла непредвиденная ошибка:
Traceback (most recent call last):
  File "/home/shliamb/Desktop/WORK_FOLDER/chatgpt/app/run_bot.py", line 9, in <module>
    from tele_bot import start_bot
  File "/home/shliamb/Desktop/WORK_FOLDER/chatgpt/app/tele_bot.py", line 62, in <module>
    start_bot = bot.polling()
                ^^^^^^^^^^^^^
  File "/home/shliamb/Desktop/WORK_FOLDER/chatgpt/myvenv/lib/python3.11/site-packages/telebot/__init__.py", line 1045, in polling
    self.__threaded_polling(non_stop=non_stop, interval=interval, timeout=timeout, long_polling_timeout=long_polling_timeout,
  File "/home/shliamb/Desktop/WORK_FOLDER/chatgpt/myvenv/lib/python3.11/site-packages/telebot/__init__.py", line 1120, in __threaded_polling
    raise e
  File "/home/shliamb/Desktop/WORK_FOLDER/chatgpt/myvenv/lib/python3.11/site-packages/telebot/__init__.py", line 1082, in __threaded_polling
    self.worker_pool.raise_exceptions()
  File "/home/shliamb/Desktop/WORK_FOLDER/chatgpt/myvenv/lib/python3.11/site-packages/telebot/util.py", line 147, in raise_exceptions
    raise self.exception_info
  File "/home/shliamb/Desktop/WORK_FOLDER/chatgpt/myvenv/lib/python3.11/site-packages/telebot/util.py", line 90, in run
    task(*args, **kwargs)
  File "/home/shliamb/Desktop/WORK_FOLDER/chatgpt/myvenv/lib/python3.11/site-packages/telebot/__init__.py", line 6793, in _run_middlewares_and_handler
    result = handler['function'](message)
             ^^^^^^^^^^^^^^^^^^^^^^^^^^^^
  File "/home/shliamb/Desktop/WORK_FOLDER/chatgpt/app/tele_bot.py", line 48, in handle_message
    asyncio.run(main(message))
  File "/usr/lib/python3.11/asyncio/runners.py", line 190, in run
    return runner.run(main)
           ^^^^^^^^^^^^^^^^
  File "/usr/lib/python3.11/asyncio/runners.py", line 118, in run
    return self._loop.run_until_complete(task)
           ^^^^^^^^^^^^^^^^^^^^^^^^^^^^^^^^^^^
  File "/usr/lib/python3.11/asyncio/base_events.py", line 653, in run_until_complete
    return future.result()
           ^^^^^^^^^^^^^^^
  File "/home/shliamb/Desktop/WORK_FOLDER/chatgpt/app/open_ai.py", line 18, in main
    stream = await client.chat.completions.create(
             ^^^^^^^^^^^^^^^^^^^^^^^^^^^^^^^^^^^^^
  File "/home/shliamb/Desktop/WORK_FOLDER/chatgpt/myvenv/lib/python3.11/site-packages/openai/resources/chat/completions.py", line 1291, in create
    return await self._post(
           ^^^^^^^^^^^^^^^^^
  File "/home/shliamb/Desktop/WORK_FOLDER/chatgpt/myvenv/lib/python3.11/site-packages/openai/_base_client.py", line 1578, in post
    return await self.request(cast_to, opts, stream=stream, stream_cls=stream_cls)
           ^^^^^^^^^^^^^^^^^^^^^^^^^^^^^^^^^^^^^^^^^^^^^^^^^^^^^^^^^^^^^^^^^^^^^^^
  File "/home/shliamb/Desktop/WORK_FOLDER/chatgpt/myvenv/lib/python3.11/site-packages/openai/_base_client.py", line 1339, in request
    return await self._request(
           ^^^^^^^^^^^^^^^^^^^^
  File "/home/shliamb/Desktop/WORK_FOLDER/chatgpt/myvenv/lib/python3.11/site-packages/openai/_base_client.py", line 1359, in _request
    request = self._build_request(options)
              ^^^^^^^^^^^^^^^^^^^^^^^^^^^^
  File "/home/shliamb/Desktop/WORK_FOLDER/chatgpt/myvenv/lib/python3.11/site-packages/openai/_base_client.py", line 467, in _build_request
    return self._client.build_request(  # pyright: ignore[reportUnknownMemberType]
           ^^^^^^^^^^^^^^^^^^^^^^^^^^^^^^^^^^^^^^^^^^^^^^^^^^^^^^^^^^^^^^^^^^^^^^^
  File "/home/shliamb/Desktop/WORK_FOLDER/chatgpt/myvenv/lib/python3.11/site-packages/httpx/_client.py", line 358, in build_request
    return Request(
           ^^^^^^^^
  File "/home/shliamb/Desktop/WORK_FOLDER/chatgpt/myvenv/lib/python3.11/site-packages/httpx/_models.py", line 338, in __init__
    headers, stream = encode_request(
                      ^^^^^^^^^^^^^^^
  File "/home/shliamb/Desktop/WORK_FOLDER/chatgpt/myvenv/lib/python3.11/site-packages/httpx/_content.py", line 214, in encode_request
    return encode_json(json)
           ^^^^^^^^^^^^^^^^^
  File "/home/shliamb/Desktop/WORK_FOLDER/chatgpt/myvenv/lib/python3.11/site-packages/httpx/_content.py", line 177, in encode_json
    body = json_dumps(json).encode("utf-8")
           ^^^^^^^^^^^^^^^^
  File "/usr/lib/python3.11/json/__init__.py", line 231, in dumps
    return _default_encoder.encode(obj)
           ^^^^^^^^^^^^^^^^^^^^^^^^^^^^
  File "/usr/lib/python3.11/json/encoder.py", line 200, in encode
    chunks = self.iterencode(o, _one_shot=True)
             ^^^^^^^^^^^^^^^^^^^^^^^^^^^^^^^^^^
  File "/usr/lib/python3.11/json/encoder.py", line 258, in iterencode
    return _iterencode(o, 0)
           ^^^^^^^^^^^^^^^^^
  File "/usr/lib/python3.11/json/encoder.py", line 180, in default
    raise TypeError(f'Object of type {o.__class__.__name__} '
TypeError: Object of type Message is not JSON serializable
2024-01-25 22:37:57,278 - logging_bot - ERROR - Произошла непредвиденная ошибка:
Traceback (most recent call last):
  File "/home/shliamb/Desktop/WORK_FOLDER/chatgpt/app/run_bot.py", line 9, in <module>
    from tele_bot import start_bot
  File "/home/shliamb/Desktop/WORK_FOLDER/chatgpt/app/tele_bot.py", line 4, in <module>
    from open_ai import main # open_ai first_choice_message,
    ^^^^^^^^^^^^^^^^^^^^^^^^
ImportError: cannot import name 'main' from 'open_ai' (/home/shliamb/Desktop/WORK_FOLDER/chatgpt/app/open_ai.py)
2024-01-25 22:38:16,538 - logging_bot - ERROR - Произошла непредвиденная ошибка:
Traceback (most recent call last):
  File "/home/shliamb/Desktop/WORK_FOLDER/chatgpt/app/run_bot.py", line 9, in <module>
    from tele_bot import start_bot
  File "/home/shliamb/Desktop/WORK_FOLDER/chatgpt/app/tele_bot.py", line 4, in <module>
    from open_ai import main # open_ai first_choice_message,
    ^^^^^^^^^^^^^^^^^^^^^^^^
ImportError: cannot import name 'main' from 'open_ai' (/home/shliamb/Desktop/WORK_FOLDER/chatgpt/app/open_ai.py)
2024-01-25 22:40:06,601 - httpx - INFO - HTTP Request: POST https://api.openai.com/v1/chat/completions "HTTP/1.1 200 OK"
2024-01-25 22:41:10,326 - httpx - INFO - HTTP Request: POST https://api.openai.com/v1/chat/completions "HTTP/1.1 200 OK"
2024-01-25 22:43:15,982 - logging_bot - ERROR - Произошла непредвиденная ошибка:
Traceback (most recent call last):
  File "/home/shliamb/Desktop/WORK_FOLDER/chatgpt/app/run_bot.py", line 9, in <module>
    from tele_bot import start_bot
  File "/home/shliamb/Desktop/WORK_FOLDER/chatgpt/app/tele_bot.py", line 4, in <module>
    from open_ai import main # open_ai first_choice_message,
    ^^^^^^^^^^^^^^^^^^^^^^^^
  File "/home/shliamb/Desktop/WORK_FOLDER/chatgpt/app/open_ai.py", line 26, in <module>
    asyncio.run(main())
                ^^^^^^
TypeError: main() missing 1 required positional argument: 'message'
2024-01-25 22:44:04,419 - httpx - INFO - HTTP Request: POST https://api.openai.com/v1/chat/completions "HTTP/1.1 200 OK"
2024-01-25 22:50:04,131 - logging_bot - ERROR - Произошла непредвиденная ошибка:
Traceback (most recent call last):
  File "/home/shliamb/Desktop/WORK_FOLDER/chatgpt/app/run_bot.py", line 9, in <module>
    from tele_bot import start_bot
  File "/home/shliamb/Desktop/WORK_FOLDER/chatgpt/app/tele_bot.py", line 4, in <module>
    from open_ai import main # open_ai first_choice_message,
    ^^^^^^^^^^^^^^^^^^^^^^^^
  File "/home/shliamb/Desktop/WORK_FOLDER/chatgpt/app/open_ai.py", line 4, in <module>
    from tele_bot import question
ImportError: cannot import name 'question' from partially initialized module 'tele_bot' (most likely due to a circular import) (/home/shliamb/Desktop/WORK_FOLDER/chatgpt/app/tele_bot.py)
2024-01-25 22:55:37,214 - logging_bot - ERROR - Произошла непредвиденная ошибка:
Traceback (most recent call last):
  File "/home/shliamb/Desktop/WORK_FOLDER/chatgpt/app/run_bot.py", line 9, in <module>
    from tele_bot import start_bot
  File "/home/shliamb/Desktop/WORK_FOLDER/chatgpt/app/tele_bot.py", line 4, in <module>
    from open_ai import main # open_ai first_choice_message,
    ^^^^^^^^^^^^^^^^^^^^^^^^
  File "/home/shliamb/Desktop/WORK_FOLDER/chatgpt/app/open_ai.py", line 4, in <module>
    from tele_bot import question
ImportError: cannot import name 'question' from partially initialized module 'tele_bot' (most likely due to a circular import) (/home/shliamb/Desktop/WORK_FOLDER/chatgpt/app/tele_bot.py)
2024-01-25 22:59:27,462 - httpx - INFO - HTTP Request: POST https://api.openai.com/v1/chat/completions "HTTP/1.1 200 OK"
2024-01-25 23:04:24,628 - logging_bot - ERROR - Произошла непредвиденная ошибка:
Traceback (most recent call last):
  File "/home/shliamb/Desktop/WORK_FOLDER/chatgpt/app/run_bot.py", line 9, in <module>
    from tele_bot import start_bot
  File "/home/shliamb/Desktop/WORK_FOLDER/chatgpt/app/tele_bot.py", line 4, in <module>
    from open_ai import ais # open_ai first_choice_message,
    ^^^^^^^^^^^^^^^^^^^^^^^
  File "/home/shliamb/Desktop/WORK_FOLDER/chatgpt/app/open_ai.py", line 4, in <module>
    from tele_bot import question
ImportError: cannot import name 'question' from partially initialized module 'tele_bot' (most likely due to a circular import) (/home/shliamb/Desktop/WORK_FOLDER/chatgpt/app/tele_bot.py)
2024-01-25 23:07:10,618 - httpx - INFO - HTTP Request: POST https://api.openai.com/v1/chat/completions "HTTP/1.1 200 OK"
2024-01-25 23:07:58,673 - httpx - INFO - HTTP Request: POST https://api.openai.com/v1/chat/completions "HTTP/1.1 200 OK"
2024-01-25 23:08:44,593 - httpx - INFO - HTTP Request: POST https://api.openai.com/v1/chat/completions "HTTP/1.1 200 OK"
2024-01-25 23:12:33,782 - httpx - INFO - HTTP Request: POST https://api.openai.com/v1/chat/completions "HTTP/1.1 200 OK"
2024-01-25 23:12:55,825 - httpx - INFO - HTTP Request: POST https://api.openai.com/v1/chat/completions "HTTP/1.1 200 OK"
2024-01-25 23:15:13,607 - httpx - INFO - HTTP Request: POST https://api.openai.com/v1/chat/completions "HTTP/1.1 200 OK"
2024-01-25 23:16:06,653 - httpx - INFO - HTTP Request: POST https://api.openai.com/v1/chat/completions "HTTP/1.1 200 OK"
2024-01-25 23:16:42,420 - openai._base_client - INFO - Retrying request to /chat/completions in 0.783737 seconds
2024-01-25 23:16:44,693 - httpx - INFO - HTTP Request: POST https://api.openai.com/v1/chat/completions "HTTP/1.1 200 OK"
2024-01-25 23:18:11,223 - logging_bot - ERROR - Произошла непредвиденная ошибка:
Traceback (most recent call last):
  File "/home/shliamb/Desktop/WORK_FOLDER/chatgpt/app/run_bot.py", line 9, in <module>
    from tele_bot import start_bot
  File "/home/shliamb/Desktop/WORK_FOLDER/chatgpt/app/tele_bot.py", line 88, in <module>
    asyncio.run(main(question))
                     ^^^^^^^^
NameError: name 'question' is not defined
2024-01-25 23:25:02,595 - logging_bot - ERROR - Произошла непредвиденная ошибка:
Traceback (most recent call last):
  File "/home/shliamb/Desktop/WORK_FOLDER/chatgpt/app/run_bot.py", line 9, in <module>
    from tele_bot import start_bot
  File "/home/shliamb/Desktop/WORK_FOLDER/chatgpt/app/tele_bot.py", line 84
    fort = (content, end="")
                     ^^^^^^
SyntaxError: invalid syntax. Maybe you meant '==' or ':=' instead of '='?
2024-01-25 23:30:15,855 - logging_bot - ERROR - Произошла непредвиденная ошибка:
Traceback (most recent call last):
  File "/home/shliamb/Desktop/WORK_FOLDER/chatgpt/app/run_bot.py", line 9, in <module>
    from tele_bot import start_bot
  File "/home/shliamb/Desktop/WORK_FOLDER/chatgpt/app/tele_bot.py", line 83, in <module>
    start_bot = bot.polling()
                ^^^^^^^^^^^^^
  File "/home/shliamb/Desktop/WORK_FOLDER/chatgpt/myvenv/lib/python3.11/site-packages/telebot/__init__.py", line 1045, in polling
    self.__threaded_polling(non_stop=non_stop, interval=interval, timeout=timeout, long_polling_timeout=long_polling_timeout,
  File "/home/shliamb/Desktop/WORK_FOLDER/chatgpt/myvenv/lib/python3.11/site-packages/telebot/__init__.py", line 1120, in __threaded_polling
    raise e
  File "/home/shliamb/Desktop/WORK_FOLDER/chatgpt/myvenv/lib/python3.11/site-packages/telebot/__init__.py", line 1082, in __threaded_polling
    self.worker_pool.raise_exceptions()
  File "/home/shliamb/Desktop/WORK_FOLDER/chatgpt/myvenv/lib/python3.11/site-packages/telebot/util.py", line 147, in raise_exceptions
    raise self.exception_info
  File "/home/shliamb/Desktop/WORK_FOLDER/chatgpt/myvenv/lib/python3.11/site-packages/telebot/util.py", line 90, in run
    task(*args, **kwargs)
  File "/home/shliamb/Desktop/WORK_FOLDER/chatgpt/myvenv/lib/python3.11/site-packages/telebot/__init__.py", line 6793, in _run_middlewares_and_handler
    result = handler['function'](message)
             ^^^^^^^^^^^^^^^^^^^^^^^^^^^^
  File "/home/shliamb/Desktop/WORK_FOLDER/chatgpt/app/tele_bot.py", line 73, in handle_message
    main(question)
  File "/home/shliamb/Desktop/WORK_FOLDER/chatgpt/app/tele_bot.py", line 63, in main
    for chunk in stream:
TypeError: 'coroutine' object is not iterable
2024-01-25 23:31:46,101 - logging_bot - ERROR - Произошла непредвиденная ошибка:
Traceback (most recent call last):
  File "/home/shliamb/Desktop/WORK_FOLDER/chatgpt/app/run_bot.py", line 9, in <module>
    from tele_bot import start_bot
  File "/home/shliamb/Desktop/WORK_FOLDER/chatgpt/app/tele_bot.py", line 66, in <module>
    asyncio.run(main(question))
                     ^^^^^^^^
NameError: name 'question' is not defined
2024-01-25 23:38:40,199 - logging_bot - ERROR - Произошла непредвиденная ошибка:
Traceback (most recent call last):
  File "/home/shliamb/Desktop/WORK_FOLDER/chatgpt/app/run_bot.py", line 9, in <module>
    from tele_bot import start_bot
  File "/home/shliamb/Desktop/WORK_FOLDER/chatgpt/app/tele_bot.py", line 64, in <module>
    asyncio.run(main())
                ^^^^^^
TypeError: main() missing 1 required positional argument: 'question'
2024-01-25 23:40:38,466 - logging_bot - ERROR - Произошла непредвиденная ошибка:
Traceback (most recent call last):
  File "/home/shliamb/Desktop/WORK_FOLDER/chatgpt/app/run_bot.py", line 9, in <module>
    from tele_bot import start_bot
  File "/home/shliamb/Desktop/WORK_FOLDER/chatgpt/app/tele_bot.py", line 64, in <module>
    asyncio.run(main(message.text))
                     ^^^^^^^
NameError: name 'message' is not defined
2024-01-25 23:42:54,242 - logging_bot - ERROR - Произошла непредвиденная ошибка:
Traceback (most recent call last):
  File "/home/shliamb/Desktop/WORK_FOLDER/chatgpt/app/run_bot.py", line 9, in <module>
    from tele_bot import start_bot
  File "/home/shliamb/Desktop/WORK_FOLDER/chatgpt/app/tele_bot.py", line 85, in <module>
    start_bot = bot.polling()
                ^^^^^^^^^^^^^
  File "/home/shliamb/Desktop/WORK_FOLDER/chatgpt/myvenv/lib/python3.11/site-packages/telebot/__init__.py", line 1045, in polling
    self.__threaded_polling(non_stop=non_stop, interval=interval, timeout=timeout, long_polling_timeout=long_polling_timeout,
  File "/home/shliamb/Desktop/WORK_FOLDER/chatgpt/myvenv/lib/python3.11/site-packages/telebot/__init__.py", line 1120, in __threaded_polling
    raise e
  File "/home/shliamb/Desktop/WORK_FOLDER/chatgpt/myvenv/lib/python3.11/site-packages/telebot/__init__.py", line 1082, in __threaded_polling
    self.worker_pool.raise_exceptions()
  File "/home/shliamb/Desktop/WORK_FOLDER/chatgpt/myvenv/lib/python3.11/site-packages/telebot/util.py", line 147, in raise_exceptions
    raise self.exception_info
  File "/home/shliamb/Desktop/WORK_FOLDER/chatgpt/myvenv/lib/python3.11/site-packages/telebot/util.py", line 90, in run
    task(*args, **kwargs)
  File "/home/shliamb/Desktop/WORK_FOLDER/chatgpt/myvenv/lib/python3.11/site-packages/telebot/__init__.py", line 6793, in _run_middlewares_and_handler
    result = handler['function'](message)
             ^^^^^^^^^^^^^^^^^^^^^^^^^^^^
  File "/home/shliamb/Desktop/WORK_FOLDER/chatgpt/app/tele_bot.py", line 55, in handle_message
    asyncio.create_task(main(message.text))
  File "/usr/lib/python3.11/asyncio/tasks.py", line 381, in create_task
    loop = events.get_running_loop()
           ^^^^^^^^^^^^^^^^^^^^^^^^^
RuntimeError: no running event loop
2024-01-25 23:53:09,851 - logging_bot - ERROR - Произошла непредвиденная ошибка:
Traceback (most recent call last):
  File "/home/shliamb/Desktop/WORK_FOLDER/chatgpt/app/run_bot.py", line 9, in <module>
    from tele_bot import start_bot
  File "/home/shliamb/Desktop/WORK_FOLDER/chatgpt/app/tele_bot.py", line 85, in <module>
    start_bot = bot.polling()
                ^^^^^^^^^^^^^
  File "/home/shliamb/Desktop/WORK_FOLDER/chatgpt/myvenv/lib/python3.11/site-packages/telebot/__init__.py", line 1045, in polling
    self.__threaded_polling(non_stop=non_stop, interval=interval, timeout=timeout, long_polling_timeout=long_polling_timeout,
  File "/home/shliamb/Desktop/WORK_FOLDER/chatgpt/myvenv/lib/python3.11/site-packages/telebot/__init__.py", line 1120, in __threaded_polling
    raise e
  File "/home/shliamb/Desktop/WORK_FOLDER/chatgpt/myvenv/lib/python3.11/site-packages/telebot/__init__.py", line 1082, in __threaded_polling
    self.worker_pool.raise_exceptions()
  File "/home/shliamb/Desktop/WORK_FOLDER/chatgpt/myvenv/lib/python3.11/site-packages/telebot/util.py", line 147, in raise_exceptions
    raise self.exception_info
  File "/home/shliamb/Desktop/WORK_FOLDER/chatgpt/myvenv/lib/python3.11/site-packages/telebot/util.py", line 90, in run
    task(*args, **kwargs)
  File "/home/shliamb/Desktop/WORK_FOLDER/chatgpt/myvenv/lib/python3.11/site-packages/telebot/__init__.py", line 6793, in _run_middlewares_and_handler
    result = handler['function'](message)
             ^^^^^^^^^^^^^^^^^^^^^^^^^^^^
  File "/home/shliamb/Desktop/WORK_FOLDER/chatgpt/app/tele_bot.py", line 68, in handle_message
    asyncio.create_task(main(message.text))
  File "/usr/lib/python3.11/asyncio/tasks.py", line 381, in create_task
    loop = events.get_running_loop()
           ^^^^^^^^^^^^^^^^^^^^^^^^^
RuntimeError: no running event loop
2024-01-25 23:54:16,131 - logging_bot - ERROR - Произошла непредвиденная ошибка:
Traceback (most recent call last):
  File "/home/shliamb/Desktop/WORK_FOLDER/chatgpt/app/run_bot.py", line 9, in <module>
    from tele_bot import start_bot
  File "/home/shliamb/Desktop/WORK_FOLDER/chatgpt/app/tele_bot.py", line 85, in <module>
    start_bot = bot.polling()
                ^^^^^^^^^^^^^
  File "/home/shliamb/Desktop/WORK_FOLDER/chatgpt/myvenv/lib/python3.11/site-packages/telebot/__init__.py", line 1045, in polling
    self.__threaded_polling(non_stop=non_stop, interval=interval, timeout=timeout, long_polling_timeout=long_polling_timeout,
  File "/home/shliamb/Desktop/WORK_FOLDER/chatgpt/myvenv/lib/python3.11/site-packages/telebot/__init__.py", line 1120, in __threaded_polling
    raise e
  File "/home/shliamb/Desktop/WORK_FOLDER/chatgpt/myvenv/lib/python3.11/site-packages/telebot/__init__.py", line 1082, in __threaded_polling
    self.worker_pool.raise_exceptions()
  File "/home/shliamb/Desktop/WORK_FOLDER/chatgpt/myvenv/lib/python3.11/site-packages/telebot/util.py", line 147, in raise_exceptions
    raise self.exception_info
  File "/home/shliamb/Desktop/WORK_FOLDER/chatgpt/myvenv/lib/python3.11/site-packages/telebot/util.py", line 90, in run
    task(*args, **kwargs)
  File "/home/shliamb/Desktop/WORK_FOLDER/chatgpt/myvenv/lib/python3.11/site-packages/telebot/__init__.py", line 6793, in _run_middlewares_and_handler
    result = handler['function'](message)
             ^^^^^^^^^^^^^^^^^^^^^^^^^^^^
  File "/home/shliamb/Desktop/WORK_FOLDER/chatgpt/app/tele_bot.py", line 68, in handle_message
    asyncio.create_task(main(message))
  File "/usr/lib/python3.11/asyncio/tasks.py", line 381, in create_task
    loop = events.get_running_loop()
           ^^^^^^^^^^^^^^^^^^^^^^^^^
RuntimeError: no running event loop
2024-01-25 23:55:01,975 - logging_bot - ERROR - Произошла непредвиденная ошибка:
Traceback (most recent call last):
  File "/home/shliamb/Desktop/WORK_FOLDER/chatgpt/app/run_bot.py", line 9, in <module>
    from tele_bot import start_bot
  File "/home/shliamb/Desktop/WORK_FOLDER/chatgpt/app/tele_bot.py", line 63, in <module>
    asyncio.create_task(main(message))
                             ^^^^^^^
NameError: name 'message' is not defined
2024-01-26 00:00:55,900 - logging_bot - ERROR - Произошла непредвиденная ошибка:
Traceback (most recent call last):
  File "/home/shliamb/Desktop/WORK_FOLDER/chatgpt/app/run_bot.py", line 9, in <module>
    from tele_bot import start_bot
ImportError: cannot import name 'start_bot' from 'tele_bot' (/home/shliamb/Desktop/WORK_FOLDER/chatgpt/app/tele_bot.py)
2024-01-26 00:04:54,067 - logging_bot - ERROR - Произошла непредвиденная ошибка:
Traceback (most recent call last):
  File "/home/shliamb/Desktop/WORK_FOLDER/chatgpt/app/run_bot.py", line 9, in <module>
    from tele_bot import start_bot
  File "/home/shliamb/Desktop/WORK_FOLDER/chatgpt/app/tele_bot.py", line 79
    await bot_task
    ^^^^^^^^^^^^^^
SyntaxError: 'await' outside function
2024-01-26 09:49:32,924 - httpx - INFO - HTTP Request: POST https://api.openai.com/v1/chat/completions "HTTP/1.1 200 OK"
2024-01-26 09:51:40,331 - httpx - INFO - HTTP Request: POST https://api.openai.com/v1/chat/completions "HTTP/1.1 200 OK"
2024-01-26 09:52:46,045 - httpx - INFO - HTTP Request: POST https://api.openai.com/v1/chat/completions "HTTP/1.1 200 OK"
2024-01-26 09:53:07,578 - httpx - INFO - HTTP Request: POST https://api.openai.com/v1/chat/completions "HTTP/1.1 200 OK"
2024-01-26 09:54:07,093 - httpx - INFO - HTTP Request: POST https://api.openai.com/v1/chat/completions "HTTP/1.1 200 OK"
2024-01-26 09:54:45,693 - httpx - INFO - HTTP Request: POST https://api.openai.com/v1/chat/completions "HTTP/1.1 200 OK"
2024-01-26 09:54:45,695 - logging_bot - ERROR - Произошла непредвиденная ошибка:
Traceback (most recent call last):
  File "/home/shliamb/Desktop/WORK_FOLDER/chatgpt/app/run_bot.py", line 9, in <module>
    from tele_bot import start_bot
  File "/home/shliamb/Desktop/WORK_FOLDER/chatgpt/app/tele_bot.py", line 51, in <module>
    start_bot = bot.polling()
                ^^^^^^^^^^^^^
  File "/home/shliamb/Desktop/WORK_FOLDER/chatgpt/myvenv/lib/python3.11/site-packages/telebot/__init__.py", line 1045, in polling
    self.__threaded_polling(non_stop=non_stop, interval=interval, timeout=timeout, long_polling_timeout=long_polling_timeout,
  File "/home/shliamb/Desktop/WORK_FOLDER/chatgpt/myvenv/lib/python3.11/site-packages/telebot/__init__.py", line 1120, in __threaded_polling
    raise e
  File "/home/shliamb/Desktop/WORK_FOLDER/chatgpt/myvenv/lib/python3.11/site-packages/telebot/__init__.py", line 1082, in __threaded_polling
    self.worker_pool.raise_exceptions()
  File "/home/shliamb/Desktop/WORK_FOLDER/chatgpt/myvenv/lib/python3.11/site-packages/telebot/util.py", line 147, in raise_exceptions
    raise self.exception_info
  File "/home/shliamb/Desktop/WORK_FOLDER/chatgpt/myvenv/lib/python3.11/site-packages/telebot/util.py", line 90, in run
    task(*args, **kwargs)
  File "/home/shliamb/Desktop/WORK_FOLDER/chatgpt/myvenv/lib/python3.11/site-packages/telebot/__init__.py", line 6793, in _run_middlewares_and_handler
    result = handler['function'](message)
             ^^^^^^^^^^^^^^^^^^^^^^^^^^^^
  File "/home/shliamb/Desktop/WORK_FOLDER/chatgpt/app/tele_bot.py", line 41, in handle_message
    open_ai(question)
  File "/home/shliamb/Desktop/WORK_FOLDER/chatgpt/app/open_ai.py", line 14, in open_ai
    print(stream.choices[0])
          ^^^^^^^^^^^^^^
AttributeError: 'Stream' object has no attribute 'choices'
2024-01-26 09:58:12,792 - httpx - INFO - HTTP Request: POST https://api.openai.com/v1/chat/completions "HTTP/1.1 200 OK"
2024-01-26 09:59:03,250 - httpx - INFO - HTTP Request: POST https://api.openai.com/v1/chat/completions "HTTP/1.1 200 OK"
2024-01-26 10:22:11,514 - httpx - INFO - HTTP Request: POST https://api.openai.com/v1/chat/completions "HTTP/1.1 200 OK"
2024-01-26 10:23:19,112 - logging_bot - ERROR - Произошла непредвиденная ошибка:
Traceback (most recent call last):
  File "/home/shliamb/Desktop/WORK_FOLDER/chatgpt/app/run_bot.py", line 9, in <module>
    from tele_bot import start_bot
  File "/home/shliamb/Desktop/WORK_FOLDER/chatgpt/app/tele_bot.py", line 51, in <module>
    start_bot = bot.polling()
                ^^^^^^^^^^^^^
  File "/home/shliamb/Desktop/WORK_FOLDER/chatgpt/myvenv/lib/python3.11/site-packages/telebot/__init__.py", line 1045, in polling
    self.__threaded_polling(non_stop=non_stop, interval=interval, timeout=timeout, long_polling_timeout=long_polling_timeout,
  File "/home/shliamb/Desktop/WORK_FOLDER/chatgpt/myvenv/lib/python3.11/site-packages/telebot/__init__.py", line 1120, in __threaded_polling
    raise e
  File "/home/shliamb/Desktop/WORK_FOLDER/chatgpt/myvenv/lib/python3.11/site-packages/telebot/__init__.py", line 1082, in __threaded_polling
    self.worker_pool.raise_exceptions()
  File "/home/shliamb/Desktop/WORK_FOLDER/chatgpt/myvenv/lib/python3.11/site-packages/telebot/util.py", line 147, in raise_exceptions
    raise self.exception_info
  File "/home/shliamb/Desktop/WORK_FOLDER/chatgpt/myvenv/lib/python3.11/site-packages/telebot/util.py", line 90, in run
    task(*args, **kwargs)
  File "/home/shliamb/Desktop/WORK_FOLDER/chatgpt/myvenv/lib/python3.11/site-packages/telebot/__init__.py", line 6793, in _run_middlewares_and_handler
    result = handler['function'](message)
             ^^^^^^^^^^^^^^^^^^^^^^^^^^^^
TypeError: handle_message() takes 0 positional arguments but 1 was given
2024-01-26 10:24:03,200 - httpx - INFO - HTTP Request: POST https://api.openai.com/v1/chat/completions "HTTP/1.1 200 OK"
2024-01-26 10:26:47,824 - httpx - INFO - HTTP Request: POST https://api.openai.com/v1/chat/completions "HTTP/1.1 200 OK"
2024-01-26 10:27:49,781 - logging_bot - ERROR - Произошла непредвиденная ошибка:
Traceback (most recent call last):
  File "/home/shliamb/Desktop/WORK_FOLDER/chatgpt/app/run_bot.py", line 9, in <module>
    from tele_bot import start_bot
  File "/home/shliamb/Desktop/WORK_FOLDER/chatgpt/app/tele_bot.py", line 4, in <module>
    from open_ai import open_ai
  File "/home/shliamb/Desktop/WORK_FOLDER/chatgpt/app/open_ai.py", line 3, in <module>
    from tele_bot import question
ImportError: cannot import name 'question' from partially initialized module 'tele_bot' (most likely due to a circular import) (/home/shliamb/Desktop/WORK_FOLDER/chatgpt/app/tele_bot.py)
2024-01-26 10:28:43,531 - logging_bot - ERROR - Произошла непредвиденная ошибка:
Traceback (most recent call last):
  File "/home/shliamb/Desktop/WORK_FOLDER/chatgpt/app/run_bot.py", line 9, in <module>
    from tele_bot import start_bot
  File "/home/shliamb/Desktop/WORK_FOLDER/chatgpt/app/tele_bot.py", line 4, in <module>
    from open_ai import open_ai
  File "/home/shliamb/Desktop/WORK_FOLDER/chatgpt/app/open_ai.py", line 3, in <module>
    from tele_bot import quest
ImportError: cannot import name 'quest' from partially initialized module 'tele_bot' (most likely due to a circular import) (/home/shliamb/Desktop/WORK_FOLDER/chatgpt/app/tele_bot.py)
2024-01-26 10:29:13,684 - logging_bot - ERROR - Произошла непредвиденная ошибка:
Traceback (most recent call last):
  File "/home/shliamb/Desktop/WORK_FOLDER/chatgpt/app/run_bot.py", line 9, in <module>
    from tele_bot import start_bot
  File "/home/shliamb/Desktop/WORK_FOLDER/chatgpt/app/tele_bot.py", line 4, in <module>
    from open_ai import open_ai
  File "/home/shliamb/Desktop/WORK_FOLDER/chatgpt/app/open_ai.py", line 3, in <module>
    from tele_bot import quest
ImportError: cannot import name 'quest' from partially initialized module 'tele_bot' (most likely due to a circular import) (/home/shliamb/Desktop/WORK_FOLDER/chatgpt/app/tele_bot.py)
2024-01-26 10:31:22,400 - httpx - INFO - HTTP Request: POST https://api.openai.com/v1/chat/completions "HTTP/1.1 200 OK"
2024-01-26 10:31:30,286 - logging_bot - ERROR - Произошла непредвиденная ошибка:
Traceback (most recent call last):
  File "/home/shliamb/Desktop/WORK_FOLDER/chatgpt/app/run_bot.py", line 9, in <module>
    from tele_bot import start_bot
  File "/home/shliamb/Desktop/WORK_FOLDER/chatgpt/app/tele_bot.py", line 52, in <module>
    start_bot = bot.polling()
                ^^^^^^^^^^^^^
  File "/home/shliamb/Desktop/WORK_FOLDER/chatgpt/myvenv/lib/python3.11/site-packages/telebot/__init__.py", line 1045, in polling
    self.__threaded_polling(non_stop=non_stop, interval=interval, timeout=timeout, long_polling_timeout=long_polling_timeout,
  File "/home/shliamb/Desktop/WORK_FOLDER/chatgpt/myvenv/lib/python3.11/site-packages/telebot/__init__.py", line 1120, in __threaded_polling
    raise e
  File "/home/shliamb/Desktop/WORK_FOLDER/chatgpt/myvenv/lib/python3.11/site-packages/telebot/__init__.py", line 1082, in __threaded_polling
    self.worker_pool.raise_exceptions()
  File "/home/shliamb/Desktop/WORK_FOLDER/chatgpt/myvenv/lib/python3.11/site-packages/telebot/util.py", line 147, in raise_exceptions
    raise self.exception_info
  File "/home/shliamb/Desktop/WORK_FOLDER/chatgpt/myvenv/lib/python3.11/site-packages/telebot/util.py", line 90, in run
    task(*args, **kwargs)
  File "/home/shliamb/Desktop/WORK_FOLDER/chatgpt/myvenv/lib/python3.11/site-packages/telebot/__init__.py", line 6793, in _run_middlewares_and_handler
    result = handler['function'](message)
             ^^^^^^^^^^^^^^^^^^^^^^^^^^^^
  File "/home/shliamb/Desktop/WORK_FOLDER/chatgpt/app/tele_bot.py", line 42, in handle_message
    open_ai()
TypeError: open_ai() missing 1 required positional argument: 'quest'
2024-01-26 10:32:17,766 - httpx - INFO - HTTP Request: POST https://api.openai.com/v1/chat/completions "HTTP/1.1 200 OK"
2024-01-26 10:32:20,918 - logging_bot - ERROR - Произошла непредвиденная ошибка:
Traceback (most recent call last):
  File "/home/shliamb/Desktop/WORK_FOLDER/chatgpt/app/run_bot.py", line 9, in <module>
    from tele_bot import start_bot
  File "/home/shliamb/Desktop/WORK_FOLDER/chatgpt/app/tele_bot.py", line 52, in <module>
    start_bot = bot.polling()
                ^^^^^^^^^^^^^
  File "/home/shliamb/Desktop/WORK_FOLDER/chatgpt/myvenv/lib/python3.11/site-packages/telebot/__init__.py", line 1045, in polling
    self.__threaded_polling(non_stop=non_stop, interval=interval, timeout=timeout, long_polling_timeout=long_polling_timeout,
  File "/home/shliamb/Desktop/WORK_FOLDER/chatgpt/myvenv/lib/python3.11/site-packages/telebot/__init__.py", line 1120, in __threaded_polling
    raise e
  File "/home/shliamb/Desktop/WORK_FOLDER/chatgpt/myvenv/lib/python3.11/site-packages/telebot/__init__.py", line 1082, in __threaded_polling
    self.worker_pool.raise_exceptions()
  File "/home/shliamb/Desktop/WORK_FOLDER/chatgpt/myvenv/lib/python3.11/site-packages/telebot/util.py", line 147, in raise_exceptions
    raise self.exception_info
  File "/home/shliamb/Desktop/WORK_FOLDER/chatgpt/myvenv/lib/python3.11/site-packages/telebot/util.py", line 90, in run
    task(*args, **kwargs)
  File "/home/shliamb/Desktop/WORK_FOLDER/chatgpt/myvenv/lib/python3.11/site-packages/telebot/__init__.py", line 6793, in _run_middlewares_and_handler
    result = handler['function'](message)
             ^^^^^^^^^^^^^^^^^^^^^^^^^^^^
  File "/home/shliamb/Desktop/WORK_FOLDER/chatgpt/app/tele_bot.py", line 42, in handle_message
    open_ai()
TypeError: open_ai() missing 1 required positional argument: 'quest'
2024-01-26 10:32:46,250 - httpx - INFO - HTTP Request: POST https://api.openai.com/v1/chat/completions "HTTP/1.1 200 OK"
2024-01-26 10:32:47,886 - logging_bot - ERROR - Произошла непредвиденная ошибка:
Traceback (most recent call last):
  File "/home/shliamb/Desktop/WORK_FOLDER/chatgpt/app/run_bot.py", line 9, in <module>
    from tele_bot import start_bot
  File "/home/shliamb/Desktop/WORK_FOLDER/chatgpt/app/tele_bot.py", line 52, in <module>
    start_bot = bot.polling()
                ^^^^^^^^^^^^^
  File "/home/shliamb/Desktop/WORK_FOLDER/chatgpt/myvenv/lib/python3.11/site-packages/telebot/__init__.py", line 1045, in polling
    self.__threaded_polling(non_stop=non_stop, interval=interval, timeout=timeout, long_polling_timeout=long_polling_timeout,
  File "/home/shliamb/Desktop/WORK_FOLDER/chatgpt/myvenv/lib/python3.11/site-packages/telebot/__init__.py", line 1120, in __threaded_polling
    raise e
  File "/home/shliamb/Desktop/WORK_FOLDER/chatgpt/myvenv/lib/python3.11/site-packages/telebot/__init__.py", line 1082, in __threaded_polling
    self.worker_pool.raise_exceptions()
  File "/home/shliamb/Desktop/WORK_FOLDER/chatgpt/myvenv/lib/python3.11/site-packages/telebot/util.py", line 147, in raise_exceptions
    raise self.exception_info
  File "/home/shliamb/Desktop/WORK_FOLDER/chatgpt/myvenv/lib/python3.11/site-packages/telebot/util.py", line 90, in run
    task(*args, **kwargs)
  File "/home/shliamb/Desktop/WORK_FOLDER/chatgpt/myvenv/lib/python3.11/site-packages/telebot/__init__.py", line 6793, in _run_middlewares_and_handler
    result = handler['function'](message)
             ^^^^^^^^^^^^^^^^^^^^^^^^^^^^
  File "/home/shliamb/Desktop/WORK_FOLDER/chatgpt/app/tele_bot.py", line 42, in handle_message
    open_ai()
TypeError: open_ai() missing 1 required positional argument: 'quest'
2024-01-26 10:33:06,902 - logging_bot - ERROR - Произошла непредвиденная ошибка:
Traceback (most recent call last):
  File "/home/shliamb/Desktop/WORK_FOLDER/chatgpt/app/run_bot.py", line 9, in <module>
    from tele_bot import start_bot
  File "/home/shliamb/Desktop/WORK_FOLDER/chatgpt/app/tele_bot.py", line 4, in <module>
    from open_ai import open_ai
  File "/home/shliamb/Desktop/WORK_FOLDER/chatgpt/app/open_ai.py", line 38, in <module>
    open_ai(quest)
            ^^^^^
NameError: name 'quest' is not defined
2024-01-26 10:33:26,802 - logging_bot - ERROR - Произошла непредвиденная ошибка:
Traceback (most recent call last):
  File "/home/shliamb/Desktop/WORK_FOLDER/chatgpt/app/run_bot.py", line 9, in <module>
    from tele_bot import start_bot
  File "/home/shliamb/Desktop/WORK_FOLDER/chatgpt/app/tele_bot.py", line 4, in <module>
    from open_ai import open_ai
  File "/home/shliamb/Desktop/WORK_FOLDER/chatgpt/app/open_ai.py", line 38, in <module>
    open_ai(quest)
            ^^^^^
NameError: name 'quest' is not defined
2024-01-26 10:33:53,970 - logging_bot - ERROR - Произошла непредвиденная ошибка:
Traceback (most recent call last):
  File "/home/shliamb/Desktop/WORK_FOLDER/chatgpt/app/run_bot.py", line 9, in <module>
    from tele_bot import start_bot
  File "/home/shliamb/Desktop/WORK_FOLDER/chatgpt/app/tele_bot.py", line 4, in <module>
    from open_ai import open_ai
  File "/home/shliamb/Desktop/WORK_FOLDER/chatgpt/app/open_ai.py", line 3, in <module>
    from tele_bot import quest
ImportError: cannot import name 'quest' from partially initialized module 'tele_bot' (most likely due to a circular import) (/home/shliamb/Desktop/WORK_FOLDER/chatgpt/app/tele_bot.py)
2024-01-26 10:35:05,457 - logging_bot - ERROR - Произошла непредвиденная ошибка:
Traceback (most recent call last):
  File "/home/shliamb/Desktop/WORK_FOLDER/chatgpt/app/run_bot.py", line 9, in <module>
    from tele_bot import start_bot
  File "/home/shliamb/Desktop/WORK_FOLDER/chatgpt/app/tele_bot.py", line 4, in <module>
    from open_ai import open_ai
  File "/home/shliamb/Desktop/WORK_FOLDER/chatgpt/app/open_ai.py", line 3, in <module>
    from tele_bot import quest
ImportError: cannot import name 'quest' from partially initialized module 'tele_bot' (most likely due to a circular import) (/home/shliamb/Desktop/WORK_FOLDER/chatgpt/app/tele_bot.py)
2024-01-26 10:36:21,190 - httpx - INFO - HTTP Request: POST https://api.openai.com/v1/chat/completions "HTTP/1.1 200 OK"
2024-01-26 10:37:05,924 - httpx - INFO - HTTP Request: POST https://api.openai.com/v1/chat/completions "HTTP/1.1 200 OK"
2024-01-26 10:38:14,379 - httpx - INFO - HTTP Request: POST https://api.openai.com/v1/chat/completions "HTTP/1.1 200 OK"
2024-01-26 10:39:24,839 - httpx - INFO - HTTP Request: POST https://api.openai.com/v1/chat/completions "HTTP/1.1 200 OK"
2024-01-26 11:04:11,564 - httpx - INFO - HTTP Request: POST https://api.openai.com/v1/chat/completions "HTTP/1.1 200 OK"
2024-01-26 11:04:11,573 - logging_bot - ERROR - Произошла непредвиденная ошибка:
Traceback (most recent call last):
  File "/home/shliamb/Desktop/WORK_FOLDER/chatgpt/app/run_bot.py", line 9, in <module>
    from tele_bot import start_bot
  File "/home/shliamb/Desktop/WORK_FOLDER/chatgpt/app/tele_bot.py", line 4, in <module>
    from open_ai import open_ai
ImportError: cannot import name 'open_ai' from 'open_ai' (/home/shliamb/Desktop/WORK_FOLDER/chatgpt/app/open_ai.py)
2024-01-26 11:14:30,263 - logging_bot - ERROR - Произошла непредвиденная ошибка:
Traceback (most recent call last):
  File "/home/shliamb/Desktop/WORK_FOLDER/chatgpt/app/run_bot.py", line 9, in <module>
    from tele_bot import start_bot
  File "/home/shliamb/Desktop/WORK_FOLDER/chatgpt/app/tele_bot.py", line 4, in <module>
    from open_ai import open_ai
ImportError: cannot import name 'open_ai' from 'open_ai' (/home/shliamb/Desktop/WORK_FOLDER/chatgpt/app/open_ai.py)
2024-01-26 11:16:14,853 - httpx - INFO - HTTP Request: POST https://api.openai.com/v1/chat/completions "HTTP/1.1 200 OK"
2024-01-26 11:17:18,988 - logging_bot - ERROR - Произошла непредвиденная ошибка:
Traceback (most recent call last):
  File "/home/shliamb/Desktop/WORK_FOLDER/chatgpt/app/run_bot.py", line 9, in <module>
    from tele_bot import start_bot
  File "/home/shliamb/Desktop/WORK_FOLDER/chatgpt/app/tele_bot.py", line 4, in <module>
    from open_ai import main, total_answer
ImportError: cannot import name 'total_answer' from 'open_ai' (/home/shliamb/Desktop/WORK_FOLDER/chatgpt/app/open_ai.py)
2024-01-26 11:18:18,872 - logging_bot - ERROR - Произошла непредвиденная ошибка:
Traceback (most recent call last):
  File "/home/shliamb/Desktop/WORK_FOLDER/chatgpt/app/run_bot.py", line 9, in <module>
    from tele_bot import start_bot
  File "/home/shliamb/Desktop/WORK_FOLDER/chatgpt/app/tele_bot.py", line 4, in <module>
    from open_ai import main, total_answer
ImportError: cannot import name 'total_answer' from 'open_ai' (/home/shliamb/Desktop/WORK_FOLDER/chatgpt/app/open_ai.py)
2024-01-26 11:18:36,365 - httpx - INFO - HTTP Request: POST https://api.openai.com/v1/chat/completions "HTTP/1.1 200 OK"
2024-01-26 11:21:01,076 - logging_bot - ERROR - Произошла непредвиденная ошибка:
Traceback (most recent call last):
  File "/home/shliamb/Desktop/WORK_FOLDER/chatgpt/app/run_bot.py", line 9, in <module>
    from tele_bot import start_bot
  File "/home/shliamb/Desktop/WORK_FOLDER/chatgpt/app/tele_bot.py", line 6, in <module>
    from open_ai import total_answer
ImportError: cannot import name 'total_answer' from 'open_ai' (/home/shliamb/Desktop/WORK_FOLDER/chatgpt/app/open_ai.py)
2024-01-26 11:36:18,668 - logging_bot - ERROR - Произошла непредвиденная ошибка:
Traceback (most recent call last):
  File "/home/shliamb/Desktop/WORK_FOLDER/chatgpt/app/run_bot.py", line 9, in <module>
    from tele_bot import start_bot
  File "/home/shliamb/Desktop/WORK_FOLDER/chatgpt/app/tele_bot.py", line 6, in <module>
    from open_ai import total_answer
ImportError: cannot import name 'total_answer' from 'open_ai' (/home/shliamb/Desktop/WORK_FOLDER/chatgpt/app/open_ai.py)
2024-01-26 11:36:51,858 - httpx - INFO - HTTP Request: POST https://api.openai.com/v1/chat/completions "HTTP/1.1 200 OK"
2024-01-26 11:37:13,011 - openai._base_client - INFO - Retrying request to /chat/completions in 0.867927 seconds
2024-01-26 11:38:21,521 - httpx - INFO - HTTP Request: POST https://api.openai.com/v1/chat/completions "HTTP/1.1 200 OK"
2024-01-26 11:38:29,023 - openai._base_client - INFO - Retrying request to /chat/completions in 0.948170 seconds
2024-01-26 11:39:44,572 - httpx - INFO - HTTP Request: POST https://api.openai.com/v1/chat/completions "HTTP/1.1 200 OK"
2024-01-26 11:39:51,694 - openai._base_client - INFO - Retrying request to /chat/completions in 0.951211 seconds
2024-01-26 11:41:14,237 - httpx - INFO - HTTP Request: POST https://api.openai.com/v1/chat/completions "HTTP/1.1 200 OK"
2024-01-26 11:41:21,515 - openai._base_client - INFO - Retrying request to /chat/completions in 0.828195 seconds
2024-01-26 11:42:14,557 - logging_bot - ERROR - Произошла непредвиденная ошибка:
Traceback (most recent call last):
  File "/home/shliamb/Desktop/WORK_FOLDER/chatgpt/app/run_bot.py", line 9, in <module>
    from tele_bot import start_bot
  File "/home/shliamb/Desktop/WORK_FOLDER/chatgpt/app/tele_bot.py", line 5, in <module>
    from open_ai import main #, total_answer
    ^^^^^^^^^^^^^^^^^^^^^^^^
  File "/home/shliamb/Desktop/WORK_FOLDER/chatgpt/app/open_ai.py", line 28, in <module>
    asyncio.run(main())
                ^^^^^^
TypeError: main() missing 1 required positional argument: 'question'
2024-01-26 11:42:18,412 - logging_bot - ERROR - Произошла непредвиденная ошибка:
Traceback (most recent call last):
  File "/home/shliamb/Desktop/WORK_FOLDER/chatgpt/app/run_bot.py", line 9, in <module>
    from tele_bot import start_bot
  File "/home/shliamb/Desktop/WORK_FOLDER/chatgpt/app/tele_bot.py", line 5, in <module>
    from open_ai import main #, total_answer
    ^^^^^^^^^^^^^^^^^^^^^^^^
  File "/home/shliamb/Desktop/WORK_FOLDER/chatgpt/app/open_ai.py", line 28, in <module>
    asyncio.run(main())
                ^^^^^^
TypeError: main() missing 1 required positional argument: 'question'
2024-01-26 11:42:38,978 - httpx - INFO - HTTP Request: POST https://api.openai.com/v1/chat/completions "HTTP/1.1 200 OK"
2024-01-26 11:46:36,523 - logging_bot - ERROR - Произошла непредвиденная ошибка:
Traceback (most recent call last):
  File "/home/shliamb/Desktop/WORK_FOLDER/chatgpt/app/run_bot.py", line 9, in <module>
    from tele_bot import start_bot
  File "/home/shliamb/Desktop/WORK_FOLDER/chatgpt/app/tele_bot.py", line 52, in <module>
    start_bot = bot.polling()
                ^^^^^^^^^^^^^
  File "/home/shliamb/Desktop/WORK_FOLDER/chatgpt/myvenv/lib/python3.11/site-packages/telebot/__init__.py", line 1045, in polling
    self.__threaded_polling(non_stop=non_stop, interval=interval, timeout=timeout, long_polling_timeout=long_polling_timeout,
  File "/home/shliamb/Desktop/WORK_FOLDER/chatgpt/myvenv/lib/python3.11/site-packages/telebot/__init__.py", line 1120, in __threaded_polling
    raise e
  File "/home/shliamb/Desktop/WORK_FOLDER/chatgpt/myvenv/lib/python3.11/site-packages/telebot/__init__.py", line 1082, in __threaded_polling
    self.worker_pool.raise_exceptions()
  File "/home/shliamb/Desktop/WORK_FOLDER/chatgpt/myvenv/lib/python3.11/site-packages/telebot/util.py", line 147, in raise_exceptions
    raise self.exception_info
  File "/home/shliamb/Desktop/WORK_FOLDER/chatgpt/myvenv/lib/python3.11/site-packages/telebot/util.py", line 90, in run
    task(*args, **kwargs)
  File "/home/shliamb/Desktop/WORK_FOLDER/chatgpt/myvenv/lib/python3.11/site-packages/telebot/__init__.py", line 6793, in _run_middlewares_and_handler
    result = handler['function'](message)
             ^^^^^^^^^^^^^^^^^^^^^^^^^^^^
  File "/home/shliamb/Desktop/WORK_FOLDER/chatgpt/app/tele_bot.py", line 47, in handle_message
    loop = asyncio.get_event_loop()
           ^^^^^^^^^^^^^^^^^^^^^^^^
  File "/usr/lib/python3.11/asyncio/events.py", line 677, in get_event_loop
    raise RuntimeError('There is no current event loop in thread %r.'
RuntimeError: There is no current event loop in thread 'WorkerThread1'.
2024-01-26 11:48:28,994 - httpx - INFO - HTTP Request: POST https://api.openai.com/v1/chat/completions "HTTP/1.1 200 OK"
2024-01-26 11:48:33,671 - openai._base_client - INFO - Retrying request to /chat/completions in 0.858954 seconds
2024-01-26 11:48:35,953 - httpx - INFO - HTTP Request: POST https://api.openai.com/v1/chat/completions "HTTP/1.1 200 OK"
2024-01-26 11:49:05,181 - httpx - INFO - HTTP Request: POST https://api.openai.com/v1/chat/completions "HTTP/1.1 200 OK"
2024-01-26 11:49:47,483 - httpx - INFO - HTTP Request: POST https://api.openai.com/v1/chat/completions "HTTP/1.1 200 OK"
2024-01-26 11:50:35,026 - httpx - INFO - HTTP Request: POST https://api.openai.com/v1/chat/completions "HTTP/1.1 200 OK"
2024-01-26 11:52:35,512 - httpx - INFO - HTTP Request: POST https://api.openai.com/v1/chat/completions "HTTP/1.1 200 OK"
2024-01-26 11:53:46,287 - httpx - INFO - HTTP Request: POST https://api.openai.com/v1/chat/completions "HTTP/1.1 200 OK"
2024-01-26 11:54:15,200 - httpx - INFO - HTTP Request: POST https://api.openai.com/v1/chat/completions "HTTP/1.1 200 OK"
2024-01-26 11:56:10,968 - httpx - INFO - HTTP Request: POST https://api.openai.com/v1/chat/completions "HTTP/1.1 200 OK"
2024-01-26 11:59:23,060 - httpx - INFO - HTTP Request: POST https://api.openai.com/v1/chat/completions "HTTP/1.1 200 OK"
2024-01-26 12:00:54,956 - httpx - INFO - HTTP Request: POST https://api.openai.com/v1/chat/completions "HTTP/1.1 200 OK"
2024-01-26 12:09:27,300 - httpx - INFO - HTTP Request: POST https://api.openai.com/v1/chat/completions "HTTP/1.1 200 OK"
2024-01-26 12:13:32,584 - httpx - INFO - HTTP Request: POST https://api.openai.com/v1/chat/completions "HTTP/1.1 200 OK"
2024-01-26 12:14:34,094 - httpx - INFO - HTTP Request: POST https://api.openai.com/v1/chat/completions "HTTP/1.1 200 OK"
2024-01-26 12:16:06,606 - httpx - INFO - HTTP Request: POST https://api.openai.com/v1/chat/completions "HTTP/1.1 200 OK"
2024-01-26 12:19:32,161 - httpx - INFO - HTTP Request: POST https://api.openai.com/v1/chat/completions "HTTP/1.1 200 OK"
2024-01-26 12:21:18,821 - httpx - INFO - HTTP Request: POST https://api.openai.com/v1/chat/completions "HTTP/1.1 200 OK"
2024-01-26 12:21:18,834 - logging_bot - ERROR - Произошла непредвиденная ошибка:
Traceback (most recent call last):
  File "/home/shliamb/Desktop/WORK_FOLDER/chatgpt/app/run_bot.py", line 9, in <module>
    from tele_bot import start_bot
  File "/home/shliamb/Desktop/WORK_FOLDER/chatgpt/app/tele_bot.py", line 52, in <module>
    start_bot = bot.polling()
                ^^^^^^^^^^^^^
  File "/home/shliamb/Desktop/WORK_FOLDER/chatgpt/myvenv/lib/python3.11/site-packages/telebot/__init__.py", line 1045, in polling
    self.__threaded_polling(non_stop=non_stop, interval=interval, timeout=timeout, long_polling_timeout=long_polling_timeout,
  File "/home/shliamb/Desktop/WORK_FOLDER/chatgpt/myvenv/lib/python3.11/site-packages/telebot/__init__.py", line 1120, in __threaded_polling
    raise e
  File "/home/shliamb/Desktop/WORK_FOLDER/chatgpt/myvenv/lib/python3.11/site-packages/telebot/__init__.py", line 1082, in __threaded_polling
    self.worker_pool.raise_exceptions()
  File "/home/shliamb/Desktop/WORK_FOLDER/chatgpt/myvenv/lib/python3.11/site-packages/telebot/util.py", line 147, in raise_exceptions
    raise self.exception_info
  File "/home/shliamb/Desktop/WORK_FOLDER/chatgpt/myvenv/lib/python3.11/site-packages/telebot/util.py", line 90, in run
    task(*args, **kwargs)
  File "/home/shliamb/Desktop/WORK_FOLDER/chatgpt/myvenv/lib/python3.11/site-packages/telebot/__init__.py", line 6793, in _run_middlewares_and_handler
    result = handler['function'](message)
             ^^^^^^^^^^^^^^^^^^^^^^^^^^^^
  File "/home/shliamb/Desktop/WORK_FOLDER/chatgpt/app/tele_bot.py", line 49, in handle_message
    loop.run_until_complete(run_main())
  File "/usr/lib/python3.11/asyncio/base_events.py", line 653, in run_until_complete
    return future.result()
           ^^^^^^^^^^^^^^^
  File "/home/shliamb/Desktop/WORK_FOLDER/chatgpt/app/tele_bot.py", line 45, in run_main
    bot.reply_to(message, f"{result[0]}\n- - - - - - - - - - - - - - - - - - - - - - - - - - - - -\n**Версия модели**: {result[1]}\n*Завершенные* токены: {result[2]}\n_Подсказки токены_: {result[3]}\nВсего токенов: {result[4]}",'<b>bold text</b> and <i>italic text</i> and <code>monospaced text</code>', parse_mode='HTML')
TypeError: TeleBot.reply_to() takes 3 positional arguments but 4 were given
2024-01-26 12:22:13,260 - httpx - INFO - HTTP Request: POST https://api.openai.com/v1/chat/completions "HTTP/1.1 200 OK"
2024-01-26 12:23:55,003 - httpx - INFO - HTTP Request: POST https://api.openai.com/v1/chat/completions "HTTP/1.1 200 OK"
2024-01-26 12:24:53,428 - httpx - INFO - HTTP Request: POST https://api.openai.com/v1/chat/completions "HTTP/1.1 200 OK"
2024-01-26 12:24:53,652 - TeleBot - ERROR - Threaded polling exception: A request to the Telegram API was unsuccessful. Error code: 400. Description: Bad Request: chat not found
2024-01-26 12:24:53,653 - TeleBot - ERROR - Exception traceback:
Traceback (most recent call last):
  File "/home/shliamb/Desktop/WORK_FOLDER/chatgpt/myvenv/lib/python3.11/site-packages/telebot/__init__.py", line 1082, in __threaded_polling
    self.worker_pool.raise_exceptions()
  File "/home/shliamb/Desktop/WORK_FOLDER/chatgpt/myvenv/lib/python3.11/site-packages/telebot/util.py", line 147, in raise_exceptions
    raise self.exception_info
  File "/home/shliamb/Desktop/WORK_FOLDER/chatgpt/myvenv/lib/python3.11/site-packages/telebot/util.py", line 90, in run
    task(*args, **kwargs)
  File "/home/shliamb/Desktop/WORK_FOLDER/chatgpt/myvenv/lib/python3.11/site-packages/telebot/__init__.py", line 6793, in _run_middlewares_and_handler
    result = handler['function'](message)
             ^^^^^^^^^^^^^^^^^^^^^^^^^^^^
  File "/home/shliamb/Desktop/WORK_FOLDER/chatgpt/app/tele_bot.py", line 50, in handle_message
    loop.run_until_complete(run_main())
  File "/usr/lib/python3.11/asyncio/base_events.py", line 653, in run_until_complete
    return future.result()
           ^^^^^^^^^^^^^^^
  File "/home/shliamb/Desktop/WORK_FOLDER/chatgpt/app/tele_bot.py", line 46, in run_main
    bot.send_message(message, '<b>bold text</b> and <i>italic text</i> and <code>monospaced text</code>', parse_mode='HTML')
  File "/home/shliamb/Desktop/WORK_FOLDER/chatgpt/myvenv/lib/python3.11/site-packages/telebot/__init__.py", line 1541, in send_message
    apihelper.send_message(
  File "/home/shliamb/Desktop/WORK_FOLDER/chatgpt/myvenv/lib/python3.11/site-packages/telebot/apihelper.py", line 266, in send_message
    return _make_request(token, method_url, params=payload, method='post')
           ^^^^^^^^^^^^^^^^^^^^^^^^^^^^^^^^^^^^^^^^^^^^^^^^^^^^^^^^^^^^^^^
  File "/home/shliamb/Desktop/WORK_FOLDER/chatgpt/myvenv/lib/python3.11/site-packages/telebot/apihelper.py", line 164, in _make_request
    json_result = _check_result(method_name, result)
                  ^^^^^^^^^^^^^^^^^^^^^^^^^^^^^^^^^^
  File "/home/shliamb/Desktop/WORK_FOLDER/chatgpt/myvenv/lib/python3.11/site-packages/telebot/apihelper.py", line 191, in _check_result
    raise ApiTelegramException(method_name, result, result_json)
telebot.apihelper.ApiTelegramException: A request to the Telegram API was unsuccessful. Error code: 400. Description: Bad Request: chat not found

2024-01-26 12:24:53,653 - logging_bot - ERROR - Произошла непредвиденная ошибка:
Traceback (most recent call last):
  File "/home/shliamb/Desktop/WORK_FOLDER/chatgpt/app/run_bot.py", line 10, in <module>
    start_bot(none_stop=True, timeout=60)
TypeError: 'NoneType' object is not callable
2024-01-26 12:25:30,301 - httpx - INFO - HTTP Request: POST https://api.openai.com/v1/chat/completions "HTTP/1.1 200 OK"
2024-01-26 12:28:36,480 - httpx - INFO - HTTP Request: POST https://api.openai.com/v1/chat/completions "HTTP/1.1 200 OK"
2024-01-26 12:34:12,759 - httpx - INFO - HTTP Request: POST https://api.openai.com/v1/chat/completions "HTTP/1.1 200 OK"
2024-01-26 12:36:31,218 - httpx - INFO - HTTP Request: POST https://api.openai.com/v1/chat/completions "HTTP/1.1 200 OK"
2024-01-26 12:36:31,234 - logging_bot - ERROR - Произошла непредвиденная ошибка:
Traceback (most recent call last):
  File "/home/shliamb/Desktop/WORK_FOLDER/chatgpt/app/run_bot.py", line 9, in <module>
    from tele_bot import start_bot
  File "/home/shliamb/Desktop/WORK_FOLDER/chatgpt/app/tele_bot.py", line 56, in <module>
    start_bot = bot.polling()
                ^^^^^^^^^^^^^
  File "/home/shliamb/Desktop/WORK_FOLDER/chatgpt/myvenv/lib/python3.11/site-packages/telebot/__init__.py", line 1045, in polling
    self.__threaded_polling(non_stop=non_stop, interval=interval, timeout=timeout, long_polling_timeout=long_polling_timeout,
  File "/home/shliamb/Desktop/WORK_FOLDER/chatgpt/myvenv/lib/python3.11/site-packages/telebot/__init__.py", line 1120, in __threaded_polling
    raise e
  File "/home/shliamb/Desktop/WORK_FOLDER/chatgpt/myvenv/lib/python3.11/site-packages/telebot/__init__.py", line 1082, in __threaded_polling
    self.worker_pool.raise_exceptions()
  File "/home/shliamb/Desktop/WORK_FOLDER/chatgpt/myvenv/lib/python3.11/site-packages/telebot/util.py", line 147, in raise_exceptions
    raise self.exception_info
  File "/home/shliamb/Desktop/WORK_FOLDER/chatgpt/myvenv/lib/python3.11/site-packages/telebot/util.py", line 90, in run
    task(*args, **kwargs)
  File "/home/shliamb/Desktop/WORK_FOLDER/chatgpt/myvenv/lib/python3.11/site-packages/telebot/__init__.py", line 6793, in _run_middlewares_and_handler
    result = handler['function'](message)
             ^^^^^^^^^^^^^^^^^^^^^^^^^^^^
  File "/home/shliamb/Desktop/WORK_FOLDER/chatgpt/app/tele_bot.py", line 53, in handle_message
    loop.run_until_complete(run_main())
  File "/usr/lib/python3.11/asyncio/base_events.py", line 653, in run_until_complete
    return future.result()
           ^^^^^^^^^^^^^^^
  File "/home/shliamb/Desktop/WORK_FOLDER/chatgpt/app/tele_bot.py", line 47, in run_main
    result[0] = 'bold text'
    ~~~~~~^^^
TypeError: 'tuple' object does not support item assignment
2024-01-26 12:37:51,268 - httpx - INFO - HTTP Request: POST https://api.openai.com/v1/chat/completions "HTTP/1.1 200 OK"
2024-01-26 12:38:50,216 - httpx - INFO - HTTP Request: POST https://api.openai.com/v1/chat/completions "HTTP/1.1 200 OK"
2024-01-26 12:41:23,710 - httpx - INFO - HTTP Request: POST https://api.openai.com/v1/chat/completions "HTTP/1.1 200 OK"
2024-01-26 12:44:52,050 - httpx - INFO - HTTP Request: POST https://api.openai.com/v1/chat/completions "HTTP/1.1 200 OK"
2024-01-26 12:52:52,876 - httpx - INFO - HTTP Request: POST https://api.openai.com/v1/chat/completions "HTTP/1.1 200 OK"
2024-01-26 12:59:06,490 - httpx - INFO - HTTP Request: POST https://api.openai.com/v1/chat/completions "HTTP/1.1 200 OK"
2024-01-26 12:59:51,536 - httpx - INFO - HTTP Request: POST https://api.openai.com/v1/chat/completions "HTTP/1.1 200 OK"
2024-01-26 12:59:51,762 - TeleBot - ERROR - Threaded polling exception: A request to the Telegram API was unsuccessful. Error code: 400. Description: Bad Request: can't parse entities: Unsupported start tag "div" at byte offset 381
2024-01-26 12:59:51,765 - TeleBot - ERROR - Exception traceback:
Traceback (most recent call last):
  File "/home/shliamb/Desktop/WORK_FOLDER/chatgpt/myvenv/lib/python3.11/site-packages/telebot/__init__.py", line 1082, in __threaded_polling
    self.worker_pool.raise_exceptions()
  File "/home/shliamb/Desktop/WORK_FOLDER/chatgpt/myvenv/lib/python3.11/site-packages/telebot/util.py", line 147, in raise_exceptions
    raise self.exception_info
  File "/home/shliamb/Desktop/WORK_FOLDER/chatgpt/myvenv/lib/python3.11/site-packages/telebot/util.py", line 90, in run
    task(*args, **kwargs)
  File "/home/shliamb/Desktop/WORK_FOLDER/chatgpt/myvenv/lib/python3.11/site-packages/telebot/__init__.py", line 6793, in _run_middlewares_and_handler
    result = handler['function'](message)
             ^^^^^^^^^^^^^^^^^^^^^^^^^^^^
  File "/home/shliamb/Desktop/WORK_FOLDER/chatgpt/app/tele_bot.py", line 58, in handle_message
    loop.run_until_complete(run_main())
  File "/usr/lib/python3.11/asyncio/base_events.py", line 653, in run_until_complete
    return future.result()
           ^^^^^^^^^^^^^^^
  File "/home/shliamb/Desktop/WORK_FOLDER/chatgpt/app/tele_bot.py", line 54, in run_main
    bot.reply_to(message, send, parse_mode='HTML')
  File "/home/shliamb/Desktop/WORK_FOLDER/chatgpt/myvenv/lib/python3.11/site-packages/telebot/__init__.py", line 4520, in reply_to
    return self.send_message(message.chat.id, text, reply_to_message_id=message.message_id, **kwargs)
           ^^^^^^^^^^^^^^^^^^^^^^^^^^^^^^^^^^^^^^^^^^^^^^^^^^^^^^^^^^^^^^^^^^^^^^^^^^^^^^^^^^^^^^^^^^
  File "/home/shliamb/Desktop/WORK_FOLDER/chatgpt/myvenv/lib/python3.11/site-packages/telebot/__init__.py", line 1541, in send_message
    apihelper.send_message(
  File "/home/shliamb/Desktop/WORK_FOLDER/chatgpt/myvenv/lib/python3.11/site-packages/telebot/apihelper.py", line 266, in send_message
    return _make_request(token, method_url, params=payload, method='post')
           ^^^^^^^^^^^^^^^^^^^^^^^^^^^^^^^^^^^^^^^^^^^^^^^^^^^^^^^^^^^^^^^
  File "/home/shliamb/Desktop/WORK_FOLDER/chatgpt/myvenv/lib/python3.11/site-packages/telebot/apihelper.py", line 164, in _make_request
    json_result = _check_result(method_name, result)
                  ^^^^^^^^^^^^^^^^^^^^^^^^^^^^^^^^^^
  File "/home/shliamb/Desktop/WORK_FOLDER/chatgpt/myvenv/lib/python3.11/site-packages/telebot/apihelper.py", line 191, in _check_result
    raise ApiTelegramException(method_name, result, result_json)
telebot.apihelper.ApiTelegramException: A request to the Telegram API was unsuccessful. Error code: 400. Description: Bad Request: can't parse entities: Unsupported start tag "div" at byte offset 381

2024-01-26 12:59:51,765 - logging_bot - ERROR - Произошла непредвиденная ошибка:
Traceback (most recent call last):
  File "/home/shliamb/Desktop/WORK_FOLDER/chatgpt/app/run_bot.py", line 10, in <module>
    start_bot(none_stop=True, timeout=60)
TypeError: 'NoneType' object is not callable
2024-01-26 13:02:10,197 - httpx - INFO - HTTP Request: POST https://api.openai.com/v1/chat/completions "HTTP/1.1 200 OK"
2024-01-26 13:02:10,580 - TeleBot - ERROR - Threaded polling exception: A request to the Telegram API was unsuccessful. Error code: 400. Description: Bad Request: can't parse entities: Unsupported start tag "div" at byte offset 604
2024-01-26 13:02:10,581 - TeleBot - ERROR - Exception traceback:
Traceback (most recent call last):
  File "/home/shliamb/Desktop/WORK_FOLDER/chatgpt/myvenv/lib/python3.11/site-packages/telebot/__init__.py", line 1082, in __threaded_polling
    self.worker_pool.raise_exceptions()
  File "/home/shliamb/Desktop/WORK_FOLDER/chatgpt/myvenv/lib/python3.11/site-packages/telebot/util.py", line 147, in raise_exceptions
    raise self.exception_info
  File "/home/shliamb/Desktop/WORK_FOLDER/chatgpt/myvenv/lib/python3.11/site-packages/telebot/util.py", line 90, in run
    task(*args, **kwargs)
  File "/home/shliamb/Desktop/WORK_FOLDER/chatgpt/myvenv/lib/python3.11/site-packages/telebot/__init__.py", line 6793, in _run_middlewares_and_handler
    result = handler['function'](message)
             ^^^^^^^^^^^^^^^^^^^^^^^^^^^^
  File "/home/shliamb/Desktop/WORK_FOLDER/chatgpt/app/tele_bot.py", line 60, in handle_message
    loop.run_until_complete(run_main())
  File "/usr/lib/python3.11/asyncio/base_events.py", line 653, in run_until_complete
    return future.result()
           ^^^^^^^^^^^^^^^
  File "/home/shliamb/Desktop/WORK_FOLDER/chatgpt/app/tele_bot.py", line 56, in run_main
    bot.reply_to(message, send, parse_mode='HTML')
  File "/home/shliamb/Desktop/WORK_FOLDER/chatgpt/myvenv/lib/python3.11/site-packages/telebot/__init__.py", line 4520, in reply_to
    return self.send_message(message.chat.id, text, reply_to_message_id=message.message_id, **kwargs)
           ^^^^^^^^^^^^^^^^^^^^^^^^^^^^^^^^^^^^^^^^^^^^^^^^^^^^^^^^^^^^^^^^^^^^^^^^^^^^^^^^^^^^^^^^^^
  File "/home/shliamb/Desktop/WORK_FOLDER/chatgpt/myvenv/lib/python3.11/site-packages/telebot/__init__.py", line 1541, in send_message
    apihelper.send_message(
  File "/home/shliamb/Desktop/WORK_FOLDER/chatgpt/myvenv/lib/python3.11/site-packages/telebot/apihelper.py", line 266, in send_message
    return _make_request(token, method_url, params=payload, method='post')
           ^^^^^^^^^^^^^^^^^^^^^^^^^^^^^^^^^^^^^^^^^^^^^^^^^^^^^^^^^^^^^^^
  File "/home/shliamb/Desktop/WORK_FOLDER/chatgpt/myvenv/lib/python3.11/site-packages/telebot/apihelper.py", line 164, in _make_request
    json_result = _check_result(method_name, result)
                  ^^^^^^^^^^^^^^^^^^^^^^^^^^^^^^^^^^
  File "/home/shliamb/Desktop/WORK_FOLDER/chatgpt/myvenv/lib/python3.11/site-packages/telebot/apihelper.py", line 191, in _check_result
    raise ApiTelegramException(method_name, result, result_json)
telebot.apihelper.ApiTelegramException: A request to the Telegram API was unsuccessful. Error code: 400. Description: Bad Request: can't parse entities: Unsupported start tag "div" at byte offset 604

2024-01-26 13:02:10,581 - logging_bot - ERROR - Произошла непредвиденная ошибка:
Traceback (most recent call last):
  File "/home/shliamb/Desktop/WORK_FOLDER/chatgpt/app/run_bot.py", line 10, in <module>
    start_bot(none_stop=True, timeout=60)
TypeError: 'NoneType' object is not callable
2024-01-26 13:05:46,112 - httpx - INFO - HTTP Request: POST https://api.openai.com/v1/chat/completions "HTTP/1.1 200 OK"
2024-01-26 13:07:03,814 - httpx - INFO - HTTP Request: POST https://api.openai.com/v1/chat/completions "HTTP/1.1 200 OK"
2024-01-26 13:07:04,077 - TeleBot - ERROR - Threaded polling exception: A request to the Telegram API was unsuccessful. Error code: 400. Description: Bad Request: can't parse entities: Unsupported start tag "div" at byte offset 630
2024-01-26 13:07:04,080 - TeleBot - ERROR - Exception traceback:
Traceback (most recent call last):
  File "/home/shliamb/Desktop/WORK_FOLDER/chatgpt/myvenv/lib/python3.11/site-packages/telebot/__init__.py", line 1082, in __threaded_polling
    self.worker_pool.raise_exceptions()
  File "/home/shliamb/Desktop/WORK_FOLDER/chatgpt/myvenv/lib/python3.11/site-packages/telebot/util.py", line 147, in raise_exceptions
    raise self.exception_info
  File "/home/shliamb/Desktop/WORK_FOLDER/chatgpt/myvenv/lib/python3.11/site-packages/telebot/util.py", line 90, in run
    task(*args, **kwargs)
  File "/home/shliamb/Desktop/WORK_FOLDER/chatgpt/myvenv/lib/python3.11/site-packages/telebot/__init__.py", line 6793, in _run_middlewares_and_handler
    result = handler['function'](message)
             ^^^^^^^^^^^^^^^^^^^^^^^^^^^^
  File "/home/shliamb/Desktop/WORK_FOLDER/chatgpt/app/tele_bot.py", line 59, in handle_message
    loop.run_until_complete(run_main())
  File "/usr/lib/python3.11/asyncio/base_events.py", line 653, in run_until_complete
    return future.result()
           ^^^^^^^^^^^^^^^
  File "/home/shliamb/Desktop/WORK_FOLDER/chatgpt/app/tele_bot.py", line 55, in run_main
    bot.reply_to(message, send, parse_mode='HTML')
  File "/home/shliamb/Desktop/WORK_FOLDER/chatgpt/myvenv/lib/python3.11/site-packages/telebot/__init__.py", line 4520, in reply_to
    return self.send_message(message.chat.id, text, reply_to_message_id=message.message_id, **kwargs)
           ^^^^^^^^^^^^^^^^^^^^^^^^^^^^^^^^^^^^^^^^^^^^^^^^^^^^^^^^^^^^^^^^^^^^^^^^^^^^^^^^^^^^^^^^^^
  File "/home/shliamb/Desktop/WORK_FOLDER/chatgpt/myvenv/lib/python3.11/site-packages/telebot/__init__.py", line 1541, in send_message
    apihelper.send_message(
  File "/home/shliamb/Desktop/WORK_FOLDER/chatgpt/myvenv/lib/python3.11/site-packages/telebot/apihelper.py", line 266, in send_message
    return _make_request(token, method_url, params=payload, method='post')
           ^^^^^^^^^^^^^^^^^^^^^^^^^^^^^^^^^^^^^^^^^^^^^^^^^^^^^^^^^^^^^^^
  File "/home/shliamb/Desktop/WORK_FOLDER/chatgpt/myvenv/lib/python3.11/site-packages/telebot/apihelper.py", line 164, in _make_request
    json_result = _check_result(method_name, result)
                  ^^^^^^^^^^^^^^^^^^^^^^^^^^^^^^^^^^
  File "/home/shliamb/Desktop/WORK_FOLDER/chatgpt/myvenv/lib/python3.11/site-packages/telebot/apihelper.py", line 191, in _check_result
    raise ApiTelegramException(method_name, result, result_json)
telebot.apihelper.ApiTelegramException: A request to the Telegram API was unsuccessful. Error code: 400. Description: Bad Request: can't parse entities: Unsupported start tag "div" at byte offset 630

2024-01-26 13:07:04,081 - logging_bot - ERROR - Произошла непредвиденная ошибка:
Traceback (most recent call last):
  File "/home/shliamb/Desktop/WORK_FOLDER/chatgpt/app/run_bot.py", line 10, in <module>
    start_bot(none_stop=True, timeout=60)
TypeError: 'NoneType' object is not callable
2024-01-26 13:13:08,713 - httpx - INFO - HTTP Request: POST https://api.openai.com/v1/chat/completions "HTTP/1.1 200 OK"
2024-01-26 13:13:08,969 - TeleBot - ERROR - Threaded polling exception: A request to the Telegram API was unsuccessful. Error code: 400. Description: Bad Request: can't parse entities: Character '>' is reserved and must be escaped with the preceding '\'
2024-01-26 13:13:08,970 - TeleBot - ERROR - Exception traceback:
Traceback (most recent call last):
  File "/home/shliamb/Desktop/WORK_FOLDER/chatgpt/myvenv/lib/python3.11/site-packages/telebot/__init__.py", line 1082, in __threaded_polling
    self.worker_pool.raise_exceptions()
  File "/home/shliamb/Desktop/WORK_FOLDER/chatgpt/myvenv/lib/python3.11/site-packages/telebot/util.py", line 147, in raise_exceptions
    raise self.exception_info
  File "/home/shliamb/Desktop/WORK_FOLDER/chatgpt/myvenv/lib/python3.11/site-packages/telebot/util.py", line 90, in run
    task(*args, **kwargs)
  File "/home/shliamb/Desktop/WORK_FOLDER/chatgpt/myvenv/lib/python3.11/site-packages/telebot/__init__.py", line 6793, in _run_middlewares_and_handler
    result = handler['function'](message)
             ^^^^^^^^^^^^^^^^^^^^^^^^^^^^
  File "/home/shliamb/Desktop/WORK_FOLDER/chatgpt/app/tele_bot.py", line 59, in handle_message
    loop.run_until_complete(run_main())
  File "/usr/lib/python3.11/asyncio/base_events.py", line 653, in run_until_complete
    return future.result()
           ^^^^^^^^^^^^^^^
  File "/home/shliamb/Desktop/WORK_FOLDER/chatgpt/app/tele_bot.py", line 55, in run_main
    bot.reply_to(message, send, parse_mode='MarkdownV2')
  File "/home/shliamb/Desktop/WORK_FOLDER/chatgpt/myvenv/lib/python3.11/site-packages/telebot/__init__.py", line 4520, in reply_to
    return self.send_message(message.chat.id, text, reply_to_message_id=message.message_id, **kwargs)
           ^^^^^^^^^^^^^^^^^^^^^^^^^^^^^^^^^^^^^^^^^^^^^^^^^^^^^^^^^^^^^^^^^^^^^^^^^^^^^^^^^^^^^^^^^^
  File "/home/shliamb/Desktop/WORK_FOLDER/chatgpt/myvenv/lib/python3.11/site-packages/telebot/__init__.py", line 1541, in send_message
    apihelper.send_message(
  File "/home/shliamb/Desktop/WORK_FOLDER/chatgpt/myvenv/lib/python3.11/site-packages/telebot/apihelper.py", line 266, in send_message
    return _make_request(token, method_url, params=payload, method='post')
           ^^^^^^^^^^^^^^^^^^^^^^^^^^^^^^^^^^^^^^^^^^^^^^^^^^^^^^^^^^^^^^^
  File "/home/shliamb/Desktop/WORK_FOLDER/chatgpt/myvenv/lib/python3.11/site-packages/telebot/apihelper.py", line 164, in _make_request
    json_result = _check_result(method_name, result)
                  ^^^^^^^^^^^^^^^^^^^^^^^^^^^^^^^^^^
  File "/home/shliamb/Desktop/WORK_FOLDER/chatgpt/myvenv/lib/python3.11/site-packages/telebot/apihelper.py", line 191, in _check_result
    raise ApiTelegramException(method_name, result, result_json)
telebot.apihelper.ApiTelegramException: A request to the Telegram API was unsuccessful. Error code: 400. Description: Bad Request: can't parse entities: Character '>' is reserved and must be escaped with the preceding '\'

2024-01-26 13:13:08,970 - logging_bot - ERROR - Произошла непредвиденная ошибка:
Traceback (most recent call last):
  File "/home/shliamb/Desktop/WORK_FOLDER/chatgpt/app/run_bot.py", line 10, in <module>
    start_bot(none_stop=True, timeout=60)
TypeError: 'NoneType' object is not callable
2024-01-26 13:16:47,627 - httpx - INFO - HTTP Request: POST https://api.openai.com/v1/chat/completions "HTTP/1.1 200 OK"
2024-01-26 13:16:47,896 - TeleBot - ERROR - Threaded polling exception: A request to the Telegram API was unsuccessful. Error code: 400. Description: Bad Request: can't parse entities: Character '>' is reserved and must be escaped with the preceding '\'
2024-01-26 13:16:47,899 - TeleBot - ERROR - Exception traceback:
Traceback (most recent call last):
  File "/home/shliamb/Desktop/WORK_FOLDER/chatgpt/myvenv/lib/python3.11/site-packages/telebot/__init__.py", line 1082, in __threaded_polling
    self.worker_pool.raise_exceptions()
  File "/home/shliamb/Desktop/WORK_FOLDER/chatgpt/myvenv/lib/python3.11/site-packages/telebot/util.py", line 147, in raise_exceptions
    raise self.exception_info
  File "/home/shliamb/Desktop/WORK_FOLDER/chatgpt/myvenv/lib/python3.11/site-packages/telebot/util.py", line 90, in run
    task(*args, **kwargs)
  File "/home/shliamb/Desktop/WORK_FOLDER/chatgpt/myvenv/lib/python3.11/site-packages/telebot/__init__.py", line 6793, in _run_middlewares_and_handler
    result = handler['function'](message)
             ^^^^^^^^^^^^^^^^^^^^^^^^^^^^
  File "/home/shliamb/Desktop/WORK_FOLDER/chatgpt/app/tele_bot.py", line 59, in handle_message
    loop.run_until_complete(run_main())
  File "/usr/lib/python3.11/asyncio/base_events.py", line 653, in run_until_complete
    return future.result()
           ^^^^^^^^^^^^^^^
  File "/home/shliamb/Desktop/WORK_FOLDER/chatgpt/app/tele_bot.py", line 55, in run_main
    bot.reply_to(message, send, parse_mode='MarkdownV2')
  File "/home/shliamb/Desktop/WORK_FOLDER/chatgpt/myvenv/lib/python3.11/site-packages/telebot/__init__.py", line 4520, in reply_to
    return self.send_message(message.chat.id, text, reply_to_message_id=message.message_id, **kwargs)
           ^^^^^^^^^^^^^^^^^^^^^^^^^^^^^^^^^^^^^^^^^^^^^^^^^^^^^^^^^^^^^^^^^^^^^^^^^^^^^^^^^^^^^^^^^^
  File "/home/shliamb/Desktop/WORK_FOLDER/chatgpt/myvenv/lib/python3.11/site-packages/telebot/__init__.py", line 1541, in send_message
    apihelper.send_message(
  File "/home/shliamb/Desktop/WORK_FOLDER/chatgpt/myvenv/lib/python3.11/site-packages/telebot/apihelper.py", line 266, in send_message
    return _make_request(token, method_url, params=payload, method='post')
           ^^^^^^^^^^^^^^^^^^^^^^^^^^^^^^^^^^^^^^^^^^^^^^^^^^^^^^^^^^^^^^^
  File "/home/shliamb/Desktop/WORK_FOLDER/chatgpt/myvenv/lib/python3.11/site-packages/telebot/apihelper.py", line 164, in _make_request
    json_result = _check_result(method_name, result)
                  ^^^^^^^^^^^^^^^^^^^^^^^^^^^^^^^^^^
  File "/home/shliamb/Desktop/WORK_FOLDER/chatgpt/myvenv/lib/python3.11/site-packages/telebot/apihelper.py", line 191, in _check_result
    raise ApiTelegramException(method_name, result, result_json)
telebot.apihelper.ApiTelegramException: A request to the Telegram API was unsuccessful. Error code: 400. Description: Bad Request: can't parse entities: Character '>' is reserved and must be escaped with the preceding '\'

2024-01-26 13:16:47,900 - logging_bot - ERROR - Произошла непредвиденная ошибка:
Traceback (most recent call last):
  File "/home/shliamb/Desktop/WORK_FOLDER/chatgpt/app/run_bot.py", line 10, in <module>
    start_bot(none_stop=True, timeout=60)
TypeError: 'NoneType' object is not callable
2024-01-26 13:18:55,478 - httpx - INFO - HTTP Request: POST https://api.openai.com/v1/chat/completions "HTTP/1.1 200 OK"
2024-01-26 13:18:55,738 - TeleBot - ERROR - Threaded polling exception: A request to the Telegram API was unsuccessful. Error code: 400. Description: Bad Request: can't parse entities: Character '-' is reserved and must be escaped with the preceding '\'
2024-01-26 13:18:55,741 - TeleBot - ERROR - Exception traceback:
Traceback (most recent call last):
  File "/home/shliamb/Desktop/WORK_FOLDER/chatgpt/myvenv/lib/python3.11/site-packages/telebot/__init__.py", line 1082, in __threaded_polling
    self.worker_pool.raise_exceptions()
  File "/home/shliamb/Desktop/WORK_FOLDER/chatgpt/myvenv/lib/python3.11/site-packages/telebot/util.py", line 147, in raise_exceptions
    raise self.exception_info
  File "/home/shliamb/Desktop/WORK_FOLDER/chatgpt/myvenv/lib/python3.11/site-packages/telebot/util.py", line 90, in run
    task(*args, **kwargs)
  File "/home/shliamb/Desktop/WORK_FOLDER/chatgpt/myvenv/lib/python3.11/site-packages/telebot/__init__.py", line 6793, in _run_middlewares_and_handler
    result = handler['function'](message)
             ^^^^^^^^^^^^^^^^^^^^^^^^^^^^
  File "/home/shliamb/Desktop/WORK_FOLDER/chatgpt/app/tele_bot.py", line 55, in handle_message
    loop.run_until_complete(run_main())
  File "/usr/lib/python3.11/asyncio/base_events.py", line 653, in run_until_complete
    return future.result()
           ^^^^^^^^^^^^^^^
  File "/home/shliamb/Desktop/WORK_FOLDER/chatgpt/app/tele_bot.py", line 51, in run_main
    bot.reply_to(message, send, parse_mode='MarkdownV2')
  File "/home/shliamb/Desktop/WORK_FOLDER/chatgpt/myvenv/lib/python3.11/site-packages/telebot/__init__.py", line 4520, in reply_to
    return self.send_message(message.chat.id, text, reply_to_message_id=message.message_id, **kwargs)
           ^^^^^^^^^^^^^^^^^^^^^^^^^^^^^^^^^^^^^^^^^^^^^^^^^^^^^^^^^^^^^^^^^^^^^^^^^^^^^^^^^^^^^^^^^^
  File "/home/shliamb/Desktop/WORK_FOLDER/chatgpt/myvenv/lib/python3.11/site-packages/telebot/__init__.py", line 1541, in send_message
    apihelper.send_message(
  File "/home/shliamb/Desktop/WORK_FOLDER/chatgpt/myvenv/lib/python3.11/site-packages/telebot/apihelper.py", line 266, in send_message
    return _make_request(token, method_url, params=payload, method='post')
           ^^^^^^^^^^^^^^^^^^^^^^^^^^^^^^^^^^^^^^^^^^^^^^^^^^^^^^^^^^^^^^^
  File "/home/shliamb/Desktop/WORK_FOLDER/chatgpt/myvenv/lib/python3.11/site-packages/telebot/apihelper.py", line 164, in _make_request
    json_result = _check_result(method_name, result)
                  ^^^^^^^^^^^^^^^^^^^^^^^^^^^^^^^^^^
  File "/home/shliamb/Desktop/WORK_FOLDER/chatgpt/myvenv/lib/python3.11/site-packages/telebot/apihelper.py", line 191, in _check_result
    raise ApiTelegramException(method_name, result, result_json)
telebot.apihelper.ApiTelegramException: A request to the Telegram API was unsuccessful. Error code: 400. Description: Bad Request: can't parse entities: Character '-' is reserved and must be escaped with the preceding '\'

2024-01-26 13:18:55,741 - logging_bot - ERROR - Произошла непредвиденная ошибка:
Traceback (most recent call last):
  File "/home/shliamb/Desktop/WORK_FOLDER/chatgpt/app/run_bot.py", line 10, in <module>
    start_bot(none_stop=True, timeout=60)
TypeError: 'NoneType' object is not callable
2024-01-26 13:20:12,538 - httpx - INFO - HTTP Request: POST https://api.openai.com/v1/chat/completions "HTTP/1.1 200 OK"
2024-01-26 13:20:12,769 - TeleBot - ERROR - Threaded polling exception: A request to the Telegram API was unsuccessful. Error code: 400. Description: Bad Request: can't parse entities: Unsupported start tag "div" at byte offset 461
2024-01-26 13:20:12,770 - TeleBot - ERROR - Exception traceback:
Traceback (most recent call last):
  File "/home/shliamb/Desktop/WORK_FOLDER/chatgpt/myvenv/lib/python3.11/site-packages/telebot/__init__.py", line 1082, in __threaded_polling
    self.worker_pool.raise_exceptions()
  File "/home/shliamb/Desktop/WORK_FOLDER/chatgpt/myvenv/lib/python3.11/site-packages/telebot/util.py", line 147, in raise_exceptions
    raise self.exception_info
  File "/home/shliamb/Desktop/WORK_FOLDER/chatgpt/myvenv/lib/python3.11/site-packages/telebot/util.py", line 90, in run
    task(*args, **kwargs)
  File "/home/shliamb/Desktop/WORK_FOLDER/chatgpt/myvenv/lib/python3.11/site-packages/telebot/__init__.py", line 6793, in _run_middlewares_and_handler
    result = handler['function'](message)
             ^^^^^^^^^^^^^^^^^^^^^^^^^^^^
  File "/home/shliamb/Desktop/WORK_FOLDER/chatgpt/app/tele_bot.py", line 55, in handle_message
    loop.run_until_complete(run_main())
  File "/usr/lib/python3.11/asyncio/base_events.py", line 653, in run_until_complete
    return future.result()
           ^^^^^^^^^^^^^^^
  File "/home/shliamb/Desktop/WORK_FOLDER/chatgpt/app/tele_bot.py", line 51, in run_main
    bot.reply_to(message, send, parse_mode='HTML')
  File "/home/shliamb/Desktop/WORK_FOLDER/chatgpt/myvenv/lib/python3.11/site-packages/telebot/__init__.py", line 4520, in reply_to
    return self.send_message(message.chat.id, text, reply_to_message_id=message.message_id, **kwargs)
           ^^^^^^^^^^^^^^^^^^^^^^^^^^^^^^^^^^^^^^^^^^^^^^^^^^^^^^^^^^^^^^^^^^^^^^^^^^^^^^^^^^^^^^^^^^
  File "/home/shliamb/Desktop/WORK_FOLDER/chatgpt/myvenv/lib/python3.11/site-packages/telebot/__init__.py", line 1541, in send_message
    apihelper.send_message(
  File "/home/shliamb/Desktop/WORK_FOLDER/chatgpt/myvenv/lib/python3.11/site-packages/telebot/apihelper.py", line 266, in send_message
    return _make_request(token, method_url, params=payload, method='post')
           ^^^^^^^^^^^^^^^^^^^^^^^^^^^^^^^^^^^^^^^^^^^^^^^^^^^^^^^^^^^^^^^
  File "/home/shliamb/Desktop/WORK_FOLDER/chatgpt/myvenv/lib/python3.11/site-packages/telebot/apihelper.py", line 164, in _make_request
    json_result = _check_result(method_name, result)
                  ^^^^^^^^^^^^^^^^^^^^^^^^^^^^^^^^^^
  File "/home/shliamb/Desktop/WORK_FOLDER/chatgpt/myvenv/lib/python3.11/site-packages/telebot/apihelper.py", line 191, in _check_result
    raise ApiTelegramException(method_name, result, result_json)
telebot.apihelper.ApiTelegramException: A request to the Telegram API was unsuccessful. Error code: 400. Description: Bad Request: can't parse entities: Unsupported start tag "div" at byte offset 461

2024-01-26 13:20:12,770 - logging_bot - ERROR - Произошла непредвиденная ошибка:
Traceback (most recent call last):
  File "/home/shliamb/Desktop/WORK_FOLDER/chatgpt/app/run_bot.py", line 10, in <module>
    start_bot(none_stop=True, timeout=60)
TypeError: 'NoneType' object is not callable
2024-01-26 13:20:57,439 - httpx - INFO - HTTP Request: POST https://api.openai.com/v1/chat/completions "HTTP/1.1 200 OK"
2024-01-26 13:20:57,646 - TeleBot - ERROR - Threaded polling exception: A request to the Telegram API was unsuccessful. Error code: 400. Description: Bad Request: unsupported parse_mode
2024-01-26 13:20:57,647 - TeleBot - ERROR - Exception traceback:
Traceback (most recent call last):
  File "/home/shliamb/Desktop/WORK_FOLDER/chatgpt/myvenv/lib/python3.11/site-packages/telebot/__init__.py", line 1082, in __threaded_polling
    self.worker_pool.raise_exceptions()
  File "/home/shliamb/Desktop/WORK_FOLDER/chatgpt/myvenv/lib/python3.11/site-packages/telebot/util.py", line 147, in raise_exceptions
    raise self.exception_info
  File "/home/shliamb/Desktop/WORK_FOLDER/chatgpt/myvenv/lib/python3.11/site-packages/telebot/util.py", line 90, in run
    task(*args, **kwargs)
  File "/home/shliamb/Desktop/WORK_FOLDER/chatgpt/myvenv/lib/python3.11/site-packages/telebot/__init__.py", line 6793, in _run_middlewares_and_handler
    result = handler['function'](message)
             ^^^^^^^^^^^^^^^^^^^^^^^^^^^^
  File "/home/shliamb/Desktop/WORK_FOLDER/chatgpt/app/tele_bot.py", line 55, in handle_message
    loop.run_until_complete(run_main())
  File "/usr/lib/python3.11/asyncio/base_events.py", line 653, in run_until_complete
    return future.result()
           ^^^^^^^^^^^^^^^
  File "/home/shliamb/Desktop/WORK_FOLDER/chatgpt/app/tele_bot.py", line 51, in run_main
    bot.reply_to(message, send, parse_mode='text') #parse_mode='HTML'
    ^^^^^^^^^^^^^^^^^^^^^^^^^^^^^^^^^^^^^^^^^^^^^^
  File "/home/shliamb/Desktop/WORK_FOLDER/chatgpt/myvenv/lib/python3.11/site-packages/telebot/__init__.py", line 4520, in reply_to
    return self.send_message(message.chat.id, text, reply_to_message_id=message.message_id, **kwargs)
           ^^^^^^^^^^^^^^^^^^^^^^^^^^^^^^^^^^^^^^^^^^^^^^^^^^^^^^^^^^^^^^^^^^^^^^^^^^^^^^^^^^^^^^^^^^
  File "/home/shliamb/Desktop/WORK_FOLDER/chatgpt/myvenv/lib/python3.11/site-packages/telebot/__init__.py", line 1541, in send_message
    apihelper.send_message(
  File "/home/shliamb/Desktop/WORK_FOLDER/chatgpt/myvenv/lib/python3.11/site-packages/telebot/apihelper.py", line 266, in send_message
    return _make_request(token, method_url, params=payload, method='post')
           ^^^^^^^^^^^^^^^^^^^^^^^^^^^^^^^^^^^^^^^^^^^^^^^^^^^^^^^^^^^^^^^
  File "/home/shliamb/Desktop/WORK_FOLDER/chatgpt/myvenv/lib/python3.11/site-packages/telebot/apihelper.py", line 164, in _make_request
    json_result = _check_result(method_name, result)
                  ^^^^^^^^^^^^^^^^^^^^^^^^^^^^^^^^^^
  File "/home/shliamb/Desktop/WORK_FOLDER/chatgpt/myvenv/lib/python3.11/site-packages/telebot/apihelper.py", line 191, in _check_result
    raise ApiTelegramException(method_name, result, result_json)
telebot.apihelper.ApiTelegramException: A request to the Telegram API was unsuccessful. Error code: 400. Description: Bad Request: unsupported parse_mode

2024-01-26 13:20:57,647 - logging_bot - ERROR - Произошла непредвиденная ошибка:
Traceback (most recent call last):
  File "/home/shliamb/Desktop/WORK_FOLDER/chatgpt/app/run_bot.py", line 10, in <module>
    start_bot(none_stop=True, timeout=60)
TypeError: 'NoneType' object is not callable
2024-01-26 13:22:22,920 - httpx - INFO - HTTP Request: POST https://api.openai.com/v1/chat/completions "HTTP/1.1 200 OK"
2024-01-26 13:22:35,442 - httpx - INFO - HTTP Request: POST https://api.openai.com/v1/chat/completions "HTTP/1.1 200 OK"
2024-01-26 13:22:35,752 - TeleBot - ERROR - Threaded polling exception: A request to the Telegram API was unsuccessful. Error code: 400. Description: Bad Request: can't parse entities: Unsupported start tag "div" at byte offset 223
2024-01-26 13:22:35,754 - TeleBot - ERROR - Exception traceback:
Traceback (most recent call last):
  File "/home/shliamb/Desktop/WORK_FOLDER/chatgpt/myvenv/lib/python3.11/site-packages/telebot/__init__.py", line 1082, in __threaded_polling
    self.worker_pool.raise_exceptions()
  File "/home/shliamb/Desktop/WORK_FOLDER/chatgpt/myvenv/lib/python3.11/site-packages/telebot/util.py", line 147, in raise_exceptions
    raise self.exception_info
  File "/home/shliamb/Desktop/WORK_FOLDER/chatgpt/myvenv/lib/python3.11/site-packages/telebot/util.py", line 90, in run
    task(*args, **kwargs)
  File "/home/shliamb/Desktop/WORK_FOLDER/chatgpt/myvenv/lib/python3.11/site-packages/telebot/__init__.py", line 6793, in _run_middlewares_and_handler
    result = handler['function'](message)
             ^^^^^^^^^^^^^^^^^^^^^^^^^^^^
  File "/home/shliamb/Desktop/WORK_FOLDER/chatgpt/app/tele_bot.py", line 51, in handle_message
    loop.run_until_complete(run_main())
  File "/usr/lib/python3.11/asyncio/base_events.py", line 653, in run_until_complete
    return future.result()
           ^^^^^^^^^^^^^^^
  File "/home/shliamb/Desktop/WORK_FOLDER/chatgpt/app/tele_bot.py", line 47, in run_main
    bot.reply_to(message, send, parse_mode='HTML')
  File "/home/shliamb/Desktop/WORK_FOLDER/chatgpt/myvenv/lib/python3.11/site-packages/telebot/__init__.py", line 4520, in reply_to
    return self.send_message(message.chat.id, text, reply_to_message_id=message.message_id, **kwargs)
           ^^^^^^^^^^^^^^^^^^^^^^^^^^^^^^^^^^^^^^^^^^^^^^^^^^^^^^^^^^^^^^^^^^^^^^^^^^^^^^^^^^^^^^^^^^
  File "/home/shliamb/Desktop/WORK_FOLDER/chatgpt/myvenv/lib/python3.11/site-packages/telebot/__init__.py", line 1541, in send_message
    apihelper.send_message(
  File "/home/shliamb/Desktop/WORK_FOLDER/chatgpt/myvenv/lib/python3.11/site-packages/telebot/apihelper.py", line 266, in send_message
    return _make_request(token, method_url, params=payload, method='post')
           ^^^^^^^^^^^^^^^^^^^^^^^^^^^^^^^^^^^^^^^^^^^^^^^^^^^^^^^^^^^^^^^
  File "/home/shliamb/Desktop/WORK_FOLDER/chatgpt/myvenv/lib/python3.11/site-packages/telebot/apihelper.py", line 164, in _make_request
    json_result = _check_result(method_name, result)
                  ^^^^^^^^^^^^^^^^^^^^^^^^^^^^^^^^^^
  File "/home/shliamb/Desktop/WORK_FOLDER/chatgpt/myvenv/lib/python3.11/site-packages/telebot/apihelper.py", line 191, in _check_result
    raise ApiTelegramException(method_name, result, result_json)
telebot.apihelper.ApiTelegramException: A request to the Telegram API was unsuccessful. Error code: 400. Description: Bad Request: can't parse entities: Unsupported start tag "div" at byte offset 223

2024-01-26 13:22:35,755 - logging_bot - ERROR - Произошла непредвиденная ошибка:
Traceback (most recent call last):
  File "/home/shliamb/Desktop/WORK_FOLDER/chatgpt/app/run_bot.py", line 10, in <module>
    start_bot(none_stop=True, timeout=60)
TypeError: 'NoneType' object is not callable
2024-01-26 13:22:58,376 - httpx - INFO - HTTP Request: POST https://api.openai.com/v1/chat/completions "HTTP/1.1 200 OK"
2024-01-26 13:22:58,592 - TeleBot - ERROR - Threaded polling exception: A request to the Telegram API was unsuccessful. Error code: 400. Description: Bad Request: unsupported parse_mode
2024-01-26 13:22:58,594 - TeleBot - ERROR - Exception traceback:
Traceback (most recent call last):
  File "/home/shliamb/Desktop/WORK_FOLDER/chatgpt/myvenv/lib/python3.11/site-packages/telebot/__init__.py", line 1082, in __threaded_polling
    self.worker_pool.raise_exceptions()
  File "/home/shliamb/Desktop/WORK_FOLDER/chatgpt/myvenv/lib/python3.11/site-packages/telebot/util.py", line 147, in raise_exceptions
    raise self.exception_info
  File "/home/shliamb/Desktop/WORK_FOLDER/chatgpt/myvenv/lib/python3.11/site-packages/telebot/util.py", line 90, in run
    task(*args, **kwargs)
  File "/home/shliamb/Desktop/WORK_FOLDER/chatgpt/myvenv/lib/python3.11/site-packages/telebot/__init__.py", line 6793, in _run_middlewares_and_handler
    result = handler['function'](message)
             ^^^^^^^^^^^^^^^^^^^^^^^^^^^^
  File "/home/shliamb/Desktop/WORK_FOLDER/chatgpt/app/tele_bot.py", line 51, in handle_message
    loop.run_until_complete(run_main())
  File "/usr/lib/python3.11/asyncio/base_events.py", line 653, in run_until_complete
    return future.result()
           ^^^^^^^^^^^^^^^
  File "/home/shliamb/Desktop/WORK_FOLDER/chatgpt/app/tele_bot.py", line 47, in run_main
    bot.reply_to(message, send, parse_mode='text')
  File "/home/shliamb/Desktop/WORK_FOLDER/chatgpt/myvenv/lib/python3.11/site-packages/telebot/__init__.py", line 4520, in reply_to
    return self.send_message(message.chat.id, text, reply_to_message_id=message.message_id, **kwargs)
           ^^^^^^^^^^^^^^^^^^^^^^^^^^^^^^^^^^^^^^^^^^^^^^^^^^^^^^^^^^^^^^^^^^^^^^^^^^^^^^^^^^^^^^^^^^
  File "/home/shliamb/Desktop/WORK_FOLDER/chatgpt/myvenv/lib/python3.11/site-packages/telebot/__init__.py", line 1541, in send_message
    apihelper.send_message(
  File "/home/shliamb/Desktop/WORK_FOLDER/chatgpt/myvenv/lib/python3.11/site-packages/telebot/apihelper.py", line 266, in send_message
    return _make_request(token, method_url, params=payload, method='post')
           ^^^^^^^^^^^^^^^^^^^^^^^^^^^^^^^^^^^^^^^^^^^^^^^^^^^^^^^^^^^^^^^
  File "/home/shliamb/Desktop/WORK_FOLDER/chatgpt/myvenv/lib/python3.11/site-packages/telebot/apihelper.py", line 164, in _make_request
    json_result = _check_result(method_name, result)
                  ^^^^^^^^^^^^^^^^^^^^^^^^^^^^^^^^^^
  File "/home/shliamb/Desktop/WORK_FOLDER/chatgpt/myvenv/lib/python3.11/site-packages/telebot/apihelper.py", line 191, in _check_result
    raise ApiTelegramException(method_name, result, result_json)
telebot.apihelper.ApiTelegramException: A request to the Telegram API was unsuccessful. Error code: 400. Description: Bad Request: unsupported parse_mode

2024-01-26 13:22:58,595 - logging_bot - ERROR - Произошла непредвиденная ошибка:
Traceback (most recent call last):
  File "/home/shliamb/Desktop/WORK_FOLDER/chatgpt/app/run_bot.py", line 10, in <module>
    start_bot(none_stop=True, timeout=60)
TypeError: 'NoneType' object is not callable
2024-01-26 13:23:27,597 - httpx - INFO - HTTP Request: POST https://api.openai.com/v1/chat/completions "HTTP/1.1 200 OK"
2024-01-26 13:23:44,871 - httpx - INFO - HTTP Request: POST https://api.openai.com/v1/chat/completions "HTTP/1.1 200 OK"
2024-01-26 13:24:47,999 - httpx - INFO - HTTP Request: POST https://api.openai.com/v1/chat/completions "HTTP/1.1 200 OK"
2024-01-26 13:25:02,507 - httpx - INFO - HTTP Request: POST https://api.openai.com/v1/chat/completions "HTTP/1.1 200 OK"
2024-01-26 13:25:54,808 - httpx - INFO - HTTP Request: POST https://api.openai.com/v1/chat/completions "HTTP/1.1 200 OK"
2024-01-26 13:26:09,523 - httpx - INFO - HTTP Request: POST https://api.openai.com/v1/chat/completions "HTTP/1.1 200 OK"
2024-01-26 13:45:11,382 - httpx - INFO - HTTP Request: POST https://api.openai.com/v1/chat/completions "HTTP/1.1 200 OK"
2024-01-26 13:45:56,860 - httpx - INFO - HTTP Request: POST https://api.openai.com/v1/chat/completions "HTTP/1.1 200 OK"
2024-01-26 13:45:57,070 - TeleBot - ERROR - Threaded polling exception: A request to the Telegram API was unsuccessful. Error code: 400. Description: Bad Request: can't parse entities: Unsupported start tag "div" at byte offset 3
2024-01-26 13:45:57,072 - TeleBot - ERROR - Exception traceback:
Traceback (most recent call last):
  File "/home/shliamb/Desktop/WORK_FOLDER/chatgpt/myvenv/lib/python3.11/site-packages/telebot/__init__.py", line 1082, in __threaded_polling
    self.worker_pool.raise_exceptions()
  File "/home/shliamb/Desktop/WORK_FOLDER/chatgpt/myvenv/lib/python3.11/site-packages/telebot/util.py", line 147, in raise_exceptions
    raise self.exception_info
  File "/home/shliamb/Desktop/WORK_FOLDER/chatgpt/myvenv/lib/python3.11/site-packages/telebot/util.py", line 90, in run
    task(*args, **kwargs)
  File "/home/shliamb/Desktop/WORK_FOLDER/chatgpt/myvenv/lib/python3.11/site-packages/telebot/__init__.py", line 6793, in _run_middlewares_and_handler
    result = handler['function'](message)
             ^^^^^^^^^^^^^^^^^^^^^^^^^^^^
  File "/home/shliamb/Desktop/WORK_FOLDER/chatgpt/app/tele_bot.py", line 53, in handle_message
    loop.run_until_complete(run_main())
  File "/usr/lib/python3.11/asyncio/base_events.py", line 653, in run_until_complete
    return future.result()
           ^^^^^^^^^^^^^^^
  File "/home/shliamb/Desktop/WORK_FOLDER/chatgpt/app/tele_bot.py", line 48, in run_main
    bot.reply_to(message, send, parse_mode='HTML')
  File "/home/shliamb/Desktop/WORK_FOLDER/chatgpt/myvenv/lib/python3.11/site-packages/telebot/__init__.py", line 4520, in reply_to
    return self.send_message(message.chat.id, text, reply_to_message_id=message.message_id, **kwargs)
           ^^^^^^^^^^^^^^^^^^^^^^^^^^^^^^^^^^^^^^^^^^^^^^^^^^^^^^^^^^^^^^^^^^^^^^^^^^^^^^^^^^^^^^^^^^
  File "/home/shliamb/Desktop/WORK_FOLDER/chatgpt/myvenv/lib/python3.11/site-packages/telebot/__init__.py", line 1541, in send_message
    apihelper.send_message(
  File "/home/shliamb/Desktop/WORK_FOLDER/chatgpt/myvenv/lib/python3.11/site-packages/telebot/apihelper.py", line 266, in send_message
    return _make_request(token, method_url, params=payload, method='post')
           ^^^^^^^^^^^^^^^^^^^^^^^^^^^^^^^^^^^^^^^^^^^^^^^^^^^^^^^^^^^^^^^
  File "/home/shliamb/Desktop/WORK_FOLDER/chatgpt/myvenv/lib/python3.11/site-packages/telebot/apihelper.py", line 164, in _make_request
    json_result = _check_result(method_name, result)
                  ^^^^^^^^^^^^^^^^^^^^^^^^^^^^^^^^^^
  File "/home/shliamb/Desktop/WORK_FOLDER/chatgpt/myvenv/lib/python3.11/site-packages/telebot/apihelper.py", line 191, in _check_result
    raise ApiTelegramException(method_name, result, result_json)
telebot.apihelper.ApiTelegramException: A request to the Telegram API was unsuccessful. Error code: 400. Description: Bad Request: can't parse entities: Unsupported start tag "div" at byte offset 3

2024-01-26 13:45:57,073 - logging_bot - ERROR - Произошла непредвиденная ошибка:
Traceback (most recent call last):
  File "/home/shliamb/Desktop/WORK_FOLDER/chatgpt/app/run_bot.py", line 10, in <module>
    start_bot(none_stop=True, timeout=60)
TypeError: 'NoneType' object is not callable
2024-01-26 13:46:39,823 - httpx - INFO - HTTP Request: POST https://api.openai.com/v1/chat/completions "HTTP/1.1 200 OK"
2024-01-26 13:46:40,025 - TeleBot - ERROR - Threaded polling exception: A request to the Telegram API was unsuccessful. Error code: 400. Description: Bad Request: can't parse entities: Unsupported start tag "div" at byte offset 9
2024-01-26 13:46:40,026 - TeleBot - ERROR - Exception traceback:
Traceback (most recent call last):
  File "/home/shliamb/Desktop/WORK_FOLDER/chatgpt/myvenv/lib/python3.11/site-packages/telebot/__init__.py", line 1082, in __threaded_polling
    self.worker_pool.raise_exceptions()
  File "/home/shliamb/Desktop/WORK_FOLDER/chatgpt/myvenv/lib/python3.11/site-packages/telebot/util.py", line 147, in raise_exceptions
    raise self.exception_info
  File "/home/shliamb/Desktop/WORK_FOLDER/chatgpt/myvenv/lib/python3.11/site-packages/telebot/util.py", line 90, in run
    task(*args, **kwargs)
  File "/home/shliamb/Desktop/WORK_FOLDER/chatgpt/myvenv/lib/python3.11/site-packages/telebot/__init__.py", line 6793, in _run_middlewares_and_handler
    result = handler['function'](message)
             ^^^^^^^^^^^^^^^^^^^^^^^^^^^^
  File "/home/shliamb/Desktop/WORK_FOLDER/chatgpt/app/tele_bot.py", line 53, in handle_message
    loop.run_until_complete(run_main())
  File "/usr/lib/python3.11/asyncio/base_events.py", line 653, in run_until_complete
    return future.result()
           ^^^^^^^^^^^^^^^
  File "/home/shliamb/Desktop/WORK_FOLDER/chatgpt/app/tele_bot.py", line 48, in run_main
    bot.reply_to(message, send, parse_mode='HTML')
  File "/home/shliamb/Desktop/WORK_FOLDER/chatgpt/myvenv/lib/python3.11/site-packages/telebot/__init__.py", line 4520, in reply_to
    return self.send_message(message.chat.id, text, reply_to_message_id=message.message_id, **kwargs)
           ^^^^^^^^^^^^^^^^^^^^^^^^^^^^^^^^^^^^^^^^^^^^^^^^^^^^^^^^^^^^^^^^^^^^^^^^^^^^^^^^^^^^^^^^^^
  File "/home/shliamb/Desktop/WORK_FOLDER/chatgpt/myvenv/lib/python3.11/site-packages/telebot/__init__.py", line 1541, in send_message
    apihelper.send_message(
  File "/home/shliamb/Desktop/WORK_FOLDER/chatgpt/myvenv/lib/python3.11/site-packages/telebot/apihelper.py", line 266, in send_message
    return _make_request(token, method_url, params=payload, method='post')
           ^^^^^^^^^^^^^^^^^^^^^^^^^^^^^^^^^^^^^^^^^^^^^^^^^^^^^^^^^^^^^^^
  File "/home/shliamb/Desktop/WORK_FOLDER/chatgpt/myvenv/lib/python3.11/site-packages/telebot/apihelper.py", line 164, in _make_request
    json_result = _check_result(method_name, result)
                  ^^^^^^^^^^^^^^^^^^^^^^^^^^^^^^^^^^
  File "/home/shliamb/Desktop/WORK_FOLDER/chatgpt/myvenv/lib/python3.11/site-packages/telebot/apihelper.py", line 191, in _check_result
    raise ApiTelegramException(method_name, result, result_json)
telebot.apihelper.ApiTelegramException: A request to the Telegram API was unsuccessful. Error code: 400. Description: Bad Request: can't parse entities: Unsupported start tag "div" at byte offset 9

2024-01-26 13:46:40,026 - logging_bot - ERROR - Произошла непредвиденная ошибка:
Traceback (most recent call last):
  File "/home/shliamb/Desktop/WORK_FOLDER/chatgpt/app/run_bot.py", line 10, in <module>
    start_bot(none_stop=True, timeout=60)
TypeError: 'NoneType' object is not callable
2024-01-26 13:46:59,394 - httpx - INFO - HTTP Request: POST https://api.openai.com/v1/chat/completions "HTTP/1.1 200 OK"
2024-01-26 13:47:58,708 - httpx - INFO - HTTP Request: POST https://api.openai.com/v1/chat/completions "HTTP/1.1 200 OK"
2024-01-26 13:47:58,929 - TeleBot - ERROR - Threaded polling exception: A request to the Telegram API was unsuccessful. Error code: 400. Description: Bad Request: can't parse entities: Unsupported start tag "div" at byte offset 12
2024-01-26 13:47:58,932 - TeleBot - ERROR - Exception traceback:
Traceback (most recent call last):
  File "/home/shliamb/Desktop/WORK_FOLDER/chatgpt/myvenv/lib/python3.11/site-packages/telebot/__init__.py", line 1082, in __threaded_polling
    self.worker_pool.raise_exceptions()
  File "/home/shliamb/Desktop/WORK_FOLDER/chatgpt/myvenv/lib/python3.11/site-packages/telebot/util.py", line 147, in raise_exceptions
    raise self.exception_info
  File "/home/shliamb/Desktop/WORK_FOLDER/chatgpt/myvenv/lib/python3.11/site-packages/telebot/util.py", line 90, in run
    task(*args, **kwargs)
  File "/home/shliamb/Desktop/WORK_FOLDER/chatgpt/myvenv/lib/python3.11/site-packages/telebot/__init__.py", line 6793, in _run_middlewares_and_handler
    result = handler['function'](message)
             ^^^^^^^^^^^^^^^^^^^^^^^^^^^^
  File "/home/shliamb/Desktop/WORK_FOLDER/chatgpt/app/tele_bot.py", line 53, in handle_message
    loop.run_until_complete(run_main())
  File "/usr/lib/python3.11/asyncio/base_events.py", line 653, in run_until_complete
    return future.result()
           ^^^^^^^^^^^^^^^
  File "/home/shliamb/Desktop/WORK_FOLDER/chatgpt/app/tele_bot.py", line 48, in run_main
    bot.reply_to(message, send, parse_mode='HTML')
  File "/home/shliamb/Desktop/WORK_FOLDER/chatgpt/myvenv/lib/python3.11/site-packages/telebot/__init__.py", line 4520, in reply_to
    return self.send_message(message.chat.id, text, reply_to_message_id=message.message_id, **kwargs)
           ^^^^^^^^^^^^^^^^^^^^^^^^^^^^^^^^^^^^^^^^^^^^^^^^^^^^^^^^^^^^^^^^^^^^^^^^^^^^^^^^^^^^^^^^^^
  File "/home/shliamb/Desktop/WORK_FOLDER/chatgpt/myvenv/lib/python3.11/site-packages/telebot/__init__.py", line 1541, in send_message
    apihelper.send_message(
  File "/home/shliamb/Desktop/WORK_FOLDER/chatgpt/myvenv/lib/python3.11/site-packages/telebot/apihelper.py", line 266, in send_message
    return _make_request(token, method_url, params=payload, method='post')
           ^^^^^^^^^^^^^^^^^^^^^^^^^^^^^^^^^^^^^^^^^^^^^^^^^^^^^^^^^^^^^^^
  File "/home/shliamb/Desktop/WORK_FOLDER/chatgpt/myvenv/lib/python3.11/site-packages/telebot/apihelper.py", line 164, in _make_request
    json_result = _check_result(method_name, result)
                  ^^^^^^^^^^^^^^^^^^^^^^^^^^^^^^^^^^
  File "/home/shliamb/Desktop/WORK_FOLDER/chatgpt/myvenv/lib/python3.11/site-packages/telebot/apihelper.py", line 191, in _check_result
    raise ApiTelegramException(method_name, result, result_json)
telebot.apihelper.ApiTelegramException: A request to the Telegram API was unsuccessful. Error code: 400. Description: Bad Request: can't parse entities: Unsupported start tag "div" at byte offset 12

2024-01-26 13:47:58,933 - logging_bot - ERROR - Произошла непредвиденная ошибка:
Traceback (most recent call last):
  File "/home/shliamb/Desktop/WORK_FOLDER/chatgpt/app/run_bot.py", line 10, in <module>
    start_bot(none_stop=True, timeout=60)
TypeError: 'NoneType' object is not callable
2024-01-26 13:50:55,042 - httpx - INFO - HTTP Request: POST https://api.openai.com/v1/chat/completions "HTTP/1.1 200 OK"
2024-01-26 13:52:08,194 - httpx - INFO - HTTP Request: POST https://api.openai.com/v1/chat/completions "HTTP/1.1 200 OK"
2024-01-26 14:02:06,461 - httpx - INFO - HTTP Request: POST https://api.openai.com/v1/chat/completions "HTTP/1.1 200 OK"
2024-01-26 14:02:47,881 - httpx - INFO - HTTP Request: POST https://api.openai.com/v1/chat/completions "HTTP/1.1 200 OK"
2024-01-26 16:00:04,693 - httpx - INFO - HTTP Request: POST https://api.openai.com/v1/chat/completions "HTTP/1.1 200 OK"
2024-01-26 16:04:06,051 - httpx - INFO - HTTP Request: POST https://api.openai.com/v1/chat/completions "HTTP/1.1 200 OK"
2024-01-26 17:23:01,679 - httpx - INFO - HTTP Request: POST https://api.openai.com/v1/chat/completions "HTTP/1.1 200 OK"
2024-01-26 17:35:42,527 - httpx - INFO - HTTP Request: POST https://api.openai.com/v1/chat/completions "HTTP/1.1 200 OK"
2024-01-26 17:46:23,295 - httpx - INFO - HTTP Request: POST https://api.openai.com/v1/chat/completions "HTTP/1.1 200 OK"
2024-01-26 17:49:25,856 - httpx - INFO - HTTP Request: POST https://api.openai.com/v1/chat/completions "HTTP/1.1 200 OK"
2024-01-26 17:49:34,271 - httpx - INFO - HTTP Request: POST https://api.openai.com/v1/chat/completions "HTTP/1.1 200 OK"
2024-01-26 18:09:53,367 - logging_bot - ERROR - Произошла непредвиденная ошибка:
Traceback (most recent call last):
  File "/home/shliamb/Desktop/WORK_FOLDER/chatgpt/app/run_bot.py", line 9, in <module>
    from tele_bot import start_bot
  File "/home/shliamb/Desktop/WORK_FOLDER/chatgpt/app/tele_bot.py", line 57, in <module>
    start_bot = bot.polling()
                ^^^^^^^^^^^^^
  File "/home/shliamb/Desktop/WORK_FOLDER/chatgpt/myvenv/lib/python3.11/site-packages/telebot/__init__.py", line 1045, in polling
    self.__threaded_polling(non_stop=non_stop, interval=interval, timeout=timeout, long_polling_timeout=long_polling_timeout,
  File "/home/shliamb/Desktop/WORK_FOLDER/chatgpt/myvenv/lib/python3.11/site-packages/telebot/__init__.py", line 1120, in __threaded_polling
    raise e
  File "/home/shliamb/Desktop/WORK_FOLDER/chatgpt/myvenv/lib/python3.11/site-packages/telebot/__init__.py", line 1082, in __threaded_polling
    self.worker_pool.raise_exceptions()
  File "/home/shliamb/Desktop/WORK_FOLDER/chatgpt/myvenv/lib/python3.11/site-packages/telebot/util.py", line 147, in raise_exceptions
    raise self.exception_info
  File "/home/shliamb/Desktop/WORK_FOLDER/chatgpt/myvenv/lib/python3.11/site-packages/telebot/util.py", line 90, in run
    task(*args, **kwargs)
  File "/home/shliamb/Desktop/WORK_FOLDER/chatgpt/myvenv/lib/python3.11/site-packages/telebot/__init__.py", line 6793, in _run_middlewares_and_handler
    result = handler['function'](message)
             ^^^^^^^^^^^^^^^^^^^^^^^^^^^^
  File "/home/shliamb/Desktop/WORK_FOLDER/chatgpt/app/tele_bot.py", line 54, in handle_message
    loop.run_until_complete(run_main())
  File "/usr/lib/python3.11/asyncio/base_events.py", line 653, in run_until_complete
    return future.result()
           ^^^^^^^^^^^^^^^
  File "/home/shliamb/Desktop/WORK_FOLDER/chatgpt/app/tele_bot.py", line 47, in run_main
    result = await main(question)
             ^^^^^^^^^^^^^^^^^^^^
  File "/home/shliamb/Desktop/WORK_FOLDER/chatgpt/app/open_ai.py", line 12, in main
    all_in = all_in.append(all_in)
             ^^^^^^
UnboundLocalError: cannot access local variable 'all_in' where it is not associated with a value
2024-01-26 18:11:00,621 - httpx - INFO - HTTP Request: POST https://api.openai.com/v1/chat/completions "HTTP/1.1 200 OK"
2024-01-26 18:11:20,687 - httpx - INFO - HTTP Request: POST https://api.openai.com/v1/chat/completions "HTTP/1.1 200 OK"
2024-01-26 18:17:42,738 - httpx - INFO - HTTP Request: POST https://api.openai.com/v1/chat/completions "HTTP/1.1 200 OK"
2024-01-26 18:17:53,031 - httpx - INFO - HTTP Request: POST https://api.openai.com/v1/chat/completions "HTTP/1.1 200 OK"
2024-01-26 18:24:00,705 - httpx - INFO - HTTP Request: POST https://api.openai.com/v1/chat/completions "HTTP/1.1 200 OK"
2024-01-26 18:26:29,688 - httpx - INFO - HTTP Request: POST https://api.openai.com/v1/chat/completions "HTTP/1.1 400 Bad Request"
2024-01-26 18:26:29,699 - logging_bot - ERROR - Произошла непредвиденная ошибка:
Traceback (most recent call last):
  File "/home/shliamb/Desktop/WORK_FOLDER/chatgpt/app/run_bot.py", line 9, in <module>
    from tele_bot import start_bot
  File "/home/shliamb/Desktop/WORK_FOLDER/chatgpt/app/tele_bot.py", line 57, in <module>
    start_bot = bot.polling()
                ^^^^^^^^^^^^^
  File "/home/shliamb/Desktop/WORK_FOLDER/chatgpt/myvenv/lib/python3.11/site-packages/telebot/__init__.py", line 1045, in polling
    self.__threaded_polling(non_stop=non_stop, interval=interval, timeout=timeout, long_polling_timeout=long_polling_timeout,
  File "/home/shliamb/Desktop/WORK_FOLDER/chatgpt/myvenv/lib/python3.11/site-packages/telebot/__init__.py", line 1120, in __threaded_polling
    raise e
  File "/home/shliamb/Desktop/WORK_FOLDER/chatgpt/myvenv/lib/python3.11/site-packages/telebot/__init__.py", line 1082, in __threaded_polling
    self.worker_pool.raise_exceptions()
  File "/home/shliamb/Desktop/WORK_FOLDER/chatgpt/myvenv/lib/python3.11/site-packages/telebot/util.py", line 147, in raise_exceptions
    raise self.exception_info
  File "/home/shliamb/Desktop/WORK_FOLDER/chatgpt/myvenv/lib/python3.11/site-packages/telebot/util.py", line 90, in run
    task(*args, **kwargs)
  File "/home/shliamb/Desktop/WORK_FOLDER/chatgpt/myvenv/lib/python3.11/site-packages/telebot/__init__.py", line 6793, in _run_middlewares_and_handler
    result = handler['function'](message)
             ^^^^^^^^^^^^^^^^^^^^^^^^^^^^
  File "/home/shliamb/Desktop/WORK_FOLDER/chatgpt/app/tele_bot.py", line 54, in handle_message
    loop.run_until_complete(run_main())
  File "/usr/lib/python3.11/asyncio/base_events.py", line 653, in run_until_complete
    return future.result()
           ^^^^^^^^^^^^^^^
  File "/home/shliamb/Desktop/WORK_FOLDER/chatgpt/app/tele_bot.py", line 47, in run_main
    result = await main(question)
             ^^^^^^^^^^^^^^^^^^^^
  File "/home/shliamb/Desktop/WORK_FOLDER/chatgpt/app/open_ai.py", line 17, in main
    chat_completion = await client.chat.completions.create(
                      ^^^^^^^^^^^^^^^^^^^^^^^^^^^^^^^^^^^^^
  File "/home/shliamb/Desktop/WORK_FOLDER/chatgpt/myvenv/lib/python3.11/site-packages/openai/resources/chat/completions.py", line 1291, in create
    return await self._post(
           ^^^^^^^^^^^^^^^^^
  File "/home/shliamb/Desktop/WORK_FOLDER/chatgpt/myvenv/lib/python3.11/site-packages/openai/_base_client.py", line 1578, in post
    return await self.request(cast_to, opts, stream=stream, stream_cls=stream_cls)
           ^^^^^^^^^^^^^^^^^^^^^^^^^^^^^^^^^^^^^^^^^^^^^^^^^^^^^^^^^^^^^^^^^^^^^^^
  File "/home/shliamb/Desktop/WORK_FOLDER/chatgpt/myvenv/lib/python3.11/site-packages/openai/_base_client.py", line 1339, in request
    return await self._request(
           ^^^^^^^^^^^^^^^^^^^^
  File "/home/shliamb/Desktop/WORK_FOLDER/chatgpt/myvenv/lib/python3.11/site-packages/openai/_base_client.py", line 1429, in _request
    raise self._make_status_error_from_response(err.response) from None
openai.BadRequestError: Error code: 400 - {'error': {'message': "'$.messages[0].content' is invalid. Please check the API reference: https://platform.openai.com/docs/api-reference.", 'type': 'invalid_request_error', 'param': None, 'code': None}}
2024-01-26 19:25:33,464 - httpx - INFO - HTTP Request: POST https://api.openai.com/v1/chat/completions "HTTP/1.1 200 OK"
2024-01-26 19:25:59,862 - httpx - INFO - HTTP Request: POST https://api.openai.com/v1/chat/completions "HTTP/1.1 200 OK"
2024-01-26 19:26:14,081 - httpx - INFO - HTTP Request: POST https://api.openai.com/v1/chat/completions "HTTP/1.1 200 OK"
2024-01-26 19:26:35,647 - httpx - INFO - HTTP Request: POST https://api.openai.com/v1/chat/completions "HTTP/1.1 200 OK"
2024-01-26 19:26:53,573 - httpx - INFO - HTTP Request: POST https://api.openai.com/v1/chat/completions "HTTP/1.1 200 OK"
2024-01-26 19:32:43,789 - httpx - INFO - HTTP Request: POST https://api.openai.com/v1/chat/completions "HTTP/1.1 200 OK"
2024-01-26 19:33:03,018 - httpx - INFO - HTTP Request: POST https://api.openai.com/v1/chat/completions "HTTP/1.1 200 OK"
2024-01-26 19:33:42,331 - httpx - INFO - HTTP Request: POST https://api.openai.com/v1/chat/completions "HTTP/1.1 200 OK"
2024-01-26 19:35:13,100 - httpx - INFO - HTTP Request: POST https://api.openai.com/v1/chat/completions "HTTP/1.1 200 OK"
2024-01-26 19:35:51,127 - httpx - INFO - HTTP Request: POST https://api.openai.com/v1/chat/completions "HTTP/1.1 200 OK"
2024-01-26 19:39:38,884 - httpx - INFO - HTTP Request: POST https://api.openai.com/v1/chat/completions "HTTP/1.1 200 OK"
2024-01-26 19:39:50,748 - httpx - INFO - HTTP Request: POST https://api.openai.com/v1/chat/completions "HTTP/1.1 200 OK"
2024-01-26 19:42:04,773 - httpx - INFO - HTTP Request: POST https://api.openai.com/v1/chat/completions "HTTP/1.1 200 OK"
2024-01-26 19:42:31,267 - httpx - INFO - HTTP Request: POST https://api.openai.com/v1/chat/completions "HTTP/1.1 200 OK"
2024-01-26 19:43:09,379 - httpx - INFO - HTTP Request: POST https://api.openai.com/v1/chat/completions "HTTP/1.1 200 OK"
2024-01-26 19:44:50,282 - httpx - INFO - HTTP Request: POST https://api.openai.com/v1/chat/completions "HTTP/1.1 200 OK"
2024-01-26 19:45:03,289 - httpx - INFO - HTTP Request: POST https://api.openai.com/v1/chat/completions "HTTP/1.1 200 OK"
2024-01-26 19:45:16,187 - httpx - INFO - HTTP Request: POST https://api.openai.com/v1/chat/completions "HTTP/1.1 200 OK"
2024-01-26 19:45:41,836 - httpx - INFO - HTTP Request: POST https://api.openai.com/v1/chat/completions "HTTP/1.1 200 OK"
2024-01-26 20:18:14,031 - httpx - INFO - HTTP Request: POST https://api.openai.com/v1/chat/completions "HTTP/1.1 404 Not Found"
2024-01-26 20:18:14,034 - logging_bot - ERROR - Произошла непредвиденная ошибка:
Traceback (most recent call last):
  File "/home/shliamb/Desktop/WORK_FOLDER/chatgpt/app/run_bot.py", line 9, in <module>
    from tele_bot import start_bot
  File "/home/shliamb/Desktop/WORK_FOLDER/chatgpt/app/tele_bot.py", line 57, in <module>
    start_bot = bot.polling()
                ^^^^^^^^^^^^^
  File "/home/shliamb/Desktop/WORK_FOLDER/chatgpt/myvenv/lib/python3.11/site-packages/telebot/__init__.py", line 1045, in polling
    self.__threaded_polling(non_stop=non_stop, interval=interval, timeout=timeout, long_polling_timeout=long_polling_timeout,
  File "/home/shliamb/Desktop/WORK_FOLDER/chatgpt/myvenv/lib/python3.11/site-packages/telebot/__init__.py", line 1120, in __threaded_polling
    raise e
  File "/home/shliamb/Desktop/WORK_FOLDER/chatgpt/myvenv/lib/python3.11/site-packages/telebot/__init__.py", line 1082, in __threaded_polling
    self.worker_pool.raise_exceptions()
  File "/home/shliamb/Desktop/WORK_FOLDER/chatgpt/myvenv/lib/python3.11/site-packages/telebot/util.py", line 147, in raise_exceptions
    raise self.exception_info
  File "/home/shliamb/Desktop/WORK_FOLDER/chatgpt/myvenv/lib/python3.11/site-packages/telebot/util.py", line 90, in run
    task(*args, **kwargs)
  File "/home/shliamb/Desktop/WORK_FOLDER/chatgpt/myvenv/lib/python3.11/site-packages/telebot/__init__.py", line 6793, in _run_middlewares_and_handler
    result = handler['function'](message)
             ^^^^^^^^^^^^^^^^^^^^^^^^^^^^
  File "/home/shliamb/Desktop/WORK_FOLDER/chatgpt/app/tele_bot.py", line 54, in handle_message
    loop.run_until_complete(run_main())
  File "/usr/lib/python3.11/asyncio/base_events.py", line 653, in run_until_complete
    return future.result()
           ^^^^^^^^^^^^^^^
  File "/home/shliamb/Desktop/WORK_FOLDER/chatgpt/app/tele_bot.py", line 47, in run_main
    result = await main(question)
             ^^^^^^^^^^^^^^^^^^^^
  File "/home/shliamb/Desktop/WORK_FOLDER/chatgpt/app/open_ai.py", line 18, in main
    chat_completion = await client.chat.completions.create(
                      ^^^^^^^^^^^^^^^^^^^^^^^^^^^^^^^^^^^^^
  File "/home/shliamb/Desktop/WORK_FOLDER/chatgpt/myvenv/lib/python3.11/site-packages/openai/resources/chat/completions.py", line 1291, in create
    return await self._post(
           ^^^^^^^^^^^^^^^^^
  File "/home/shliamb/Desktop/WORK_FOLDER/chatgpt/myvenv/lib/python3.11/site-packages/openai/_base_client.py", line 1578, in post
    return await self.request(cast_to, opts, stream=stream, stream_cls=stream_cls)
           ^^^^^^^^^^^^^^^^^^^^^^^^^^^^^^^^^^^^^^^^^^^^^^^^^^^^^^^^^^^^^^^^^^^^^^^
  File "/home/shliamb/Desktop/WORK_FOLDER/chatgpt/myvenv/lib/python3.11/site-packages/openai/_base_client.py", line 1339, in request
    return await self._request(
           ^^^^^^^^^^^^^^^^^^^^
  File "/home/shliamb/Desktop/WORK_FOLDER/chatgpt/myvenv/lib/python3.11/site-packages/openai/_base_client.py", line 1429, in _request
    raise self._make_status_error_from_response(err.response) from None
openai.NotFoundError: Error code: 404 - {'error': {'message': 'The model `text-davinci-002` has been deprecated, learn more here: https://platform.openai.com/docs/deprecations', 'type': 'invalid_request_error', 'param': None, 'code': 'model_not_found'}}
2024-01-26 20:18:54,861 - httpx - INFO - HTTP Request: POST https://api.openai.com/v1/chat/completions "HTTP/1.1 404 Not Found"
2024-01-26 20:18:54,864 - logging_bot - ERROR - Произошла непредвиденная ошибка:
Traceback (most recent call last):
  File "/home/shliamb/Desktop/WORK_FOLDER/chatgpt/app/run_bot.py", line 9, in <module>
    from tele_bot import start_bot
  File "/home/shliamb/Desktop/WORK_FOLDER/chatgpt/app/tele_bot.py", line 57, in <module>
    start_bot = bot.polling()
                ^^^^^^^^^^^^^
  File "/home/shliamb/Desktop/WORK_FOLDER/chatgpt/myvenv/lib/python3.11/site-packages/telebot/__init__.py", line 1045, in polling
    self.__threaded_polling(non_stop=non_stop, interval=interval, timeout=timeout, long_polling_timeout=long_polling_timeout,
  File "/home/shliamb/Desktop/WORK_FOLDER/chatgpt/myvenv/lib/python3.11/site-packages/telebot/__init__.py", line 1120, in __threaded_polling
    raise e
  File "/home/shliamb/Desktop/WORK_FOLDER/chatgpt/myvenv/lib/python3.11/site-packages/telebot/__init__.py", line 1082, in __threaded_polling
    self.worker_pool.raise_exceptions()
  File "/home/shliamb/Desktop/WORK_FOLDER/chatgpt/myvenv/lib/python3.11/site-packages/telebot/util.py", line 147, in raise_exceptions
    raise self.exception_info
  File "/home/shliamb/Desktop/WORK_FOLDER/chatgpt/myvenv/lib/python3.11/site-packages/telebot/util.py", line 90, in run
    task(*args, **kwargs)
  File "/home/shliamb/Desktop/WORK_FOLDER/chatgpt/myvenv/lib/python3.11/site-packages/telebot/__init__.py", line 6793, in _run_middlewares_and_handler
    result = handler['function'](message)
             ^^^^^^^^^^^^^^^^^^^^^^^^^^^^
  File "/home/shliamb/Desktop/WORK_FOLDER/chatgpt/app/tele_bot.py", line 54, in handle_message
    loop.run_until_complete(run_main())
  File "/usr/lib/python3.11/asyncio/base_events.py", line 653, in run_until_complete
    return future.result()
           ^^^^^^^^^^^^^^^
  File "/home/shliamb/Desktop/WORK_FOLDER/chatgpt/app/tele_bot.py", line 47, in run_main
    result = await main(question)
             ^^^^^^^^^^^^^^^^^^^^
  File "/home/shliamb/Desktop/WORK_FOLDER/chatgpt/app/open_ai.py", line 18, in main
    chat_completion = await client.chat.completions.create(
                      ^^^^^^^^^^^^^^^^^^^^^^^^^^^^^^^^^^^^^
  File "/home/shliamb/Desktop/WORK_FOLDER/chatgpt/myvenv/lib/python3.11/site-packages/openai/resources/chat/completions.py", line 1291, in create
    return await self._post(
           ^^^^^^^^^^^^^^^^^
  File "/home/shliamb/Desktop/WORK_FOLDER/chatgpt/myvenv/lib/python3.11/site-packages/openai/_base_client.py", line 1578, in post
    return await self.request(cast_to, opts, stream=stream, stream_cls=stream_cls)
           ^^^^^^^^^^^^^^^^^^^^^^^^^^^^^^^^^^^^^^^^^^^^^^^^^^^^^^^^^^^^^^^^^^^^^^^
  File "/home/shliamb/Desktop/WORK_FOLDER/chatgpt/myvenv/lib/python3.11/site-packages/openai/_base_client.py", line 1339, in request
    return await self._request(
           ^^^^^^^^^^^^^^^^^^^^
  File "/home/shliamb/Desktop/WORK_FOLDER/chatgpt/myvenv/lib/python3.11/site-packages/openai/_base_client.py", line 1429, in _request
    raise self._make_status_error_from_response(err.response) from None
openai.NotFoundError: Error code: 404 - {'error': {'message': 'The model `text-curie-003` does not exist', 'type': 'invalid_request_error', 'param': None, 'code': 'model_not_found'}}
2024-01-26 20:58:38,928 - httpx - INFO - HTTP Request: POST https://api.openai.com/v1/chat/completions "HTTP/1.1 200 OK"
