2024-01-27 20:23:45,401 - httpx - INFO - HTTP Request: POST https://api.openai.com/v1/chat/completions "HTTP/1.1 200 OK"
2024-01-27 20:46:41,891 - httpx - INFO - HTTP Request: POST https://api.openai.com/v1/chat/completions "HTTP/1.1 200 OK"
2024-01-27 20:47:41,135 - httpx - INFO - HTTP Request: POST https://api.openai.com/v1/chat/completions "HTTP/1.1 200 OK"
2024-01-27 21:14:10,155 - logging_bot - ERROR - Произошла непредвиденная ошибка:
Traceback (most recent call last):
  File "/home/shliamb/Desktop/WORK_FOLDER/chatgpt/app/run_bot.py", line 9, in <module>
    from tele_bot import start_bot
  File "/home/shliamb/Desktop/WORK_FOLDER/chatgpt/app/tele_bot.py", line 69, in <module>
    start_bot = bot.polling() # Запуск инициализируется в run_bot.py
                ^^^^^^^^^^^^^
  File "/home/shliamb/Desktop/WORK_FOLDER/chatgpt/myvenv/lib/python3.11/site-packages/telebot/__init__.py", line 1045, in polling
    self.__threaded_polling(non_stop=non_stop, interval=interval, timeout=timeout, long_polling_timeout=long_polling_timeout,
  File "/home/shliamb/Desktop/WORK_FOLDER/chatgpt/myvenv/lib/python3.11/site-packages/telebot/__init__.py", line 1120, in __threaded_polling
    raise e
  File "/home/shliamb/Desktop/WORK_FOLDER/chatgpt/myvenv/lib/python3.11/site-packages/telebot/__init__.py", line 1082, in __threaded_polling
    self.worker_pool.raise_exceptions()
  File "/home/shliamb/Desktop/WORK_FOLDER/chatgpt/myvenv/lib/python3.11/site-packages/telebot/util.py", line 147, in raise_exceptions
    raise self.exception_info
  File "/home/shliamb/Desktop/WORK_FOLDER/chatgpt/myvenv/lib/python3.11/site-packages/telebot/util.py", line 90, in run
    task(*args, **kwargs)
  File "/home/shliamb/Desktop/WORK_FOLDER/chatgpt/myvenv/lib/python3.11/site-packages/telebot/__init__.py", line 6793, in _run_middlewares_and_handler
    result = handler['function'](message)
             ^^^^^^^^^^^^^^^^^^^^^^^^^^^^
  File "/home/shliamb/Desktop/WORK_FOLDER/chatgpt/app/tele_bot.py", line 63, in handle_message
    loop.run_until_complete(run_main())
  File "/usr/lib/python3.11/asyncio/base_events.py", line 653, in run_until_complete
    return future.result()
           ^^^^^^^^^^^^^^^
  File "/home/shliamb/Desktop/WORK_FOLDER/chatgpt/app/tele_bot.py", line 57, in run_main
    result = await main(message.text, id)
             ^^^^^^^^^^^^^^^^^^^^^^^^^^^^
  File "/home/shliamb/Desktop/WORK_FOLDER/chatgpt/app/open_ai.py", line 13, in main
    read_data = read_chatgpt_setings(id)
                ^^^^^^^^^^^^^^^^^^^^^^^^
  File "/home/shliamb/Desktop/WORK_FOLDER/chatgpt/app/worker_db.py", line 49, in read_chatgpt_setings
    for data in read_data:
TypeError: 'SavedQuestion' object is not iterable
2024-01-27 21:16:47,645 - logging_bot - ERROR - Произошла непредвиденная ошибка:
Traceback (most recent call last):
  File "/home/shliamb/Desktop/WORK_FOLDER/chatgpt/app/run_bot.py", line 9, in <module>
    from tele_bot import start_bot
  File "/home/shliamb/Desktop/WORK_FOLDER/chatgpt/app/tele_bot.py", line 69, in <module>
    start_bot = bot.polling() # Запуск инициализируется в run_bot.py
                ^^^^^^^^^^^^^
  File "/home/shliamb/Desktop/WORK_FOLDER/chatgpt/myvenv/lib/python3.11/site-packages/telebot/__init__.py", line 1045, in polling
    self.__threaded_polling(non_stop=non_stop, interval=interval, timeout=timeout, long_polling_timeout=long_polling_timeout,
  File "/home/shliamb/Desktop/WORK_FOLDER/chatgpt/myvenv/lib/python3.11/site-packages/telebot/__init__.py", line 1120, in __threaded_polling
    raise e
  File "/home/shliamb/Desktop/WORK_FOLDER/chatgpt/myvenv/lib/python3.11/site-packages/telebot/__init__.py", line 1082, in __threaded_polling
    self.worker_pool.raise_exceptions()
  File "/home/shliamb/Desktop/WORK_FOLDER/chatgpt/myvenv/lib/python3.11/site-packages/telebot/util.py", line 147, in raise_exceptions
    raise self.exception_info
  File "/home/shliamb/Desktop/WORK_FOLDER/chatgpt/myvenv/lib/python3.11/site-packages/telebot/util.py", line 90, in run
    task(*args, **kwargs)
  File "/home/shliamb/Desktop/WORK_FOLDER/chatgpt/myvenv/lib/python3.11/site-packages/telebot/__init__.py", line 6793, in _run_middlewares_and_handler
    result = handler['function'](message)
             ^^^^^^^^^^^^^^^^^^^^^^^^^^^^
  File "/home/shliamb/Desktop/WORK_FOLDER/chatgpt/app/tele_bot.py", line 63, in handle_message
    loop.run_until_complete(run_main())
  File "/usr/lib/python3.11/asyncio/base_events.py", line 653, in run_until_complete
    return future.result()
           ^^^^^^^^^^^^^^^
  File "/home/shliamb/Desktop/WORK_FOLDER/chatgpt/app/tele_bot.py", line 57, in run_main
    result = await main(message.text, id)
             ^^^^^^^^^^^^^^^^^^^^^^^^^^^^
  File "/home/shliamb/Desktop/WORK_FOLDER/chatgpt/app/open_ai.py", line 13, in main
    read_data = read_chatgpt_setings(id)
                ^^^^^^^^^^^^^^^^^^^^^^^^
  File "/home/shliamb/Desktop/WORK_FOLDER/chatgpt/app/worker_db.py", line 49, in read_chatgpt_setings
    for data in read_data:
TypeError: 'SavedQuestion' object is not iterable
2024-01-27 21:20:16,041 - logging_bot - ERROR - Произошла непредвиденная ошибка:
Traceback (most recent call last):
  File "/home/shliamb/Desktop/WORK_FOLDER/chatgpt/app/run_bot.py", line 9, in <module>
    from tele_bot import start_bot
  File "/home/shliamb/Desktop/WORK_FOLDER/chatgpt/app/tele_bot.py", line 69, in <module>
    start_bot = bot.polling() # Запуск инициализируется в run_bot.py
                ^^^^^^^^^^^^^
  File "/home/shliamb/Desktop/WORK_FOLDER/chatgpt/myvenv/lib/python3.11/site-packages/telebot/__init__.py", line 1045, in polling
    self.__threaded_polling(non_stop=non_stop, interval=interval, timeout=timeout, long_polling_timeout=long_polling_timeout,
  File "/home/shliamb/Desktop/WORK_FOLDER/chatgpt/myvenv/lib/python3.11/site-packages/telebot/__init__.py", line 1120, in __threaded_polling
    raise e
  File "/home/shliamb/Desktop/WORK_FOLDER/chatgpt/myvenv/lib/python3.11/site-packages/telebot/__init__.py", line 1082, in __threaded_polling
    self.worker_pool.raise_exceptions()
  File "/home/shliamb/Desktop/WORK_FOLDER/chatgpt/myvenv/lib/python3.11/site-packages/telebot/util.py", line 147, in raise_exceptions
    raise self.exception_info
  File "/home/shliamb/Desktop/WORK_FOLDER/chatgpt/myvenv/lib/python3.11/site-packages/telebot/util.py", line 90, in run
    task(*args, **kwargs)
  File "/home/shliamb/Desktop/WORK_FOLDER/chatgpt/myvenv/lib/python3.11/site-packages/telebot/__init__.py", line 6793, in _run_middlewares_and_handler
    result = handler['function'](message)
             ^^^^^^^^^^^^^^^^^^^^^^^^^^^^
  File "/home/shliamb/Desktop/WORK_FOLDER/chatgpt/app/tele_bot.py", line 63, in handle_message
    loop.run_until_complete(run_main())
  File "/usr/lib/python3.11/asyncio/base_events.py", line 653, in run_until_complete
    return future.result()
           ^^^^^^^^^^^^^^^
  File "/home/shliamb/Desktop/WORK_FOLDER/chatgpt/app/tele_bot.py", line 57, in run_main
    result = await main(message.text, id)
             ^^^^^^^^^^^^^^^^^^^^^^^^^^^^
  File "/home/shliamb/Desktop/WORK_FOLDER/chatgpt/app/open_ai.py", line 13, in main
    read_data = read_chatgpt_setings(id)
                ^^^^^^^^^^^^^^^^^^^^^^^^
  File "/home/shliamb/Desktop/WORK_FOLDER/chatgpt/app/worker_db.py", line 50, in read_chatgpt_setings
    for data in read_data:
TypeError: 'SavedQuestion' object is not iterable
2024-01-27 21:28:22,390 - logging_bot - ERROR - Произошла непредвиденная ошибка:
Traceback (most recent call last):
  File "/home/shliamb/Desktop/WORK_FOLDER/chatgpt/app/run_bot.py", line 9, in <module>
    from tele_bot import start_bot
  File "/home/shliamb/Desktop/WORK_FOLDER/chatgpt/app/tele_bot.py", line 69, in <module>
    start_bot = bot.polling() # Запуск инициализируется в run_bot.py
                ^^^^^^^^^^^^^
  File "/home/shliamb/Desktop/WORK_FOLDER/chatgpt/myvenv/lib/python3.11/site-packages/telebot/__init__.py", line 1045, in polling
    self.__threaded_polling(non_stop=non_stop, interval=interval, timeout=timeout, long_polling_timeout=long_polling_timeout,
  File "/home/shliamb/Desktop/WORK_FOLDER/chatgpt/myvenv/lib/python3.11/site-packages/telebot/__init__.py", line 1120, in __threaded_polling
    raise e
  File "/home/shliamb/Desktop/WORK_FOLDER/chatgpt/myvenv/lib/python3.11/site-packages/telebot/__init__.py", line 1082, in __threaded_polling
    self.worker_pool.raise_exceptions()
  File "/home/shliamb/Desktop/WORK_FOLDER/chatgpt/myvenv/lib/python3.11/site-packages/telebot/util.py", line 147, in raise_exceptions
    raise self.exception_info
  File "/home/shliamb/Desktop/WORK_FOLDER/chatgpt/myvenv/lib/python3.11/site-packages/telebot/util.py", line 90, in run
    task(*args, **kwargs)
  File "/home/shliamb/Desktop/WORK_FOLDER/chatgpt/myvenv/lib/python3.11/site-packages/telebot/__init__.py", line 6793, in _run_middlewares_and_handler
    result = handler['function'](message)
             ^^^^^^^^^^^^^^^^^^^^^^^^^^^^
  File "/home/shliamb/Desktop/WORK_FOLDER/chatgpt/app/tele_bot.py", line 63, in handle_message
    loop.run_until_complete(run_main())
  File "/usr/lib/python3.11/asyncio/base_events.py", line 653, in run_until_complete
    return future.result()
           ^^^^^^^^^^^^^^^
  File "/home/shliamb/Desktop/WORK_FOLDER/chatgpt/app/tele_bot.py", line 57, in run_main
    result = await main(message.text, id)
             ^^^^^^^^^^^^^^^^^^^^^^^^^^^^
  File "/home/shliamb/Desktop/WORK_FOLDER/chatgpt/app/open_ai.py", line 13, in main
    read_data = read_data_ans_ques(id)
                ^^^^^^^^^^^^^^^^^^^^^^
  File "/home/shliamb/Desktop/WORK_FOLDER/chatgpt/app/worker_db.py", line 49, in read_data_ans_ques
    for data in read_data:
TypeError: 'SavedQuestion' object is not iterable
2024-01-27 21:30:31,407 - logging_bot - ERROR - Произошла непредвиденная ошибка:
Traceback (most recent call last):
  File "/home/shliamb/Desktop/WORK_FOLDER/chatgpt/app/run_bot.py", line 9, in <module>
    from tele_bot import start_bot
  File "/home/shliamb/Desktop/WORK_FOLDER/chatgpt/app/tele_bot.py", line 69, in <module>
    start_bot = bot.polling() # Запуск инициализируется в run_bot.py
                ^^^^^^^^^^^^^
  File "/home/shliamb/Desktop/WORK_FOLDER/chatgpt/myvenv/lib/python3.11/site-packages/telebot/__init__.py", line 1045, in polling
    self.__threaded_polling(non_stop=non_stop, interval=interval, timeout=timeout, long_polling_timeout=long_polling_timeout,
  File "/home/shliamb/Desktop/WORK_FOLDER/chatgpt/myvenv/lib/python3.11/site-packages/telebot/__init__.py", line 1120, in __threaded_polling
    raise e
  File "/home/shliamb/Desktop/WORK_FOLDER/chatgpt/myvenv/lib/python3.11/site-packages/telebot/__init__.py", line 1082, in __threaded_polling
    self.worker_pool.raise_exceptions()
  File "/home/shliamb/Desktop/WORK_FOLDER/chatgpt/myvenv/lib/python3.11/site-packages/telebot/util.py", line 147, in raise_exceptions
    raise self.exception_info
  File "/home/shliamb/Desktop/WORK_FOLDER/chatgpt/myvenv/lib/python3.11/site-packages/telebot/util.py", line 90, in run
    task(*args, **kwargs)
  File "/home/shliamb/Desktop/WORK_FOLDER/chatgpt/myvenv/lib/python3.11/site-packages/telebot/__init__.py", line 6793, in _run_middlewares_and_handler
    result = handler['function'](message)
             ^^^^^^^^^^^^^^^^^^^^^^^^^^^^
  File "/home/shliamb/Desktop/WORK_FOLDER/chatgpt/app/tele_bot.py", line 63, in handle_message
    loop.run_until_complete(run_main())
  File "/usr/lib/python3.11/asyncio/base_events.py", line 653, in run_until_complete
    return future.result()
           ^^^^^^^^^^^^^^^
  File "/home/shliamb/Desktop/WORK_FOLDER/chatgpt/app/tele_bot.py", line 57, in run_main
    result = await main(message.text, id)
             ^^^^^^^^^^^^^^^^^^^^^^^^^^^^
  File "/home/shliamb/Desktop/WORK_FOLDER/chatgpt/app/open_ai.py", line 13, in main
    read_data = read_data_ans_ques(id)
                ^^^^^^^^^^^^^^^^^^^^^^
  File "/home/shliamb/Desktop/WORK_FOLDER/chatgpt/app/worker_db.py", line 49, in read_data_ans_ques
    for data in read_data:
TypeError: 'SavedQuestion' object is not iterable
2024-01-27 21:32:15,174 - logging_bot - ERROR - Произошла непредвиденная ошибка:
Traceback (most recent call last):
  File "/home/shliamb/Desktop/WORK_FOLDER/chatgpt/app/run_bot.py", line 9, in <module>
    from tele_bot import start_bot
  File "/home/shliamb/Desktop/WORK_FOLDER/chatgpt/app/tele_bot.py", line 69, in <module>
    start_bot = bot.polling() # Запуск инициализируется в run_bot.py
                ^^^^^^^^^^^^^
  File "/home/shliamb/Desktop/WORK_FOLDER/chatgpt/myvenv/lib/python3.11/site-packages/telebot/__init__.py", line 1045, in polling
    self.__threaded_polling(non_stop=non_stop, interval=interval, timeout=timeout, long_polling_timeout=long_polling_timeout,
  File "/home/shliamb/Desktop/WORK_FOLDER/chatgpt/myvenv/lib/python3.11/site-packages/telebot/__init__.py", line 1120, in __threaded_polling
    raise e
  File "/home/shliamb/Desktop/WORK_FOLDER/chatgpt/myvenv/lib/python3.11/site-packages/telebot/__init__.py", line 1082, in __threaded_polling
    self.worker_pool.raise_exceptions()
  File "/home/shliamb/Desktop/WORK_FOLDER/chatgpt/myvenv/lib/python3.11/site-packages/telebot/util.py", line 147, in raise_exceptions
    raise self.exception_info
  File "/home/shliamb/Desktop/WORK_FOLDER/chatgpt/myvenv/lib/python3.11/site-packages/telebot/util.py", line 90, in run
    task(*args, **kwargs)
  File "/home/shliamb/Desktop/WORK_FOLDER/chatgpt/myvenv/lib/python3.11/site-packages/telebot/__init__.py", line 6793, in _run_middlewares_and_handler
    result = handler['function'](message)
             ^^^^^^^^^^^^^^^^^^^^^^^^^^^^
  File "/home/shliamb/Desktop/WORK_FOLDER/chatgpt/app/tele_bot.py", line 63, in handle_message
    loop.run_until_complete(run_main())
  File "/usr/lib/python3.11/asyncio/base_events.py", line 653, in run_until_complete
    return future.result()
           ^^^^^^^^^^^^^^^
  File "/home/shliamb/Desktop/WORK_FOLDER/chatgpt/app/tele_bot.py", line 57, in run_main
    result = await main(message.text, id)
             ^^^^^^^^^^^^^^^^^^^^^^^^^^^^
  File "/home/shliamb/Desktop/WORK_FOLDER/chatgpt/app/open_ai.py", line 13, in main
    read_data = read_data_ans_ques(id)
                ^^^^^^^^^^^^^^^^^^^^^^
  File "/home/shliamb/Desktop/WORK_FOLDER/chatgpt/app/worker_db.py", line 49, in read_data_ans_ques
    for data in read_data:
TypeError: 'SavedQuestion' object is not iterable
2024-01-27 21:33:19,314 - logging_bot - ERROR - Произошла непредвиденная ошибка:
Traceback (most recent call last):
  File "/home/shliamb/Desktop/WORK_FOLDER/chatgpt/app/run_bot.py", line 9, in <module>
    from tele_bot import start_bot
  File "/home/shliamb/Desktop/WORK_FOLDER/chatgpt/app/tele_bot.py", line 69, in <module>
    start_bot = bot.polling() # Запуск инициализируется в run_bot.py
                ^^^^^^^^^^^^^
  File "/home/shliamb/Desktop/WORK_FOLDER/chatgpt/myvenv/lib/python3.11/site-packages/telebot/__init__.py", line 1045, in polling
    self.__threaded_polling(non_stop=non_stop, interval=interval, timeout=timeout, long_polling_timeout=long_polling_timeout,
  File "/home/shliamb/Desktop/WORK_FOLDER/chatgpt/myvenv/lib/python3.11/site-packages/telebot/__init__.py", line 1120, in __threaded_polling
    raise e
  File "/home/shliamb/Desktop/WORK_FOLDER/chatgpt/myvenv/lib/python3.11/site-packages/telebot/__init__.py", line 1082, in __threaded_polling
    self.worker_pool.raise_exceptions()
  File "/home/shliamb/Desktop/WORK_FOLDER/chatgpt/myvenv/lib/python3.11/site-packages/telebot/util.py", line 147, in raise_exceptions
    raise self.exception_info
  File "/home/shliamb/Desktop/WORK_FOLDER/chatgpt/myvenv/lib/python3.11/site-packages/telebot/util.py", line 90, in run
    task(*args, **kwargs)
  File "/home/shliamb/Desktop/WORK_FOLDER/chatgpt/myvenv/lib/python3.11/site-packages/telebot/__init__.py", line 6793, in _run_middlewares_and_handler
    result = handler['function'](message)
             ^^^^^^^^^^^^^^^^^^^^^^^^^^^^
  File "/home/shliamb/Desktop/WORK_FOLDER/chatgpt/app/tele_bot.py", line 63, in handle_message
    loop.run_until_complete(run_main())
  File "/usr/lib/python3.11/asyncio/base_events.py", line 653, in run_until_complete
    return future.result()
           ^^^^^^^^^^^^^^^
  File "/home/shliamb/Desktop/WORK_FOLDER/chatgpt/app/tele_bot.py", line 57, in run_main
    result = await main(message.text, id)
             ^^^^^^^^^^^^^^^^^^^^^^^^^^^^
  File "/home/shliamb/Desktop/WORK_FOLDER/chatgpt/app/open_ai.py", line 13, in main
    read_data = read_data_ans_ques(id)
                ^^^^^^^^^^^^^^^^^^^^^^
  File "/home/shliamb/Desktop/WORK_FOLDER/chatgpt/app/worker_db.py", line 49, in read_data_ans_ques
    for data in read_data:
TypeError: 'SavedQuestion' object is not iterable
2024-01-27 21:35:49,093 - httpx - INFO - HTTP Request: POST https://api.openai.com/v1/chat/completions "HTTP/1.1 200 OK"
2024-01-27 21:54:47,919 - httpx - INFO - HTTP Request: POST https://api.openai.com/v1/chat/completions "HTTP/1.1 200 OK"
2024-01-27 21:55:40,669 - httpx - INFO - HTTP Request: POST https://api.openai.com/v1/chat/completions "HTTP/1.1 200 OK"
2024-01-27 21:56:40,705 - httpx - INFO - HTTP Request: POST https://api.openai.com/v1/chat/completions "HTTP/1.1 200 OK"
2024-01-27 21:57:04,377 - httpx - INFO - HTTP Request: POST https://api.openai.com/v1/chat/completions "HTTP/1.1 200 OK"
2024-01-27 22:04:31,730 - httpx - INFO - HTTP Request: POST https://api.openai.com/v1/chat/completions "HTTP/1.1 200 OK"
2024-01-27 22:05:29,738 - httpx - INFO - HTTP Request: POST https://api.openai.com/v1/chat/completions "HTTP/1.1 200 OK"
2024-01-27 22:05:45,828 - httpx - INFO - HTTP Request: POST https://api.openai.com/v1/chat/completions "HTTP/1.1 200 OK"
2024-01-27 22:08:18,159 - httpx - INFO - HTTP Request: POST https://api.openai.com/v1/chat/completions "HTTP/1.1 200 OK"
2024-01-27 22:09:48,242 - logging_bot - ERROR - Произошла непредвиденная ошибка:
Traceback (most recent call last):
  File "/home/shliamb/Desktop/WORK_FOLDER/chatgpt/app/run_bot.py", line 9, in <module>
    from tele_bot import start_bot
  File "/home/shliamb/Desktop/WORK_FOLDER/chatgpt/app/tele_bot.py", line 69, in <module>
    start_bot = bot.polling() # Запуск инициализируется в run_bot.py
                ^^^^^^^^^^^^^
  File "/home/shliamb/Desktop/WORK_FOLDER/chatgpt/myvenv/lib/python3.11/site-packages/telebot/__init__.py", line 1045, in polling
    self.__threaded_polling(non_stop=non_stop, interval=interval, timeout=timeout, long_polling_timeout=long_polling_timeout,
  File "/home/shliamb/Desktop/WORK_FOLDER/chatgpt/myvenv/lib/python3.11/site-packages/telebot/__init__.py", line 1120, in __threaded_polling
    raise e
  File "/home/shliamb/Desktop/WORK_FOLDER/chatgpt/myvenv/lib/python3.11/site-packages/telebot/__init__.py", line 1082, in __threaded_polling
    self.worker_pool.raise_exceptions()
  File "/home/shliamb/Desktop/WORK_FOLDER/chatgpt/myvenv/lib/python3.11/site-packages/telebot/util.py", line 147, in raise_exceptions
    raise self.exception_info
  File "/home/shliamb/Desktop/WORK_FOLDER/chatgpt/myvenv/lib/python3.11/site-packages/telebot/util.py", line 90, in run
    task(*args, **kwargs)
  File "/home/shliamb/Desktop/WORK_FOLDER/chatgpt/myvenv/lib/python3.11/site-packages/telebot/__init__.py", line 6793, in _run_middlewares_and_handler
    result = handler['function'](message)
             ^^^^^^^^^^^^^^^^^^^^^^^^^^^^
  File "/home/shliamb/Desktop/WORK_FOLDER/chatgpt/app/tele_bot.py", line 63, in handle_message
    loop.run_until_complete(run_main())
  File "/usr/lib/python3.11/asyncio/base_events.py", line 653, in run_until_complete
    return future.result()
           ^^^^^^^^^^^^^^^
  File "/home/shliamb/Desktop/WORK_FOLDER/chatgpt/app/tele_bot.py", line 57, in run_main
    result = await main(message.text, id)
             ^^^^^^^^^^^^^^^^^^^^^^^^^^^^
  File "/home/shliamb/Desktop/WORK_FOLDER/chatgpt/app/open_ai.py", line 16, in main
    session_date = read_data[1]
                   ~~~~~~~~~^^^
TypeError: 'NoneType' object is not subscriptable
2024-01-27 22:14:39,699 - httpx - INFO - HTTP Request: POST https://api.openai.com/v1/chat/completions "HTTP/1.1 200 OK"
2024-01-27 22:15:42,888 - httpx - INFO - HTTP Request: POST https://api.openai.com/v1/chat/completions "HTTP/1.1 200 OK"
2024-01-27 22:15:53,227 - httpx - INFO - HTTP Request: POST https://api.openai.com/v1/chat/completions "HTTP/1.1 200 OK"
2024-01-27 22:17:14,510 - httpx - INFO - HTTP Request: POST https://api.openai.com/v1/chat/completions "HTTP/1.1 200 OK"
2024-01-27 22:17:41,765 - httpx - INFO - HTTP Request: POST https://api.openai.com/v1/chat/completions "HTTP/1.1 200 OK"
